Workbook

Sheet Read Me
B1: LEVIATHAN FUND — CORE PE VEHICLE
B2: IQT-Backed Deep-Tech Acquisition-Stake Portfolio | 5 / 7 / 10-Year Holds | Defense-Supercycle Overlay
B3: Anchored by Substrate, Inc. · Prepared 22-Sep-2026 · All figures USD millions unless noted
B5: PURPOSE
B6: Leviathan's core PE holdco is an $840M vehicle across THREE sub-funds: IQT-mirror deep-tech ($250M), Weapons ($390M), and Consumer/Value ($200M). All three sleeves are modeled bottom-up from individual holdings — IQT-mirror (nine In-Q-Tel names), Weapons (ten physical-layer holdings, incl. The Ellwood Group and Superior & Grand Valley for missile-procurement metal forging, and Faxon Machining for NGP / MOP / TLAM / BLU-136 warhead-case and missile machining), Consumer/Value (nine DTC/spending-cycle names) — each across four scenarios, 5/7/10-yr holds, gross-to-net waterfall, and PME, and roll up to a blended holdco return on the Holdco Summary tab. Start there for the top-down view; the sleeve tabs hold the detail.
B7: Scope: Leviathan runs four vehicles (~$1.5B AUM total); this workbook models only the core PE holdco vehicle ($840M) and its equity targets — not the other three vehicles.
B8: THE DEFENSE-SUPERCYCLE THESIS (now wired into returns)
B9: The book is built to be long the US side of the AI / semiconductor race with China and structurally hedged against a Taiwan contingency or loss of TSMC access. The Defense Supercycle tab scores every name on five strategic axes — China-race criticality, Taiwan/TSMC-insulation value, government/defense embeddedness, CFIUS-clean US-sovereignty, and supply-chain chokepoint leverage. Those scores drive a composite, which drives each name's re-rating in the TSMC-Shock scenario. Change a score and the shock returns move.
B11: HOW THE MODEL IS WIRED (edit blue cells only)
B12: • IC Summary — one-page holdco dashboard: net IRR / MOIC / proceeds / KS-PME by hold x scenario, sleeve gross MOIC, scenario weights and model integrity checks. Start here. • Assumptions — fund terms + per-name entry marks, checks, ownership, and Base/Bull/Bear CAGRs. TSMC-Shock CAGR is computed from the Supercycle tab.
B13: • Defense Supercycle — strategic scoring matrix, axis weights, shock calibration levers, and the four scenario probability weights. This is the thesis engine.
B14: • Allocation — nine positions, tranche, ownership, domicile, structuring/CFIUS flags.
... B27: 5. Simplified whole-fund European waterfall (no GP catch-up). Not investment advice — an internal IC planning model.

Sheet IC Summary
A1: LEVIATHAN CORE PE HOLDCO — IC SUMMARY
A2: $840M tripartite holdco (IQT-mirror / Weapons / Consumer-Value). USD $M. Expected = probability-weighted across Base/Bull/Bear/TSMC-Shock (weights on Defense Supercycle tab). Every figure links live to the model — no inputs on this page.
A4: HEADLINE — RECOMMENDED 7-YEAR VEHICLE (Expected case, net to LP)
A5: Metric | B5: Net IRR | C5: Net MOIC | D5: Net proceeds | E5: KS-PME basket | F5: KS-PME SPX
A6: Holdco — 7-yr, probability-weighted | B6: ='Holdco Summary'!F61 -> 0.19465272 | C6: ='Holdco Summary'!F59 -> 3.4728957 | D6: ='Holdco Summary'!F58 -> 2917.2323 | E6: ='Holdco Summary'!F64 -> 1.3055901 | F6: ='Holdco Summary'!F62 -> 1.8997929
A8: HOLDCO NET IRR TO LP
A9: Vehicle | B9: Base | C9: Bull | D9: Bear | E9: TSMC-Shock | F9: Expected
A10: 5-Year Hold | B10: ='Holdco Summary'!B40 -> 0.15733927 | C10: ='Holdco Summary'!C40 -> 0.27428659 | D10: ='Holdco Summary'!D40 -> -0.052345391 | E10: ='Holdco Summary'!E40 -> 0.21435583 | F10: ='Holdco Summary'!F40 -> 0.17972702
A11: 7-Year Hold | B11: ='Holdco Summary'!B61 -> 0.16130617 | C11: ='Holdco Summary'!C61 -> 0.28304723 | D11: ='Holdco Summary'!D61 -> -0.049463782 | E11: ='Holdco Summary'!E61 -> 0.23435009 | F11: ='Holdco Summary'!F61 -> 0.19465272
A12: 10-Year Hold | B12: ='Holdco Summary'!B82 -> 0.16698042 | C12: ='Holdco Summary'!C82 -> 0.29410141 | D12: ='Holdco Summary'!D82 -> -0.044928106 | E12: ='Holdco Summary'!E82 -> 0.25729863 | F12: ='Holdco Summary'!F82 -> 0.214407
A14: HOLDCO NET MOIC TO LP
A15: Vehicle | B15: Base | C15: Bull | D15: Bear | E15: TSMC-Shock | F15: Expected
A16: 5-Year Hold | B16: ='Holdco Summary'!B38 -> 2.0763638 | C16: ='Holdco Summary'!C38 -> 3.3599712 | D16: ='Holdco Summary'!D38 -> 0.76427631 | E16: ='Holdco Summary'!E38 -> 2.6407654 | F16: ='Holdco Summary'!F38 -> 2.2851128
A17: 7-Year Hold | B17: ='Holdco Summary'!B59 -> 2.8485715 | C17: ='Holdco Summary'!C59 -> 5.7239853 | D17: ='Holdco Summary'!D59 -> 0.70110116 | E17: ='Holdco Summary'!E59 -> 4.3658466 | F17: ='Holdco Summary'!F59 -> 3.4728957
A18: 10-Year Hold | B18: ='Holdco Summary'!B80 -> 4.6842028 | C18: ='Holdco Summary'!C80 -> 13.172952 | D18: ='Holdco Summary'!D80 -> 0.63148152 | E18: ='Holdco Summary'!E80 -> 9.8715289 | F18: ='Holdco Summary'!F80 -> 6.9765809
A20: HOLDCO NET PROCEEDS TO LP ($M)
A21: Vehicle | B21: Base | C21: Bull | D21: Bear | E21: TSMC-Shock | F21: Expected
A22: 5-Year Hold | B22: ='Holdco Summary'!B37 -> 1744.1456 | C22: ='Holdco Summary'!C37 -> 2822.3758 | D22: ='Holdco Summary'!D37 -> 641.9921 | E22: ='Holdco Summary'!E37 -> 2218.2429 | F22: ='Holdco Summary'!F37 -> 1919.4947
A23: 7-Year Hold | B23: ='Holdco Summary'!B58 -> 2392.8 | C23: ='Holdco Summary'!C58 -> 4808.1476 | D23: ='Holdco Summary'!D58 -> 588.92498 | E23: ='Holdco Summary'!E58 -> 3667.3112 | F23: ='Holdco Summary'!F58 -> 2917.2323
A24: 10-Year Hold | B24: ='Holdco Summary'!B79 -> 3934.7303 | C24: ='Holdco Summary'!C79 -> 11065.28 | D24: ='Holdco Summary'!D79 -> 530.44448 | E24: ='Holdco Summary'!E79 -> 8292.0843 | F24: ='Holdco Summary'!F79 -> 5860.3279
A26: KS-PME vs DEFENSE+SEMIS BASKET (>1.00x = beat the thematic ETFs)
A27: Vehicle | B27: Base | C27: Bull | D27: Bear | E27: TSMC-Shock | F27: Expected
A28: 5-Year Hold | B28: ='Holdco Summary'!B43 -> 1.0323198 | C28: ='Holdco Summary'!C43 -> 1.6704995 | D28: ='Holdco Summary'!D43 -> 0.3799804 | E28: ='Holdco Summary'!E43 -> 1.3129271 | F28: ='Holdco Summary'!F43 -> 1.1361049
A29: 7-Year Hold | B29: ='Holdco Summary'!B64 -> 1.0708835 | C29: ='Holdco Summary'!C64 -> 2.1518581 | D29: ='Holdco Summary'!D64 -> 0.2635699 | E29: ='Holdco Summary'!E64 -> 1.6412835 | F29: ='Holdco Summary'!F64 -> 1.3055901
A30: 10-Year Hold | B30: ='Holdco Summary'!B85 -> 1.1578633 | C30: ='Holdco Summary'!C85 -> 3.2561523 | D30: ='Holdco Summary'!D85 -> 0.15609257 | E30: ='Holdco Summary'!E85 -> 2.440091 | F30: ='Holdco Summary'!F85 -> 1.7245041
A32: KS-PME vs S&P 500 (>1.00x = beat)
A33: Vehicle | B33: Base | C33: Bull | D33: Bear | E33: TSMC-Shock | F33: Expected
A34: 5-Year Hold | B34: ='Holdco Summary'!B41 -> 1.349494 | C34: ='Holdco Summary'!C41 -> 2.1837508 | D34: ='Holdco Summary'!D41 -> 0.49672716 | E34: ='Holdco Summary'!E41 -> 1.7163163 | F34: ='Holdco Summary'!F41 -> 1.4851665
A35: 7-Year Hold | B35: ='Holdco Summary'!B62 -> 1.5582661 | C35: ='Holdco Summary'!C62 -> 3.131216 | D35: ='Holdco Summary'!D62 -> 0.38352634 | E35: ='Holdco Summary'!E62 -> 2.3882676 | F35: ='Holdco Summary'!F62 -> 1.8997929
A36: 10-Year Hold | B36: ='Holdco Summary'!B83 -> 1.9786579 | C36: ='Holdco Summary'!C83 -> 5.5643974 | D36: ='Holdco Summary'!D83 -> 0.26674462 | E36: ='Holdco Summary'!E83 -> 4.1698405 | F36: ='Holdco Summary'!F83 -> 2.9469832
A38: SLEEVE SIZING
A39: Sleeve | B39: Size ($M) | C39: % Holdco | D39: # Positions
A40: ='Holdco Summary'!A6 -> IQT-mirror (deep-tech) | B40: ='Holdco Summary'!B6 -> 250 | C40: ='Holdco Summary'!C6 -> 0.29761905 | D40: =COUNT(Assumptions!C18:C26) -> 9
A41: ='Holdco Summary'!A7 -> Weapons (physical layer) | B41: ='Holdco Summary'!B7 -> 390 | C41: ='Holdco Summary'!C7 -> 0.46428571 | D41: =COUNT('Weapons Sleeve'!C12:C21) -> 10
A42: ='Holdco Summary'!A8 -> Consumer / Value | B42: ='Holdco Summary'!B8 -> 200 | C42: ='Holdco Summary'!C8 -> 0.23809524 | D42: =COUNT('Consumer Sleeve'!C12:C20) -> 9
A43: Total holdco | B43: =SUM(B40:B42) -> 840 | C43: =SUM(C40:C42) -> 1 | D43: =SUM(D40:D42) -> 28
A45: SLEEVE GROSS MOIC — 5-YEAR HOLD (gross proceeds / committed)
A46: Sleeve | B46: Base | C46: Bull | D46: Bear | E46: TSMC-Shock | F46: Expected
A47: IQT-mirror | B47: ='Holdco Summary'!B28/'Holdco Summary'!$B$6 -> 2.2633231 | C47: ='Holdco Summary'!C28/'Holdco Summary'!$B$6 -> 3.6174457 | D47: ='Holdco Summary'!D28/'Holdco Summary'!$B$6 -> 0.5051741 | E47: ='Holdco Summary'!E28/'Holdco Summary'!$B$6 -> 3.6616253 | F47: ='Holdco Summary'!F28/'Holdco Summary'!$B$6 -> 2.5478767
A48: Weapons | B48: ='Holdco Summary'!B29/'Holdco Summary'!$B$7 -> 2.4025132 | C48: ='Holdco Summary'!C29/'Holdco Summary'!$B$7 -> 3.9899007 | D48: ='Holdco Summary'!D29/'Holdco Summary'!$B$7 -> 1.124153 | E48: ='Holdco Summary'!E29/'Holdco Summary'!$B$7 -> 3.9973937 | F48: ='Holdco Summary'!F29/'Holdco Summary'!$B$7 -> 2.8468381
...

Sheet Holdco Summary
A1: LEVIATHAN — CORE PE HOLDCO ($840M) — TRIPARTITE ROLL-UP
A2: Three sub-funds rolled up to a blended holdco return. Blue = lever. All three sleeves — IQT-mirror, Weapons, Consumer/Value — flow in bottom-up.
A4: HOLDCO STRUCTURE & SIZING
A5: Sub-fund | B5: Size ($M) | C5: % Holdco | D5: Return driver | E5: Duration | F5: Role
A6: IQT-mirror (deep-tech) | B6: 250 | C6: =B6/$B$9 -> 0.29761905 | D6: Onshoring capex + Taiwan tail | E6: Longest | F6: Convex optionality / tail hedge
A7: Weapons (physical layer) | B7: 390 | C7: =B7/$B$9 -> 0.46428571 | D7: Defense opex — budgets, conflict | E7: Medium | F7: Cash-generative supercycle core
A8: Consumer / Value | B8: 200 | C8: =B8/$B$9 -> 0.23809524 | D8: Consumer cycle + DTC/wellness | E8: Shortest | F8: Ballast + near-term DPI engine
A9: TOTAL (must = $840M) | B9: =SUM(B6:B8) -> 840 | C9: =SUM(C6:C8) -> 1
A10: IQT-mirror: Substrate, EUV Tech, ThinTronics, EdgeCortix, Syntiant, Infleqtion, Diraq, Mueon, DefendEye
A11: Weapons: Epirus, Elta, Israel Aerospace Industries, Saronic, Helicon Chemical, Applied Research Associates, Heckler & Koch, The Ellwood Group, Superior & Grand Valley, Faxon Machining
A12: Consumer/Value: Quince, Thrive Market, The Farmer's Dog, Whoop, Plunge, Made In Cookware, Polymarket, Goat Group, Stripe
A14: SLEEVE RETURN ASSUMPTIONS — gross equity CAGR, net of dilution (blue)
A15: Sleeve | B15: Base | C15: Bull | D15: Bear | E15: TSMC-Shock
A16: Weapons (memo — now bottom-up) | B16: 0.22 | C16: 0.34 | D16: 0.05 | E16: 0.32
A17: Consumer / Value (memo — now bottom-up) | B17: 0.14 | C17: 0.25 | D17: -0.1 | E17: -0.04
A18: IQT-mirror, Weapons, AND Consumer/Value are all modeled bottom-up (Portfolio Returns / Weapons Sleeve / Consumer Sleeve tabs) and flow in directly. Both rows above are memos only, kept for reference to the original sleeve-level placeholder assumptions they replaced.
A20: BENCHMARKS (KS-PME > 1.0x = beat)
A21: S&P 500 (SPX) total-return CAGR | B21: ='PME, DPI & Sensitivity'!$B$5 -> 0.09
A22: Nasdaq-100 (NDX) total-return CAGR | B22: ='PME, DPI & Sensitivity'!$B$6 -> 0.13
A23: Defense+Semis thematic basket CAGR (ITA/SOXX blend) | B23: 0.15
A24: Forward-tempered: 50/50 ITA/SOXX trailing 5yr is ~26% (ITA 18.2% / SOXX 34.5% to Jun-26), inflated by the AI+rearmament run; 15% forward. See Macro Overlay for comps & drivers.
A26: 5-YEAR HOLDCO ROLL-UP
A27: Line item ($M) | B27: Base | C27: Bull | D27: Bear | E27: TSMC-Shock | F27: Expected
A28: IQT-mirror gross | B28: ='Fund Economics'!B6 -> 565.83078 | C28: ='Fund Economics'!C6 -> 904.36142 | D28: ='Fund Economics'!D6 -> 126.29353 | E28: ='Fund Economics'!E6 -> 915.40631 | F28: ='Fund Economics'!F6 -> 636.96918
A29: Weapons gross | B29: ='Weapons Sleeve'!C36 -> 936.98016 | C29: ='Weapons Sleeve'!F36 -> 1556.0613 | D29: ='Weapons Sleeve'!I36 -> 438.41966 | E29: ='Weapons Sleeve'!L36 -> 1558.9836 | F29: =B29*'Defense Supercycle'!$B$17+C29*'Defense Supercycle'!$B$18+D29*'Defense Supercycle'!$B$19+E29*'Defense Supercycle'!$B$20 -> 1110.2669
A30: Consumer/Value gross | B30: ='Consumer Sleeve'!C34 -> 473.81214 | C30: ='Consumer Sleeve'!F34 -> 863.98824 | D30: ='Consumer Sleeve'!I34 -> 161.27892 | E30: ='Consumer Sleeve'!L34 -> 94.854864 | F30: =B30*'Defense Supercycle'!$B$17+C30*'Defense Supercycle'!$B$18+D30*'Defense Supercycle'!$B$19+E30*'Defense Supercycle'!$B$20 -> 467.63259
A31: HOLDCO gross proceeds | B31: =B28+B29+B30 -> 1976.6231 | C31: =C28+C29+C30 -> 3324.4109 | D31: =D28+D29+D30 -> 725.9921 | E31: =E28+E29+E30 -> 2569.2447 | F31: =F28+F29+F30 -> 2214.8686
A32: (-) Return of capital | B32: =-'Holdco Summary'!$B$9 -> -840 | C32: =-'Holdco Summary'!$B$9 -> -840 | D32: =-'Holdco Summary'!$B$9 -> -840 | E32: =-'Holdco Summary'!$B$9 -> -840 | F32: =-'Holdco Summary'!$B$9 -> -840
A33: (-) Preferred (8% comp.) | B33: =-'Holdco Summary'!$B$9*((1+Assumptions!$B$10)^5-1) -> -394.23558 | C33: =-'Holdco Summary'!$B$9*((1+Assumptions!$B$10)^5-1) -> -394.23558 | D33: =-'Holdco Summary'!$B$9*((1+Assumptions!$B$10)^5-1) -> -394.23558 | E33: =-'Holdco Summary'!$B$9*((1+Assumptions!$B$10)^5-1) -> -394.23558 | F33: =-'Holdco Summary'!$B$9*((1+Assumptions!$B$10)^5-1) -> -394.23558
A34: Profit above pref | B34: =MAX(0,B31+B32+B33) -> 742.3875 | C34: =MAX(0,C31+C32+C33) -> 2090.1753 | D34: =MAX(0,D31+D32+D33) -> 0 | E34: =MAX(0,E31+E32+E33) -> 1335.0092 | F34: =B34*'Defense Supercycle'!$B$17+C34*'Defense Supercycle'!$B$18+D34*'Defense Supercycle'!$B$19+E34*'Defense Supercycle'!$B$20 -> 1056.8696
A35: (-) Carry (20%) | B35: =-Assumptions!$B$9*B34 -> -148.4775 | C35: =-Assumptions!$B$9*C34 -> -418.03507 | D35: =-Assumptions!$B$9*D34 -> 0 | E35: =-Assumptions!$B$9*E34 -> -267.00183 | F35: =B35*'Defense Supercycle'!$B$17+C35*'Defense Supercycle'!$B$18+D35*'Defense Supercycle'!$B$19+E35*'Defense Supercycle'!$B$20 -> -211.37392
A36: (-) Mgmt fees (2%/yr) | B36: =-'Holdco Summary'!$B$9*Assumptions!$B$8*5 -> -84 | C36: =-'Holdco Summary'!$B$9*Assumptions!$B$8*5 -> -84 | D36: =-'Holdco Summary'!$B$9*Assumptions!$B$8*5 -> -84 | E36: =-'Holdco Summary'!$B$9*Assumptions!$B$8*5 -> -84 | F36: =-'Holdco Summary'!$B$9*Assumptions!$B$8*5 -> -84
A37: NET proceeds to LP | B37: =B31+B35+B36 -> 1744.1456 | C37: =C31+C35+C36 -> 2822.3758 | D37: =D31+D35+D36 -> 641.9921 | E37: =E31+E35+E36 -> 2218.2429 | F37: =F31+F35+F36 -> 1919.4947
A38: Net MOIC | B38: =B37/'Holdco Summary'!$B$9 -> 2.0763638 | C38: =C37/'Holdco Summary'!$B$9 -> 3.3599712 | D38: =D37/'Holdco Summary'!$B$9 -> 0.76427631 | E38: =E37/'Holdco Summary'!$B$9 -> 2.6407654 | F38: =F37/'Holdco Summary'!$B$9 -> 2.2851128
A39: Net DPI (=TVPI at exit) | B39: =B37/'Holdco Summary'!$B$9 -> 2.0763638 | C39: =C37/'Holdco Summary'!$B$9 -> 3.3599712 | D39: =D37/'Holdco Summary'!$B$9 -> 0.76427631 | E39: =E37/'Holdco Summary'!$B$9 -> 2.6407654 | F39: =F37/'Holdco Summary'!$B$9 -> 2.2851128
A40: Net IRR | B40: =(B37/'Holdco Summary'!$B$9)^(1/5)-1 -> 0.15733927 | C40: =(C37/'Holdco Summary'!$B$9)^(1/5)-1 -> 0.27428659 | D40: =(D37/'Holdco Summary'!$B$9)^(1/5)-1 -> -0.052345391 | E40: =(E37/'Holdco Summary'!$B$9)^(1/5)-1 -> 0.21435583 | F40: =(F37/'Holdco Summary'!$B$9)^(1/5)-1 -> 0.17972702
A41: KS-PME vs SPX | B41: =B38/(1+'Holdco Summary'!$B$21)^5 -> 1.349494 | C41: =C38/(1+'Holdco Summary'!$B$21)^5 -> 2.1837508 | D41: =D38/(1+'Holdco Summary'!$B$21)^5 -> 0.49672716 | E41: =E38/(1+'Holdco Summary'!$B$21)^5 -> 1.7163163 | F41: =F38/(1+'Holdco Summary'!$B$21)^5 -> 1.4851665
A42: KS-PME vs NDX | B42: =B38/(1+'Holdco Summary'!$B$22)^5 -> 1.1269671 | C42: =C38/(1+'Holdco Summary'!$B$22)^5 -> 1.8236578 | D42: =D38/(1+'Holdco Summary'!$B$22)^5 -> 0.41481856 | E42: =E38/(1+'Holdco Summary'!$B$22)^5 -> 1.4333016 | F42: =F38/(1+'Holdco Summary'!$B$22)^5 -> 1.2402677
A43: KS-PME vs Defense+Semis basket | B43: =B38/(1+'Holdco Summary'!$B$23)^5 -> 1.0323198 | C43: =C38/(1+'Holdco Summary'!$B$23)^5 -> 1.6704995 | D43: =D38/(1+'Holdco Summary'!$B$23)^5 -> 0.3799804 | E43: =E38/(1+'Holdco Summary'!$B$23)^5 -> 1.3129271 | F43: =F38/(1+'Holdco Summary'!$B$23)^5 -> 1.1361049
A44: Direct Alpha vs basket (ann.) | B44: =(B38/(1+'Holdco Summary'!$B$23)^5)^(1/5)-1 -> 0.0063819732 | C44: =(C38/(1+'Holdco Summary'!$B$23)^5)^(1/5)-1 -> 0.10807529 | D44: =(D38/(1+'Holdco Summary'!$B$23)^5)^(1/5)-1 -> -0.17595251 | E44: =(E38/(1+'Holdco Summary'!$B$23)^5)^(1/5)-1 -> 0.055961593 | F44: =(F38/(1+'Holdco Summary'!$B$23)^5)^(1/5)-1 -> 0.025849585
...

Sheet Macro Overlay
A1: MACRO, GEOPOLITICAL & DEFENSE-SUPERCYCLE OVERLAY
A2: Grounds the sleeve return assumptions in current comps and the geopolitical/macro picture. Figures as of ~Jun-Sep 2026; sourced below.
A4: 1 | PUBLIC & PRIVATE COMPS GROUNDING THE SLEEVE ASSUMPTIONS
A5: Comparable | B5: Metric | C5: Value | D5: Note / relevance
A6: ITA (US Aero & Defense ETF) | B6: Total return 1/5/10-yr | C6: 29.3% / 18.2% / 15.7% | D6: Defense supercycle already priced into public primes (as of Jun-26)
A7: SOXX (Semiconductor ETF) | B7: Total return 1/5/10-yr | C7: 169.6% / 34.5% / 36.6% | D7: AI-driven surge; forward mean-reversion risk off a huge base
A8: 50/50 ITA/SOXX basket | B8: Trailing 5-yr blend | C8: ~26.3% | D8: Thematic hurdle; model uses 15% FORWARD (tempered)
A9: SPX / NDX | B9: Forward CAGR (model) | C9: 9.0% / 13.0% | D9: Broad-market floor benchmarks
A10: Rheinmetall (RHM) | B10: Rev growth / EV-Rev / EV-EBITDA | C10: 40% / 4.0x / 17.3x | D10: European rearmament bellwether; $54B cap
A11: AeroVironment (AVAV) | B11: TTM rev / YoY | C11: $1.61B / +117% | D11: Drones/loitering munitions (incl. M&A); supercycle demand
A12: L3Harris (LHX) | B12: EV-Rev / EV-EBITDA | C12: 2.6x / 15.1x | D12: Established prime multiple anchor
A13: Saronic (private) | B13: Valuation / 2025 rev | C13: $9.25B / $200M (+1,500%) | D13: Naval autonomy hypergrowth (Series D, Mar-26)
A14: Anduril (private) | B14: Valuation / 2025 rev | C14: $61B / $2.2B (+120%) | D14: Scale-up reference; $20B Army ceiling (Mar-26)
A15: Epirus (private) | B15: Directed energy / HPM | C15: Growth-stage | D15: Counter-drone; Weapons-sleeve holding
A16: Grounded sleeve assumptions (Base/Bull/Bear/Shock gross CAGR): Weapons 22/34/5/32% (original sleeve memo, reference only — model runs bottom-up per name with the munitions/FMS overlay); Consumer modeled bottom-up per-name, two now market-priced via Forge secondary (Quince 28/45/2/-18%, Whoop 27/42/-3/-16%, The Farmer's Dog 22/34/10/-5% @ $3.76B Forge-implied, Made In Cookware 14/26/-10/-14% est., Thrive Market 7/16/-5/-8% @ ~$945M Forge-implied (down from $1.29B Series C), Plunge 20/50/-22/-28% est.); thematic basket 15% fwd. IQT-mirror is bottom-up.
A18: 2 | DEFENSE SUPERCYCLE DRIVERS
A19: • NATO 5%-of-GDP pledge (Hague summit, Jun-2025): 3.5% core defense + 1.5% defense-related, on a path to 2035 — a structural, decade-long step-up, not a cyclical bump.
A20: • European allies + Canada raised defense spending ~20% in 2025 alone; all allies now above the old 2% floor. Rheinmetall growing 40%/yr is the bellwether.
A21: • Munitions/energetics replenishment (Ukraine drawdown) + naval autonomy (Replicator) + counter-drone are the fastest-growing demand pools — directly the Weapons sleeve (Helicon, Saronic, Epirus).
A23: 3 | CHINA & GEOPOLITICAL PICTURE
A24: • China official defense budget ~1.78T yuan (~$245B) for 2025, +7.2% YoY (widely cited; pre-cutoff — confirm 2026 figure) — sustained double-digit real modernization for a decade.
A25: • 'Davidson window' (PLA capability vs. Taiwan by 2027) frames the tail-risk timeline the TSMC-Shock scenario models — the single point of failure is TSMC leading-edge capacity.
A26: • US-China tech decoupling: export controls on advanced semis/tooling, entity-list expansion, and reshoring incentives are the policy tailwind behind the IQT-mirror sleeve's sovereign-chokepoint names.
A28: 4 | GLOBAL MACRO BACKDROP
A29: • Rates/exit markets: the Fed path drives PE exit windows and long-duration deep-tech valuations most — a higher-for-longer regime compresses the IQT sleeve's terminal multiples and delays exits (lengthens duration, lowers DPI timing).
A30: • USD & inflation: a decoupling/Taiwan shock is inflationary (supply shock) and USD-volatile — negative for the Consumer sleeve overall, though now modeled per-name on the Consumer Sleeve tab: import/hardware-exposed names (Quince, Whoop, Made In, Plunge) take the sharper Shock hit via COGS/chip-supply, while staple/subscription names (Farmer's Dog, Thrive Market) are more defensive; Goat Group (discretionary resale demand + cross-border logistics) also skews Shock-worse-than-Bear, while Stripe (fee-based payments infra, not import-exposed) skews milder, in line with its tighter Bear/Shock spread on the Consumer Sleeve tab.
... A39: 5 | DRIVER x SLEEVE MAPPING (direction of impact)
A40: Driver | B40: IQT-mirror | C40: Weapons | D40: Consumer / Value
A41: NATO / EU rearmament | B41: + | C41: + + | D41: 0
A42: US budget / Replicator / munitions | B42: + | C42: + + | D42: 0
A43: Classified / black-budget growth (+14% IC) | B43: + + (IQT = CIA arm) | C43: + + | D43: 0
A44: China modernization / decoupling | B44: + + | C44: + | D44: -
A45: Taiwan / TSMC shock | B45: + + (convex) | C45: + + (conflict demand) | D45: - (inflation/spend)
A46: CHIPS / reshoring capital | B46: + + | C46: + | D46: 0
A47: Higher-for-longer rates | B47: - (long-duration) | C47: - / 0 | D47: -
A48: USD strength / inflation | B48: 0 / - | C48: 0 | D48: - -
A49: Consumer spending cycle | B49: 0 | C49: 0 | D49: + + (primary driver)
A51: 6 | KEY TAKEAWAY
A52: • The supercycle is already loudly priced in PUBLIC comps (ITA +29% 1yr, SOXX +170% 1yr) — so the edge is NOT the theme being undiscovered; it is capturing it at PRIVATE / VC-stage entry before the public re-rate. That is why the scoreboard is KS-PME vs the ITA/SOXX basket, not vs SPX.
A53: • The barbell's logic: Weapons + IQT are both long the geopolitical supercycle (opex + capex legs) and both convex to a Taiwan/TSMC shock; Consumer is the uncorrelated ballast that carries near-term DPI and is the one sleeve hurt by the shock. Net holdco is long the supercycle with a spending-cycle diversifier.
...

Sheet Assumptions
A1: ASSUMPTIONS & INPUTS
A2: Blue = hardcoded input / lever. TSMC-Shock CAGR (col I) is computed on the Defense Supercycle tab. All $M.
A4: FUND TERMS (IQT-mirror sleeve)
A5: Committed capital ($M) | B5: ='Holdco Summary'!$B$6 -> 250 | C5: IQT sleeve = 1 of 3 holdco sub-funds (see Holdco Summary)
A6: Initial deployment ($M) | B6: 225 | C6: Memo — reserve embedded in retention
A7: Follow-on reserve ($M) | B7: 25 | C7: Pro-rata defense on winners
A8: Mgmt fee (% of committed / yr) | B8: 0.02 | C8: Charged over full vehicle life
A9: Carried interest (%) | B9: 0.2 | C9: Over pref, no catch-up modeled
A10: Preferred return (% comp.) | B10: 0.08 | C10: 8% compounded hurdle
A11: Retention @ 5yr | B11: 0.85 | C11: Ownership kept after dilution
A12: Retention @ 7yr | B12: 0.78
A13: Retention @ 10yr | B13: 0.68
A16: PORTFOLIO — ENTRY MARKS, CHECKS & GROWTH ASSUMPTIONS
A17: Company | B17: Entry post-$M | C17: Check ($M) | D17: Own % | E17: Tranche | F17: Base CAGR | G17: Bull CAGR | H17: Bear CAGR | I17: TSMC-Shock | J17: Valuation basis
A18: Substrate (anchor) | B18: 1050 | C18: 80 | D18: =C18/B18 -> 0.076190476 | E18: Anchor / growth | F18: 0.22 | G18: 0.34 | H18: -0.18 | I18: ='Defense Supercycle'!I24 -> 0.408 | J18: Est. >$1.0B post (Oct-25 round)
A19: EUV Tech | B19: 180 | C19: 30 | D19: =C19/B19 -> 0.16666667 | E19: Growth core | F19: 0.14 | G19: 0.26 | H19: 0.03 | I19: ='Defense Supercycle'!I25 -> 0.304 | J19: Est. — undisclosed (rev-gen niche)
A20: ThinTronics | B20: 120 | C20: 22.5 | D20: =C20/B20 -> 0.1875 | E20: Growth core | F20: 0.26 | G20: 0.38 | H20: -0.1 | I20: ='Defense Supercycle'!I26 -> 0.416 | J20: Est. — undisclosed + $50M CHIPS LOI
A21: EdgeCortix | B21: 350 | C21: 30.5 | D21: =C21/B21 -> 0.087142857 | E21: Growth core | F21: 0.24 | G21: 0.36 | H21: -0.08 | I21: ='Defense Supercycle'!I27 -> 0.264 | J21: Est. — undisclosed (>$110M raised)
A22: Syntiant | B22: 700 | C22: 31.5 | D22: =C22/B22 -> 0.045 | E22: Pre-IPO / liquid | F22: 0.16 | G22: 0.28 | H22: -0.02 | I22: ='Defense Supercycle'!I28 -> 0.22 | J22: $646M Dec-24; S-1 filed (SYTN)
A23: Infleqtion | B23: 3000 | C23: 25 | D23: =C23/B23 -> 0.0083333333 | E23: Public / liquid | F23: 0.15 | G23: 0.27 | H23: -0.1 | I23: ='Defense Supercycle'!I29 -> 0.222 | J23: Public NYSE:INFQ (~$3.0B mkt cap)
A24: Diraq | B24: 150 | C24: 14 | D24: =C24/B24 -> 0.093333333 | E24: Quantum venture | F24: 0.3 | G24: 0.42 | H24: -0.22 | I24: ='Defense Supercycle'!I30 -> 0.384 | J24: Never disclosed (unverified ~$107M)
A25: Mueon | B25: 65 | C25: 10 | D25: =C25/B25 -> 0.15384615 | E25: Seed optionality | F25: 0.32 | G25: 0.44 | H25: -0.28 | I25: ='Defense Supercycle'!I31 -> 0.396 | J25: Est. — undisclosed ($15.5M seed)
A26: DefendEye | B26: 50 | C26: 6.5 | D26: =C26/B26 -> 0.13 | E26: Seed optionality | F26: 0.28 | G26: 0.4 | H26: -0.25 | I26: ='Defense Supercycle'!I32 -> 0.216 | J26: Est. — undisclosed seed
A27: TOTAL DEPLOYED | C27: =SUM(C18:C26) -> 250
A28: ="Check: deployed capital (C27) "&TEXT(C27,"$#,##0")&"M vs committed (B5) "&TEXT(B5,"$#,##0")&"M — "&IF(ABS(C27-B5)<0.5,"OK","MISMATCH") -> Check: deployed capital (C27) $250M vs committed (B5) $250M — OK

Sheet Defense Supercycle
A1: DEFENSE SUPERCYCLE — STRATEGIC SCORING & SHOCK ENGINE
A2: Winning the US-China AI/semiconductor race + insulating against a Taiwan / loss-of-TSMC scenario. Blue = lever.
A4: STRATEGIC AXIS WEIGHTS (must sum to 100%)
A5: China AI/semi-race criticality | B5: 0.25 | C5: Advances US lead in AI compute / advanced nodes
A6: Taiwan / TSMC-insulation value | B6: 0.3 | C6: Reduces US dependence on Taiwan-based fabrication
A7: Government / defense embeddedness | B7: 0.15 | C7: IQT + DoD/DIU/DARPA/CHIPS pull
A8: CFIUS-clean / US-sovereign | B8: 0.15 | C8: US domicile & ownership; acquirable by US gov/primes
A9: Supply-chain chokepoint leverage | B9: 0.15 | C9: Sole/near-sole source at a critical node
A10: Sum (check = 100%) | B10: =SUM(B5:B9) -> 1
A12: TSMC-SHOCK CALIBRATION
A13: Pivot score (neutral) | B13: 2.5 | C13: Composite above pivot -> positive re-rating; below -> drag
A14: Premium per point (CAGR) | B14: 0.08 | C14: CAGR uplift per composite point above pivot, added to Base CAGR
A16: SCENARIO PROBABILITY WEIGHTS (must sum to 100%)
A17: Base | B17: 0.45
A18: Bull | B18: 0.25
A19: Bear | B19: 0.15
A20: TSMC-Shock | B20: 0.15
A21: Sum (check = 100%) | B21: =SUM(B17:B20) -> 1
A22: STRATEGIC SCORING MATRIX (1 = low, 5 = high; blue = lever)
A23: Company | B23: China Race | C23: TSMC Insul. | D23: Gov/Defense | E23: CFIUS-Clean | F23: Chokepoint | G23: Composite | H23: Shock prem. | I23: Shock CAGR
A24: Substrate (anchor) | B24: 5 | C24: 5 | D24: 4 | E24: 5 | F24: 5 | G24: =B24*'Defense Supercycle'!$B$5+C24*'Defense Supercycle'!$B$6+D24*'Defense Supercycle'!$B$7+E24*'Defense Supercycle'!$B$8+F24*'Defense Supercycle'!$B$9 -> 4.85 | H24: =(G24-'Defense Supercycle'!$B$13)*'Defense Supercycle'!$B$14 -> 0.188 | I24: =Assumptions!F18+H24 -> 0.408
A25: EUV Tech | B25: 5 | C25: 4 | D25: 4 | E25: 5 | F25: 5 | G25: =B25*'Defense Supercycle'!$B$5+C25*'Defense Supercycle'!$B$6+D25*'Defense Supercycle'!$B$7+E25*'Defense Supercycle'!$B$8+F25*'Defense Supercycle'!$B$9 -> 4.55 | H25: =(G25-'Defense Supercycle'!$B$13)*'Defense Supercycle'!$B$14 -> 0.164 | I25: =Assumptions!F19+H25 -> 0.304
A26: ThinTronics | B26: 4 | C26: 5 | D26: 4 | E26: 5 | F26: 4 | G26: =B26*'Defense Supercycle'!$B$5+C26*'Defense Supercycle'!$B$6+D26*'Defense Supercycle'!$B$7+E26*'Defense Supercycle'!$B$8+F26*'Defense Supercycle'!$B$9 -> 4.45 | H26: =(G26-'Defense Supercycle'!$B$13)*'Defense Supercycle'!$B$14 -> 0.156 | I26: =Assumptions!F20+H26 -> 0.416
A27: EdgeCortix | B27: 4 | C27: 2 | D27: 4 | E27: 2 | F27: 2 | G27: =B27*'Defense Supercycle'!$B$5+C27*'Defense Supercycle'!$B$6+D27*'Defense Supercycle'!$B$7+E27*'Defense Supercycle'!$B$8+F27*'Defense Supercycle'!$B$9 -> 2.8 | H27: =(G27-'Defense Supercycle'!$B$13)*'Defense Supercycle'!$B$14 -> 0.024 | I27: =Assumptions!F21+H27 -> 0.264
A28: Syntiant | B28: 4 | C28: 2 | D28: 4 | E28: 5 | F28: 2 | G28: =B28*'Defense Supercycle'!$B$5+C28*'Defense Supercycle'!$B$6+D28*'Defense Supercycle'!$B$7+E28*'Defense Supercycle'!$B$8+F28*'Defense Supercycle'!$B$9 -> 3.25 | H28: =(G28-'Defense Supercycle'!$B$13)*'Defense Supercycle'!$B$14 -> 0.06 | I28: =Assumptions!F22+H28 -> 0.22
A29: Infleqtion | B29: 4 | C29: 2 | D29: 4 | E29: 5 | F29: 3 | G29: =B29*'Defense Supercycle'!$B$5+C29*'Defense Supercycle'!$B$6+D29*'Defense Supercycle'!$B$7+E29*'Defense Supercycle'!$B$8+F29*'Defense Supercycle'!$B$9 -> 3.4 | H29: =(G29-'Defense Supercycle'!$B$13)*'Defense Supercycle'!$B$14 -> 0.072 | I29: =Assumptions!F23+H29 -> 0.222
A30: Diraq | B30: 4 | C30: 4 | D30: 4 | E30: 2 | F30: 3 | G30: =B30*'Defense Supercycle'!$B$5+C30*'Defense Supercycle'!$B$6+D30*'Defense Supercycle'!$B$7+E30*'Defense Supercycle'!$B$8+F30*'Defense Supercycle'!$B$9 -> 3.55 | H30: =(G30-'Defense Supercycle'!$B$13)*'Defense Supercycle'!$B$14 -> 0.084 | I30: =Assumptions!F24+H30 -> 0.384
A31: Mueon | B31: 3 | C31: 3 | D31: 4 | E31: 5 | F31: 3 | G31: =B31*'Defense Supercycle'!$B$5+C31*'Defense Supercycle'!$B$6+D31*'Defense Supercycle'!$B$7+E31*'Defense Supercycle'!$B$8+F31*'Defense Supercycle'!$B$9 -> 3.45 | H31: =(G31-'Defense Supercycle'!$B$13)*'Defense Supercycle'!$B$14 -> 0.076 | I31: =Assumptions!F25+H31 -> 0.396
A32: DefendEye | B32: 2 | C32: 1 | D32: 3 | E32: 2 | F32: 1 | G32: =B32*'Defense Supercycle'!$B$5+C32*'Defense Supercycle'!$B$6+D32*'Defense Supercycle'!$B$7+E32*'Defense Supercycle'!$B$8+F32*'Defense Supercycle'!$B$9 -> 1.7 | H32: =(G32-'Defense Supercycle'!$B$13)*'Defense Supercycle'!$B$14 -> -0.064 | I32: =Assumptions!F26+H32 -> 0.216
A33: Avg / weighted | G33: =AVERAGE(G24:G32) -> 3.5555556
A35: SCENARIO NARRATIVE — TSMC SHOCK / TAIWAN CONTINGENCY
A36: • Trigger: a Taiwan blockade/quarantine, kinetic event, or hard US-China tech decoupling that removes or severely constrains access to TSMC's leading-edge capacity — the single point of failure in the AI-compute supply chain.
A37: • Winners (large re-rate): the US sovereign-chokepoint names. Substrate (domestic X-ray litho / fabs), EUV Tech (at-wavelength EUV metrology — no fab qualifies without it), ThinTronics (US ABF/substrate materials vs Japan's Ajinomoto monopoly). Onshoring becomes a national-security imperative; demand + pricing power inflect.
A38: • Partial winners: Mueon (US advanced packaging / rack density), Infleqtion & Diraq (quantum race convexity — the 'next' compute paradigm if classical leading-edge is contested), Syntiant (US-fab-flexible edge inference).
A39: • Laggards / drag: EdgeCortix (Japan HQ + TSMC-Kumamoto fab exposure, near-term supply hit and CFIUS ceiling) and DefendEye (foreign-nexus, low semiconductor-sovereignty relevance).
A40: • Portfolio design implication: the book is intentionally overweight the sovereign core, so a tail event that would hurt a generic tech portfolio is where this one is most convex. That asymmetry is the thesis.
A42: IQT WARTIME-FUNCTION MAP — SUBSTRATE-ANCHORED SLEEVE (from uploaded IQT strategic analysis)
A43: Strategic cluster | B43: Holdings | D43: Wartime function / why IQT funds it
A44: TSMC-alternative: packaging & substrates | B44: Substrate, ThinTronics, EUV Tech | D44: Build & package chips domestically if Taiwan is blockaded — X-ray litho (Substrate), CoWoS-alternative insulators for advanced packaging (ThinTronics, + $50M CHIPS LOI Jul-26), at-wavelength EUV metrology to keep domestic litho running (EUV Tech).
A45: Denied-environment edge AI | B45: Syntiant, EdgeCortix | D45: Onboard AI for autonomous weapons when GPS / cloud / comms are jammed by PLA electronic warfare — ultra-low-power SWaP-constrained inference on drones, missiles, naval sensors. Syntiant signed a Nov-2025 IQT strategic technology-development agreement; EdgeCortix's DNA accelerator targets defense/aerospace at the tactical edge.
...

Sheet Allocation
A1: ALLOCATION & POSITION STRUCTURE
A2: Green = linked. Composite pulled from Defense Supercycle tab. Ownership >15% = significant minority (seek board seat / observer).
A4: Company | B4: Check ($M) | C4: Own % | D4: % Fund | E4: Supercycle | F4: Tranche | G4: Domicile | H4: Structuring / diligence flag
A5: =Assumptions!A18 -> Substrate (anchor) | B5: =Assumptions!C18 -> 80 | C5: =Assumptions!D18 -> 0.076190476 | D5: =Assumptions!C18/Assumptions!$B$5 -> 0.32 | E5: ='Defense Supercycle'!G24 -> 4.85 | F5: =Assumptions!E18 -> Anchor / growth | G5: USA (SF, CA) | H5: Anchor. Binary tech risk — capped ~32% of fund; the core sovereign-litho bet.
A6: =Assumptions!A19 -> EUV Tech | B6: =Assumptions!C19 -> 30 | C6: =Assumptions!D19 -> 0.16666667 | D6: =Assumptions!C19/Assumptions!$B$5 -> 0.12 | E6: ='Defense Supercycle'!G25 -> 4.55 | F6: =Assumptions!E19 -> Growth core | G6: USA (CA) | H6: Rev-generating niche leader — best risk-adjusted. ~17% stake = significant minority; seek a board seat.
A7: =Assumptions!A20 -> ThinTronics | B7: =Assumptions!C20 -> 22.5 | C7: =Assumptions!D20 -> 0.1875 | D7: =Assumptions!C20/Assumptions!$B$5 -> 0.09 | E7: ='Defense Supercycle'!G26 -> 4.45 | F7: =Assumptions!E20 -> Growth core | G7: USA (CA) | H7: CHIPS $50M LOI catalyst. ~19% stake = significant minority; likely primary + secondary blend.
A8: =Assumptions!A21 -> EdgeCortix | B8: =Assumptions!C21 -> 30.5 | C8: =Assumptions!D21 -> 0.087142857 | D8: =Assumptions!C21/Assumptions!$B$5 -> 0.122 | E8: ='Defense Supercycle'!G27 -> 2.8 | F8: =Assumptions!E21 -> Growth core | G8: JAPAN (Tokyo) | H8: CFIUS/allied flag — minority only. Renesas natural acquirer. TSMC-Kumamoto fab exposure.
A9: =Assumptions!A22 -> Syntiant | B9: =Assumptions!C22 -> 31.5 | C9: =Assumptions!D22 -> 0.045 | D9: =Assumptions!C22/Assumptions!$B$5 -> 0.126 | E9: ='Defense Supercycle'!G28 -> 3.25 | F9: =Assumptions!E22 -> Pre-IPO / liquid | G9: USA (CA) | H9: Pre-IPO secondary or SYTN cornerstone. Watch pricing vs $646M Dec-24 mark.
A10: =Assumptions!A23 -> Infleqtion | B10: =Assumptions!C23 -> 25 | C10: =Assumptions!D23 -> 0.0083333333 | D10: =Assumptions!C23/Assumptions!$B$5 -> 0.1 | E10: ='Defense Supercycle'!G29 -> 3.4 | F10: =Assumptions!E23 -> Public / liquid | G10: USA (CO) | H10: Public (INFQ). PIPE/secondary. Listed quantum benchmark for Diraq.
A11: =Assumptions!A24 -> Diraq | B11: =Assumptions!C24 -> 14 | C11: =Assumptions!D24 -> 0.093333333 | D11: =Assumptions!C24/Assumptions!$B$5 -> 0.056 | E11: ='Defense Supercycle'!G30 -> 3.55 | F11: =Assumptions!E24 -> Quantum venture | G11: AUSTRALIA (Sydney) | H11: Allied flag — minority. NRFC sovereignty covenants. AUKUS-aligned quantum optionality.
A12: =Assumptions!A25 -> Mueon | B12: =Assumptions!C25 -> 10 | C12: =Assumptions!D25 -> 0.15384615 | D12: =Assumptions!C25/Assumptions!$B$5 -> 0.04 | E12: ='Defense Supercycle'!G31 -> 3.45 | F12: =Assumptions!E25 -> Seed optionality | G12: USA (OR) | H12: Seed. Milestone-gated. Needs a shipping Cubelet design-win to scale exposure.
A13: =Assumptions!A26 -> DefendEye | B13: =Assumptions!C26 -> 6.5 | C13: =Assumptions!D26 -> 0.13 | D13: =Assumptions!C26/Assumptions!$B$5 -> 0.026 | E13: ='Defense Supercycle'!G32 -> 1.7 | F13: =Assumptions!E26 -> Seed optionality | G13: USA (FL)+POLAND | H13: EU cap table + Krakow mfg — Blue UAS/NDAA provenance diligence before US-defense thesis.
A14: TOTAL | B14: =SUM(B5:B13) -> 250 | D14: =SUM(D5:D13) -> 1

Sheet Portfolio Returns
A1: PORTFOLIO RETURNS BY HOLD & SCENARIO
A2: Proceeds = Check x (1+CAGR)^Hold x Retention. MOIC = Proceeds/Check. Gross IRR = MOIC^(1/Hold)-1.
A4: 5-YEAR HOLD VEHICLE
A5: Company | B5: Check ($M) | C5: Base $ | D5: Base MOIC | E5: Base IRR | F5: Bull $ | G5: Bull MOIC | H5: Bull IRR | I5: Bear $ | J5: Bear MOIC | K5: Bear IRR | L5: Shock $ | M5: Shock MOIC | N5: Shock IRR
A6: =Assumptions!A18 -> Substrate (anchor) | B6: =Assumptions!C18 -> 80 | C6: =Assumptions!C18*(1+Assumptions!F18)^5*Assumptions!$B$11 -> 183.78416 | D6: =C6/B6 -> 2.2973019 | E6: =(C6/B6)^(1/5)-1 -> 0.18098292 | F6: =Assumptions!C18*(1+Assumptions!G18)^5*Assumptions!$B$11 -> 293.78722 | G6: =F6/B6 -> 3.6723403 | H6: =(F6/B6)^(1/5)-1 -> 0.29714517 | I6: =Assumptions!C18*(1+Assumptions!H18)^5*Assumptions!$B$11 -> 25.210309 | J6: =I6/B6 -> 0.31512887 | K6: =(I6/B6)^(1/5)-1 -> -0.2062246 | L6: =Assumptions!C18*(1+Assumptions!I18)^5*Assumptions!$B$11 -> 376.28958 | M6: =L6/B6 -> 4.7036197 | N6: =(L6/B6)^(1/5)-1 -> 0.36297045
A7: =Assumptions!A19 -> EUV Tech | B7: =Assumptions!C19 -> 30 | C7: =Assumptions!C19*(1+Assumptions!F19)^5*Assumptions!$B$11 -> 49.098072 | D7: =C7/B7 -> 1.6366024 | E7: =(C7/B7)^(1/5)-1 -> 0.10354141 | F7: =Assumptions!C19*(1+Assumptions!G19)^5*Assumptions!$B$11 -> 80.982822 | G7: =F7/B7 -> 2.6994274 | H7: =(F7/B7)^(1/5)-1 -> 0.21970367 | I7: =Assumptions!C19*(1+Assumptions!H19)^5*Assumptions!$B$11 -> 29.561489 | J7: =I7/B7 -> 0.98538296 | K7: =(I7/B7)^(1/5)-1 -> -0.0029406514 | L7: =Assumptions!C19*(1+Assumptions!I19)^5*Assumptions!$B$11 -> 96.145317 | M7: =L7/B7 -> 3.2048439 | N7: =(L7/B7)^(1/5)-1 -> 0.2622965
A8: =Assumptions!A20 -> ThinTronics | B8: =Assumptions!C20 -> 22.5 | C8: =Assumptions!C20*(1+Assumptions!F20)^5*Assumptions!$B$11 -> 60.737116 | D8: =C8/B8 -> 2.6994274 | E8: =(C8/B8)^(1/5)-1 -> 0.21970367 | F8: =Assumptions!C20*(1+Assumptions!G20)^5*Assumptions!$B$11 -> 95.718719 | G8: =F8/B8 -> 4.2541653 | H8: =(F8/B8)^(1/5)-1 -> 0.33586592 | I8: =Assumptions!C20*(1+Assumptions!H20)^5*Assumptions!$B$11 -> 11.293121 | J8: =I8/B8 -> 0.5019165 | K8: =(I8/B8)^(1/5)-1 -> -0.12878309 | L8: =Assumptions!C20*(1+Assumptions!I20)^5*Assumptions!$B$11 -> 108.87238 | M8: =L8/B8 -> 4.8387724 | N8: =(L8/B8)^(1/5)-1 -> 0.3707146
A9: =Assumptions!A21 -> EdgeCortix | B9: =Assumptions!C21 -> 30.5 | C9: =Assumptions!C21*(1+Assumptions!F21)^5*Assumptions!$B$11 -> 76.00238 | D9: =C9/B9 -> 2.4918813 | E9: =(C9/B9)^(1/5)-1 -> 0.20034329 | F9: =Assumptions!C21*(1+Assumptions!G21)^5*Assumptions!$B$11 -> 120.61833 | G9: =F9/B9 -> 3.9546993 | H9: =(F9/B9)^(1/5)-1 -> 0.31650555 | I9: =Assumptions!C21*(1+Assumptions!H21)^5*Assumptions!$B$11 -> 17.086688 | J9: =I9/B9 -> 0.56021929 | K9: =(I9/B9)^(1/5)-1 -> -0.10942272 | L9: =Assumptions!C21*(1+Assumptions!I21)^5*Assumptions!$B$11 -> 83.647725 | M9: =L9/B9 -> 2.7425484 | N9: =(L9/B9)^(1/5)-1 -> 0.22357574
A10: =Assumptions!A22 -> Syntiant | B10: =Assumptions!C22 -> 31.5 | C10: =Assumptions!C22*(1+Assumptions!F22)^5*Assumptions!$B$11 -> 56.236648 | D10: =C10/B10 -> 1.7852904 | E10: =(C10/B10)^(1/5)-1 -> 0.12290179 | F10: =Assumptions!C22*(1+Assumptions!G22)^5*Assumptions!$B$11 -> 91.998199 | G10: =F10/B10 -> 2.9205778 | H10: =(F10/B10)^(1/5)-1 -> 0.23906404 | I10: =Assumptions!C22*(1+Assumptions!H22)^5*Assumptions!$B$11 -> 24.202479 | J10: =I10/B10 -> 0.76833268 | K10: =(I10/B10)^(1/5)-1 -> -0.051341591 | L10: =Assumptions!C22*(1+Assumptions!I22)^5*Assumptions!$B$11 -> 72.365011 | M10: =L10/B10 -> 2.2973019 | N10: =(L10/B10)^(1/5)-1 -> 0.18098292
A11: =Assumptions!A23 -> Infleqtion | B11: =Assumptions!C23 -> 25 | C11: =Assumptions!C23*(1+Assumptions!F23)^5*Assumptions!$B$11 -> 42.74134 | D11: =C11/B11 -> 1.7096536 | E11: =(C11/B11)^(1/5)-1 -> 0.1132216 | F11: =Assumptions!C23*(1+Assumptions!G23)^5*Assumptions!$B$11 -> 70.206535 | G11: =F11/B11 -> 2.8082614 | H11: =(F11/B11)^(1/5)-1 -> 0.22938386 | I11: =Assumptions!C23*(1+Assumptions!H23)^5*Assumptions!$B$11 -> 12.547913 | J11: =I11/B11 -> 0.5019165 | K11: =(I11/B11)^(1/5)-1 -> -0.12878309 | L11: =Assumptions!C23*(1+Assumptions!I23)^5*Assumptions!$B$11 -> 57.904853 | M11: =L11/B11 -> 2.3161941 | N11: =(L11/B11)^(1/5)-1 -> 0.18291896
A12: =Assumptions!A24 -> Diraq | B12: =Assumptions!C24 -> 14 | C12: =Assumptions!C24*(1+Assumptions!F24)^5*Assumptions!$B$11 -> 44.183867 | D12: =C12/B12 -> 3.1559905 | E12: =(C12/B12)^(1/5)-1 -> 0.25842442 | F12: =Assumptions!C24*(1+Assumptions!G24)^5*Assumptions!$B$11 -> 68.705054 | G12: =F12/B12 -> 4.9075038 | H12: =(F12/B12)^(1/5)-1 -> 0.37458667 | I12: =Assumptions!C24*(1+Assumptions!H24)^5*Assumptions!$B$11 -> 3.4357375 | J12: =I12/B12 -> 0.24540982 | K12: =(I12/B12)^(1/5)-1 -> -0.24494535 | L12: =Assumptions!C24*(1+Assumptions!I24)^5*Assumptions!$B$11 -> 60.426496 | M12: =L12/B12 -> 4.3161783 | N12: =(L12/B12)^(1/5)-1 -> 0.339738
A13: =Assumptions!A25 -> Mueon | B13: =Assumptions!C25 -> 10 | C13: =Assumptions!C25*(1+Assumptions!F25)^5*Assumptions!$B$11 -> 34.063446 | D13: =C13/B13 -> 3.4063446 | E13: =(C13/B13)^(1/5)-1 -> 0.2777848 | F13: =Assumptions!C25*(1+Assumptions!G25)^5*Assumptions!$B$11 -> 52.62976 | G13: =F13/B13 -> 5.262976 | H13: =(F13/B13)^(1/5)-1 -> 0.39394705 | I13: =Assumptions!C25*(1+Assumptions!H25)^5*Assumptions!$B$11 -> 1.64468 | J13: =I13/B13 -> 0.164468 | K13: =(I13/B13)^(1/5)-1 -> -0.30302647 | L13: =Assumptions!C25*(1+Assumptions!I25)^5*Assumptions!$B$11 -> 45.065689 | M13: =L13/B13 -> 4.5065689 | N13: =(L13/B13)^(1/5)-1 -> 0.35135422
A14: =Assumptions!A26 -> DefendEye | B14: =Assumptions!C26 -> 6.5 | C14: =Assumptions!C26*(1+Assumptions!F26)^5*Assumptions!$B$11 -> 18.983755 | D14: =C14/B14 -> 2.9205778 | E14: =(C14/B14)^(1/5)-1 -> 0.23906404 | F14: =Assumptions!C26*(1+Assumptions!G26)^5*Assumptions!$B$11 -> 29.714776 | G14: =F14/B14 -> 4.571504 | H14: =(F14/B14)^(1/5)-1 -> 0.3552263 | I14: =Assumptions!C26*(1+Assumptions!H26)^5*Assumptions!$B$11 -> 1.3111084 | J14: =I14/B14 -> 0.20170898 | K14: =(I14/B14)^(1/5)-1 -> -0.27398591 | L14: =Assumptions!C26*(1+Assumptions!I26)^5*Assumptions!$B$11 -> 14.689268 | M14: =L14/B14 -> 2.2598874 | N14: =(L14/B14)^(1/5)-1 -> 0.17711084
A15: FUND TOTAL | B15: =SUM(B6:B14) -> 250 | C15: =SUM(C6:C14) -> 565.83078 | D15: =C15/B15 -> 2.2633231 | E15: =(C15/B15)^(1/5)-1 -> 0.17746854 | F15: =SUM(F6:F14) -> 904.36142 | G15: =F15/B15 -> 3.6174457 | H15: =(F15/B15)^(1/5)-1 -> 0.29324379 | I15: =SUM(I6:I14) -> 126.29353 | J15: =I15/B15 -> 0.5051741 | K15: =(I15/B15)^(1/5)-1 -> -0.12765512 | L15: =SUM(L6:L14) -> 915.40631 | M15: =L15/B15 -> 3.6616253 | N15: =(L15/B15)^(1/5)-1 -> 0.29638733
A18: 7-YEAR HOLD VEHICLE
A19: Company | B19: Check ($M) | C19: Base $ | D19: Base MOIC | E19: Base IRR | F19: Bull $ | G19: Bull MOIC | H19: Bull IRR | I19: Bear $ | J19: Bear MOIC | K19: Bear IRR | L19: Shock $ | M19: Shock MOIC | N19: Shock IRR
A20: =Assumptions!A18 -> Substrate (anchor) | B20: =Assumptions!C18 -> 80 | C20: =Assumptions!C18*(1+Assumptions!F18)^7*Assumptions!$B$12 -> 251.01716 | D20: =C20/B20 -> 3.1377144 | E20: =(C20/B20)^(1/7)-1 -> 0.17745624 | F20: =Assumptions!C18*(1+Assumptions!G18)^7*Assumptions!$B$12 -> 484.08116 | G20: =F20/B20 -> 6.0510145 | H20: =(F20/B20)^(1/7)-1 -> 0.2932716 | I20: =Assumptions!C18*(1+Assumptions!H18)^7*Assumptions!$B$12 -> 15.555413 | J20: =I20/B20 -> 0.19444267 | K20: =(I20/B20)^(1/7)-1 -> -0.20859499 | L20: =Assumptions!C18*(1+Assumptions!I18)^7*Assumptions!$B$12 -> 684.54685 | M20: =L20/B20 -> 8.5568356 | N20: =(L20/B20)^(1/7)-1 -> 0.35890031
A21: =Assumptions!A19 -> EUV Tech | B21: =Assumptions!C19 -> 30 | C21: =Assumptions!C19*(1+Assumptions!F19)^7*Assumptions!$B$12 -> 58.55309 | D21: =C21/B21 -> 1.9517697 | E21: =(C21/B21)^(1/7)-1 -> 0.10024599 | F21: =Assumptions!C19*(1+Assumptions!G19)^7*Assumptions!$B$12 -> 117.98035 | G21: =F21/B21 -> 3.9326783 | H21: =(F21/B21)^(1/7)-1 -> 0.21606136 | I21: =Assumptions!C19*(1+Assumptions!H19)^7*Assumptions!$B$12 -> 28.779048 | J21: =I21/B21 -> 0.95930162 | K21: =(I21/B21)^(1/7)-1 -> -0.0059180963 | L21: =Assumptions!C19*(1+Assumptions!I19)^7*Assumptions!$B$12 -> 150.0234 | M21: =L21/B21 -> 5.0007799 | N21: =(L21/B21)^(1/7)-1 -> 0.25852699
A22: =Assumptions!A20 -> ThinTronics | B22: =Assumptions!C20 -> 22.5 | C22: =Assumptions!C20*(1+Assumptions!F20)^7*Assumptions!$B$12 -> 88.485261 | D22: =C22/B22 -> 3.9326783 | E22: =(C22/B22)^(1/7)-1 -> 0.21606136 | F22: =Assumptions!C20*(1+Assumptions!G20)^7*Assumptions!$B$12 -> 167.27488 | G22: =F22/B22 -> 7.4344391 | H22: =(F22/B22)^(1/7)-1 -> 0.33187673 | I22: =Assumptions!C20*(1+Assumptions!H20)^7*Assumptions!$B$12 -> 8.3941106 | J22: =I22/B22 -> 0.37307158 | K22: =(I22/B22)^(1/7)-1 -> -0.13138474 | L22: =Assumptions!C20*(1+Assumptions!I20)^7*Assumptions!$B$12 -> 200.31796 | M22: =L22/B22 -> 8.9030206 | N22: =(L22/B22)^(1/7)-1 -> 0.36662134
A23: =Assumptions!A21 -> EdgeCortix | B23: =Assumptions!C21 -> 30.5 | C23: =Assumptions!C21*(1+Assumptions!F21)^7*Assumptions!$B$12 -> 107.23739 | D23: =C23/B23 -> 3.51598 | E23: =(C23/B23)^(1/7)-1 -> 0.1967588 | F23: =Assumptions!C21*(1+Assumptions!G21)^7*Assumptions!$B$12 -> 204.72308 | G23: =F23/B23 -> 6.712232 | H23: =(F23/B23)^(1/7)-1 -> 0.31257416 | I23: =Assumptions!C21*(1+Assumptions!H21)^7*Assumptions!$B$12 -> 13.271171 | J23: =I23/B23 -> 0.43512035 | K23: =(I23/B23)^(1/7)-1 -> -0.11208218 | L23: =Assumptions!C21*(1+Assumptions!I21)^7*Assumptions!$B$12 -> 122.63769 | M23: =L23/B23 -> 4.0209079 | N23: =(L23/B23)^(1/7)-1 -> 0.21992187
A24: =Assumptions!A22 -> Syntiant | B24: =Assumptions!C22 -> 31.5 | C24: =Assumptions!C22*(1+Assumptions!F22)^7*Assumptions!$B$12 -> 69.440219 | D24: =C24/B24 -> 2.2044514 | E24: =(C24/B24)^(1/7)-1 -> 0.11954855 | F24: =Assumptions!C22*(1+Assumptions!G22)^7*Assumptions!$B$12 -> 138.3168 | G24: =F24/B24 -> 4.3910096 | H24: =(F24/B24)^(1/7)-1 -> 0.23536392 | I24: =Assumptions!C22*(1+Assumptions!H22)^7*Assumptions!$B$12 -> 21.329844 | J24: =I24/B24 -> 0.67713792 | K24: =(I24/B24)^(1/7)-1 -> -0.054174499 | L24: =Assumptions!C22*(1+Assumptions!I22)^7*Assumptions!$B$12 -> 98.838005 | M24: =L24/B24 -> 3.1377144 | N24: =(L24/B24)^(1/7)-1 -> 0.17745624
A25: =Assumptions!A23 -> Infleqtion | B25: =Assumptions!C23 -> 25 | C25: =Assumptions!C23*(1+Assumptions!F23)^7*Assumptions!$B$12 -> 51.870388 | D25: =C25/B25 -> 2.0748155 | E25: =(C25/B25)^(1/7)-1 -> 0.10989727 | F25: =Assumptions!C23*(1+Assumptions!G23)^7*Assumptions!$B$12 -> 103.91079 | G25: =F25/B25 -> 4.1564317 | H25: =(F25/B25)^(1/7)-1 -> 0.22571264 | I25: =Assumptions!C23*(1+Assumptions!H23)^7*Assumptions!$B$12 -> 9.3267896 | J25: =I25/B25 -> 0.37307158 | K25: =(I25/B25)^(1/7)-1 -> -0.13138474 | L25: =Assumptions!C23*(1+Assumptions!I23)^7*Assumptions!$B$12 -> 79.347464 | M25: =L25/B25 -> 3.1738986 | N25: =(L25/B25)^(1/7)-1 -> 0.17938649
A26: =Assumptions!A24 -> Diraq | B26: =Assumptions!C24 -> 14 | C26: =Assumptions!C24*(1+Assumptions!F24)^7*Assumptions!$B$12 -> 68.521381 | D26: =C26/B26 -> 4.8943843 | E26: =(C26/B26)^(1/7)-1 -> 0.25466648 | F26: =Assumptions!C24*(1+Assumptions!G24)^7*Assumptions!$B$12 -> 127.12795 | G26: =F26/B26 -> 9.080568 | H26: =(F26/B26)^(1/7)-1 -> 0.37048185 | I26: =Assumptions!C24*(1+Assumptions!H24)^7*Assumptions!$B$12 -> 1.9181601 | J26: =I26/B26 -> 0.13701144 | K26: =(I26/B26)^(1/7)-1 -> -0.24720011 | L26: =Assumptions!C24*(1+Assumptions!I24)^7*Assumptions!$B$12 -> 106.21241 | M26: =L26/B26 -> 7.5866008 | N26: =(L26/B26)^(1/7)-1 -> 0.33573724
A27: =Assumptions!A25 -> Mueon | B27: =Assumptions!C25 -> 10 | C27: =Assumptions!C25*(1+Assumptions!F25)^7*Assumptions!$B$12 -> 54.464324 | D27: =C27/B27 -> 5.4464324 | E27: =(C27/B27)^(1/7)-1 -> 0.27396904 | F27: =Assumptions!C25*(1+Assumptions!G25)^7*Assumptions!$B$12 -> 100.14564 | G27: =F27/B27 -> 10.014564 | H27: =(F27/B27)^(1/7)-1 -> 0.38978441 | I27: =Assumptions!C25*(1+Assumptions!H25)^7*Assumptions!$B$12 -> 0.78238781 | J27: =I27/B27 -> 0.078238781 | K27: =(I27/B27)^(1/7)-1 -> -0.3051078 | L27: =Assumptions!C25*(1+Assumptions!I25)^7*Assumptions!$B$12 -> 80.592111 | M27: =L27/B27 -> 8.0592111 | N27: =(L27/B27)^(1/7)-1 -> 0.34731877
A28: =Assumptions!A26 -> DefendEye | B28: =Assumptions!C26 -> 6.5 | C28: =Assumptions!C26*(1+Assumptions!F26)^7*Assumptions!$B$12 -> 28.541563 | D28: =C28/B28 -> 4.3910096 | E28: =(C28/B28)^(1/7)-1 -> 0.23536392 | F28: =Assumptions!C26*(1+Assumptions!G26)^7*Assumptions!$B$12 -> 53.444647 | G28: =F28/B28 -> 8.2222533 | H28: =(F28/B28)^(1/7)-1 -> 0.35117929 | I28: =Assumptions!C26*(1+Assumptions!H26)^7*Assumptions!$B$12 -> 0.67676331 | J28: =I28/B28 -> 0.10411743 | K28: =(I28/B28)^(1/7)-1 -> -0.27615395 | L28: =Assumptions!C26*(1+Assumptions!I26)^7*Assumptions!$B$12 -> 19.931638 | M28: =L28/B28 -> 3.0664058 | N28: =(L28/B28)^(1/7)-1 -> 0.17359572
A29: FUND TOTAL | B29: =SUM(B20:B28) -> 250 | C29: =SUM(C20:C28) -> 778.13077 | D29: =C29/B29 -> 3.1125231 | E29: =(C29/B29)^(1/7)-1 -> 0.1761011 | F29: =SUM(F20:F28) -> 1497.0053 | G29: =F29/B29 -> 5.9880212 | H29: =(F29/B29)^(1/7)-1 -> 0.29133962 | I29: =SUM(I20:I28) -> 100.03369 | J29: =I29/B29 -> 0.40013475 | K29: =(I29/B29)^(1/7)-1 -> -0.12265112 | L29: =SUM(L20:L28) -> 1542.4475 | M29: =L29/B29 -> 6.1697901 | N29: =(L29/B29)^(1/7)-1 -> 0.29686799
A32: 10-YEAR HOLD VEHICLE
A33: Company | B33: Check ($M) | C33: Base $ | D33: Base MOIC | E33: Base IRR | F33: Bull $ | G33: Bull MOIC | H33: Bull IRR | I33: Bear $ | J33: Bear MOIC | K33: Bear IRR | L33: Shock $ | M33: Shock MOIC | N33: Shock IRR
A34: =Assumptions!A18 -> Substrate (anchor) | B34: =Assumptions!C18 -> 80 | C34: =Assumptions!C18*(1+Assumptions!F18)^10*Assumptions!$B$13 -> 397.37195 | D34: =C34/B34 -> 4.9671494 | E34: =(C34/B34)^(1/10)-1 -> 0.17384491 | F34: =Assumptions!C18*(1+Assumptions!G18)^10*Assumptions!$B$13 -> 1015.4227 | G34: =F34/B34 -> 12.692784 | H34: =(F34/B34)^(1/10)-1 -> 0.28930507 | I34: =Assumptions!C18*(1+Assumptions!H18)^10*Assumptions!$B$13 -> 7.4771729 | J34: =I34/B34 -> 0.093464661 | K34: =(I34/B34)^(1/10)-1 -> -0.21102227 | L34: =Assumptions!C18*(1+Assumptions!I18)^10*Assumptions!$B$13 -> 1665.8099 | M34: =L34/B34 -> 20.822624 | N34: =(L34/B34)^(1/10)-1 -> 0.35473249
A35: =Assumptions!A19 -> EUV Tech | B35: =Assumptions!C19 -> 30 | C35: =Assumptions!C19*(1+Assumptions!F19)^10*Assumptions!$B$13 -> 75.627315 | D35: =C35/B35 -> 2.5209105 | E35: =(C35/B35)^(1/10)-1 -> 0.096871475 | F35: =Assumptions!C19*(1+Assumptions!G19)^10*Assumptions!$B$13 -> 205.748 | G35: =F35/B35 -> 6.8582666 | H35: =(F35/B35)^(1/10)-1 -> 0.21233163 | I35: =Assumptions!C19*(1+Assumptions!H19)^10*Assumptions!$B$13 -> 27.415894 | J35: =I35/B35 -> 0.91386314 | K35: =(I35/B35)^(1/10)-1 -> -0.0089670003 | L35: =Assumptions!C19*(1+Assumptions!I19)^10*Assumptions!$B$13 -> 290.0054 | M35: =L35/B35 -> 9.6668466 | N35: =(L35/B35)^(1/10)-1 -> 0.25466702
A36: =Assumptions!A20 -> ThinTronics | B36: =Assumptions!C20 -> 22.5 | C36: =Assumptions!C20*(1+Assumptions!F20)^10*Assumptions!$B$13 -> 154.311 | D36: =C36/B36 -> 6.8582666 | E36: =(C36/B36)^(1/10)-1 -> 0.21233163 | F36: =Assumptions!C20*(1+Assumptions!G20)^10*Assumptions!$B$13 -> 383.25012 | G36: =F36/B36 -> 17.033338 | H36: =(F36/B36)^(1/10)-1 -> 0.32779179 | I36: =Assumptions!C20*(1+Assumptions!H20)^10*Assumptions!$B$13 -> 5.3347801 | J36: =I36/B36 -> 0.23710134 | K36: =(I36/B36)^(1/10)-1 -> -0.13404884 | L36: =Assumptions!C20*(1+Assumptions!I20)^10*Assumptions!$B$13 -> 495.81991 | M36: =L36/B36 -> 22.036441 | N36: =(L36/B36)^(1/10)-1 -> 0.36242983
A37: =Assumptions!A21 -> EdgeCortix | B37: =Assumptions!C21 -> 30.5 | C37: =Assumptions!C21*(1+Assumptions!F21)^10*Assumptions!$B$13 -> 178.24839 | D37: =C37/B37 -> 5.8442093 | E37: =(C37/B37)^(1/10)-1 -> 0.19308827 | F37: =Assumptions!C21*(1+Assumptions!G21)^10*Assumptions!$B$13 -> 448.94986 | G37: =F37/B37 -> 14.719667 | H37: =(F37/B37)^(1/10)-1 -> 0.30854843 | I37: =Assumptions!C21*(1+Assumptions!H21)^10*Assumptions!$B$13 -> 9.0092165 | J37: =I37/B37 -> 0.29538415 | K37: =(I37/B37)^(1/10)-1 -> -0.11480548 | L37: =Assumptions!C21*(1+Assumptions!I21)^10*Assumptions!$B$13 -> 215.91335 | M37: =L37/B37 -> 7.0791262 | N37: =(L37/B37)^(1/10)-1 -> 0.2161803
A38: =Assumptions!A22 -> Syntiant | B38: =Assumptions!C22 -> 31.5 | C38: =Assumptions!C22*(1+Assumptions!F22)^10*Assumptions!$B$13 -> 94.492939 | D38: =C38/B38 -> 2.9997759 | E38: =(C38/B38)^(1/10)-1 -> 0.11611483 | F38: =Assumptions!C22*(1+Assumptions!G22)^10*Assumptions!$B$13 -> 252.88273 | G38: =F38/B38 -> 8.028023 | H38: =(F38/B38)^(1/10)-1 -> 0.23157499 | I38: =Assumptions!C22*(1+Assumptions!H22)^10*Assumptions!$B$13 -> 17.5017 | J38: =I38/B38 -> 0.55560951 | K38: =(I38/B38)^(1/10)-1 -> -0.057075398 | L38: =Assumptions!C22*(1+Assumptions!I22)^10*Assumptions!$B$13 -> 156.4652 | M38: =L38/B38 -> 4.9671494 | N38: =(L38/B38)^(1/10)-1 -> 0.17384491
A39: =Assumptions!A23 -> Infleqtion | B39: =Assumptions!C23 -> 25 | C39: =Assumptions!C23*(1+Assumptions!F23)^10*Assumptions!$B$13 -> 68.774482 | D39: =C39/B39 -> 2.7509793 | E39: =(C39/B39)^(1/10)-1 -> 0.10649315 | F39: =Assumptions!C23*(1+Assumptions!G23)^10*Assumptions!$B$13 -> 185.56076 | G39: =F39/B39 -> 7.4224302 | H39: =(F39/B39)^(1/10)-1 -> 0.22195331 | I39: =Assumptions!C23*(1+Assumptions!H23)^10*Assumptions!$B$13 -> 5.9275335 | J39: =I39/B39 -> 0.23710134 | K39: =(I39/B39)^(1/10)-1 -> -0.13404884 | L39: =Assumptions!C23*(1+Assumptions!I23)^10*Assumptions!$B$13 -> 126.22953 | M39: =L39/B39 -> 5.0491814 | N39: =(L39/B39)^(1/10)-1 -> 0.17576925
A40: =Assumptions!A24 -> Diraq | B40: =Assumptions!C24 -> 14 | C40: =Assumptions!C24*(1+Assumptions!F24)^10*Assumptions!$B$13 -> 131.24128 | D40: =C40/B40 -> 9.3743774 | E40: =(C40/B40)^(1/10)-1 -> 0.25081835 | F40: =Assumptions!C24*(1+Assumptions!G24)^10*Assumptions!$B$13 -> 317.33677 | G40: =F40/B40 -> 22.666912 | H40: =(F40/B40)^(1/10)-1 -> 0.3662785 | I40: =Assumptions!C24*(1+Assumptions!H24)^10*Assumptions!$B$13 -> 0.79356586 | J40: =I40/B40 -> 0.056683276 | K40: =(I40/B40)^(1/10)-1 -> -0.24950899 | L40: =Assumptions!C24*(1+Assumptions!I24)^10*Assumptions!$B$13 -> 245.46968 | M40: =L40/B40 -> 17.533548 | N40: =(L40/B40)^(1/10)-1 -> 0.33164046
A41: =Assumptions!A25 -> Mueon | B41: =Assumptions!C25 -> 10 | C41: =Assumptions!C25*(1+Assumptions!F25)^10*Assumptions!$B$13 -> 109.20643 | D41: =C41/B41 -> 10.920643 | E41: =(C41/B41)^(1/10)-1 -> 0.27006171 | F41: =Assumptions!C25*(1+Assumptions!G25)^10*Assumptions!$B$13 -> 260.69568 | G41: =F41/B41 -> 26.069568 | H41: =(F41/B41)^(1/10)-1 -> 0.38552186 | I41: =Assumptions!C25*(1+Assumptions!H25)^10*Assumptions!$B$13 -> 0.25458562 | J41: =I41/B41 -> 0.025458562 | K41: =(I41/B41)^(1/10)-1 -> -0.30723907 | L41: =Assumptions!C25*(1+Assumptions!I25)^10*Assumptions!$B$13 -> 191.14507 | M41: =L41/B41 -> 19.114507 | N41: =(L41/B41)^(1/10)-1 -> 0.34318647
A42: =Assumptions!A26 -> DefendEye | B42: =Assumptions!C26 -> 6.5 | C42: =Assumptions!C26*(1+Assumptions!F26)^10*Assumptions!$B$13 -> 52.18215 | D42: =C42/B42 -> 8.028023 | E42: =(C42/B42)^(1/10)-1 -> 0.23157499 | F42: =Assumptions!C26*(1+Assumptions!G26)^10*Assumptions!$B$13 -> 127.85056 | G42: =F42/B42 -> 19.669317 | H42: =(F42/B42)^(1/10)-1 -> 0.34703515 | I42: =Assumptions!C26*(1+Assumptions!H26)^10*Assumptions!$B$13 -> 0.24890574 | J42: =I42/B42 -> 0.03829319 | K42: =(I42/B42)^(1/10)-1 -> -0.27837403 | L42: =Assumptions!C26*(1+Assumptions!I26)^10*Assumptions!$B$13 -> 31.243381 | M42: =L42/B42 -> 4.8066739 | N42: =(L42/B42)^(1/10)-1 -> 0.16999624
A43: FUND TOTAL | B43: =SUM(B34:B42) -> 250 | C43: =SUM(C34:C42) -> 1261.4559 | D43: =C43/B43 -> 5.0458237 | E43: =(C43/B43)^(1/10)-1 -> 0.17569104 | F43: =SUM(F34:F42) -> 3197.6972 | G43: =F43/B43 -> 12.790789 | H43: =(F43/B43)^(1/10)-1 -> 0.29029713 | I43: =SUM(I34:I42) -> 73.963354 | J43: =I43/B43 -> 0.29585342 | K43: =(I43/B43)^(1/10)-1 -> -0.11466495 | L43: =SUM(L34:L42) -> 3418.1015 | M43: =L43/B43 -> 13.672406 | N43: =(L43/B43)^(1/10)-1 -> 0.29892625

Sheet Fund Economics
A1: FUND ECONOMICS — GROSS->NET WATERFALL
A2: Whole-fund European waterfall: return of capital -> 8% comp. pref -> 20% carry (no catch-up). Expected = prob-weighted. $M.
A4: 5-YEAR VEHICLE
A5: Line item ($M) | B5: Base | C5: Bull | D5: Bear | E5: TSMC-Shock | F5: Expected
A6: Gross exit proceeds | B6: ='Portfolio Returns'!C15 -> 565.83078 | C6: ='Portfolio Returns'!F15 -> 904.36142 | D6: ='Portfolio Returns'!I15 -> 126.29353 | E6: ='Portfolio Returns'!L15 -> 915.40631 | F6: =B6*'Defense Supercycle'!$B$17+C6*'Defense Supercycle'!$B$18+D6*'Defense Supercycle'!$B$19+E6*'Defense Supercycle'!$B$20 -> 636.96918
A7: (-) Return of committed capital | B7: =-Assumptions!$B$5 -> -250 | C7: =-Assumptions!$B$5 -> -250 | D7: =-Assumptions!$B$5 -> -250 | E7: =-Assumptions!$B$5 -> -250 | F7: =B7*'Defense Supercycle'!$B$17+C7*'Defense Supercycle'!$B$18+D7*'Defense Supercycle'!$B$19+E7*'Defense Supercycle'!$B$20 -> -250
A8: (-) Preferred return (8% comp.) | B8: =-Assumptions!$B$5*((1+Assumptions!$B$10)^5-1) -> -117.33202 | C8: =-Assumptions!$B$5*((1+Assumptions!$B$10)^5-1) -> -117.33202 | D8: =-Assumptions!$B$5*((1+Assumptions!$B$10)^5-1) -> -117.33202 | E8: =-Assumptions!$B$5*((1+Assumptions!$B$10)^5-1) -> -117.33202 | F8: =B8*'Defense Supercycle'!$B$17+C8*'Defense Supercycle'!$B$18+D8*'Defense Supercycle'!$B$19+E8*'Defense Supercycle'!$B$20 -> -117.33202
A9: Profit above pref (carry base) | B9: =MAX(0,B6+B7+B8) -> 198.49876 | C9: =MAX(0,C6+C7+C8) -> 537.0294 | D9: =MAX(0,D6+D7+D8) -> 0 | E9: =MAX(0,E6+E7+E8) -> 548.07429 | F9: =B9*'Defense Supercycle'!$B$17+C9*'Defense Supercycle'!$B$18+D9*'Defense Supercycle'!$B$19+E9*'Defense Supercycle'!$B$20 -> 305.79294
A10: (-) GP carried interest (20%) | B10: =-Assumptions!$B$9*B9 -> -39.699752 | C10: =-Assumptions!$B$9*C9 -> -107.40588 | D10: =-Assumptions!$B$9*D9 -> 0 | E10: =-Assumptions!$B$9*E9 -> -109.61486 | F10: =B10*'Defense Supercycle'!$B$17+C10*'Defense Supercycle'!$B$18+D10*'Defense Supercycle'!$B$19+E10*'Defense Supercycle'!$B$20 -> -61.158587
A11: (-) Management fees | B11: =-Assumptions!$B$5*Assumptions!$B$8*5 -> -25 | C11: =-Assumptions!$B$5*Assumptions!$B$8*5 -> -25 | D11: =-Assumptions!$B$5*Assumptions!$B$8*5 -> -25 | E11: =-Assumptions!$B$5*Assumptions!$B$8*5 -> -25 | F11: =B11*'Defense Supercycle'!$B$17+C11*'Defense Supercycle'!$B$18+D11*'Defense Supercycle'!$B$19+E11*'Defense Supercycle'!$B$20 -> -25
A12: Net proceeds to LPs | B12: =B6+B10+B11 -> 501.13103 | C12: =C6+C10+C11 -> 771.95554 | D12: =D6+D10+D11 -> 101.29353 | E12: =E6+E10+E11 -> 780.79145 | F12: =B12*'Defense Supercycle'!$B$17+C12*'Defense Supercycle'!$B$18+D12*'Defense Supercycle'!$B$19+E12*'Defense Supercycle'!$B$20 -> 550.81059
A13: Gross MOIC | B13: =B6/Assumptions!$B$5 -> 2.2633231 | C13: =C6/Assumptions!$B$5 -> 3.6174457 | D13: =D6/Assumptions!$B$5 -> 0.5051741 | E13: =E6/Assumptions!$B$5 -> 3.6616253 | F13: =F6/Assumptions!$B$5 -> 2.5478767
A14: Net MOIC (to LP) | B14: =B12/Assumptions!$B$5 -> 2.0045241 | C14: =C12/Assumptions!$B$5 -> 3.0878221 | D14: =D12/Assumptions!$B$5 -> 0.4051741 | E14: =E12/Assumptions!$B$5 -> 3.1231658 | F14: =F12/Assumptions!$B$5 -> 2.2032424
A15: Gross IRR | B15: =(B6/Assumptions!$B$5)^(1/5)-1 -> 0.17746854 | C15: =(C6/Assumptions!$B$5)^(1/5)-1 -> 0.29324379 | D15: =(D6/Assumptions!$B$5)^(1/5)-1 -> -0.12765512 | E15: =(E6/Assumptions!$B$5)^(1/5)-1 -> 0.29638733 | F15: =(F6/Assumptions!$B$5)^(1/5)-1 -> 0.20569006
A16: Net IRR (to LP) | B16: =(B12/Assumptions!$B$5)^(1/5)-1 -> 0.14921757 | C16: =(C12/Assumptions!$B$5)^(1/5)-1 -> 0.25294052 | D16: =(D12/Assumptions!$B$5)^(1/5)-1 -> -0.16530399 | E16: =(E12/Assumptions!$B$5)^(1/5)-1 -> 0.25579575 | F16: =(F12/Assumptions!$B$5)^(1/5)-1 -> 0.17114982
A17: DPI = TVPI at exit | B17: =B12/Assumptions!$B$5 -> 2.0045241 | C17: =C12/Assumptions!$B$5 -> 3.0878221 | D17: =D12/Assumptions!$B$5 -> 0.4051741 | E17: =E12/Assumptions!$B$5 -> 3.1231658 | F17: =F12/Assumptions!$B$5 -> 2.2032424
A20: 7-YEAR VEHICLE
A21: Line item ($M) | B21: Base | C21: Bull | D21: Bear | E21: TSMC-Shock | F21: Expected
A22: Gross exit proceeds | B22: ='Portfolio Returns'!C29 -> 778.13077 | C22: ='Portfolio Returns'!F29 -> 1497.0053 | D22: ='Portfolio Returns'!I29 -> 100.03369 | E22: ='Portfolio Returns'!L29 -> 1542.4475 | F22: =B22*'Defense Supercycle'!$B$17+C22*'Defense Supercycle'!$B$18+D22*'Defense Supercycle'!$B$19+E22*'Defense Supercycle'!$B$20 -> 970.78235
A23: (-) Return of committed capital | B23: =-Assumptions!$B$5 -> -250 | C23: =-Assumptions!$B$5 -> -250 | D23: =-Assumptions!$B$5 -> -250 | E23: =-Assumptions!$B$5 -> -250 | F23: =B23*'Defense Supercycle'!$B$17+C23*'Defense Supercycle'!$B$18+D23*'Defense Supercycle'!$B$19+E23*'Defense Supercycle'!$B$20 -> -250
