Workbook
Name Hold_Short: Assumptions!$F$5
Name Hold_Mid: Assumptions!$F$6
Name Hold_Long: Assumptions!$F$7
Name IQT_Committed: Assumptions!$B$5
Name Mgmt_Fee: Assumptions!$B$8
Name Carry: Assumptions!$B$9
Name Pref: Assumptions!$B$10
Name Ret_IQT_Short: Assumptions!$B$11
Name Ret_IQT_Mid: Assumptions!$B$12
Name Ret_IQT_Long: Assumptions!$B$13
Name Ret_Wpn_Short: 'Weapons Sleeve'!$B$6
Name Ret_Wpn_Mid: 'Weapons Sleeve'!$B$7
Name Ret_Wpn_Long: 'Weapons Sleeve'!$B$8
Name Ret_Con_Short: 'Consumer Sleeve'!$B$6
Name Ret_Con_Mid: 'Consumer Sleeve'!$B$7
Name Ret_Con_Long: 'Consumer Sleeve'!$B$8
Name P_Base: 'Defense Supercycle'!$B$17
Name P_Bull: 'Defense Supercycle'!$B$18
Name P_Bear: 'Defense Supercycle'!$B$19
Name P_Shock: 'Defense Supercycle'!$B$20
Name Holdco_Size: 'Holdco Summary'!$B$9
Name IQT_Size: 'Holdco Summary'!$B$6
Name Wpn_Size: 'Holdco Summary'!$B$7
Name Con_Size: 'Holdco Summary'!$B$8
Name SPX_CAGR: 'PME, DPI & Sensitivity'!$B$5
Name NDX_CAGR: 'PME, DPI & Sensitivity'!$B$6
Name Basket_CAGR: 'Holdco Summary'!$B$23

Sheet Cover
B25: LEVIATHAN CORE PRIVATE EQUITY HOLDCO (“LPEH”)
B26: ="Internal IC planning model · v3 optimised 02-Oct-2026 · "&TEXT(Holdco_Size,"$#,##0")&"M across three sub-vehicles · USD millions" -> Internal IC planning model · v3 optimised 02-Oct-2026 · $840M across three sub-vehicles · USD millions
B27: =Checks!$B$3 -> MODEL INTEGRITY: ALL 21 CHECKS PASS
B28: HIGHLY CONFIDENTIAL & TRADE SECRET · Miami · London · Zurich · Tokyo
B30: NAVIGATION
B31: Read Me | D31: How the model is wired, caveats, v3 change summary
B32: Change Log | D32: Cell-level record of the optimisation pass
B33: Checks | D33: Model integrity dashboard
B34: IC Summary | D34: One-page holdco dashboard
B35: Holdco Summary | D35: Tripartite roll-up and holdco waterfall
B36: Assumptions | D36: Fund terms, hold levers, IQT-mirror entry marks
B37: Defense Supercycle | D37: Strategic scoring and shock engine
B38: Weapons Sleeve | D38: Defense sub-vehicle with munitions / FMS overlay
B39: Consumer Sleeve | D39: Consumer sub-vehicle with cohort-exposure overlay
B40: Sleeve Economics | D40: Gross-to-net by sub-vehicle and netting reconciliation
B41: PME, DPI & Sensitivity | D41: Public-market equivalents and shock pressure tests
B42: Fact Sheet Data | D42: Every figure on the external fact sheet

Sheet Read Me
B1: LEVIATHAN FUND — CORE PE VEHICLE
B2: ="IQT-Backed Deep-Tech Acquisition-Stake Portfolio | "&Hold_Short&" / "&Hold_Mid&" / "&Hold_Long&"-Year Holds | Defense-Supercycle Overlay" -> IQT-Backed Deep-Tech Acquisition-Stake Portfolio | 5 / 7 / 10-Year Holds | Defense-Supercycle Overlay
B3: Anchored by Substrate, Inc. · Prepared 22-Sep-2026 · v3 optimization pass 02-Oct-2026 · All figures USD millions unless noted
B5: PURPOSE
B6: Leviathan's core PE holdco is an $840M vehicle across THREE sub-funds: IQT-mirror deep-tech ($250M), Weapons ($390M), and Consumer/Value ($200M). All three sleeves are modeled bottom-up from individual holdings — IQT-mirror (nine In-Q-Tel names), Weapons (nine physical-layer holdings, incl. The Ellwood Group and Superior & Grand Valley for missile-procurement metal forging), Consumer/Value (nine DTC/spending-cycle names) — each across four scenarios, 5/7/10-yr holds, gross-to-net waterfall, and PME, and roll up to a blended holdco return on the Holdco Summary tab. Start there for the top-down view; the sleeve tabs hold the detail.
B7: Scope: Leviathan runs four vehicles (~$1.5B AUM total); this workbook models only the core PE holdco vehicle ($840M) and its equity targets — not the other three vehicles.
B8: THE DEFENSE-SUPERCYCLE THESIS (now wired into returns)
B9: The book is built to be long the US side of the AI / semiconductor race with China and structurally hedged against a Taiwan contingency or loss of TSMC access. The Defense Supercycle tab scores every name on five strategic axes — China-race criticality, Taiwan/TSMC-insulation value, government/defense embeddedness, CFIUS-clean US-sovereignty, and supply-chain chokepoint leverage. Those scores drive a composite, which drives each name's re-rating in the TSMC-Shock scenario. Change a score and the shock returns move.
B11: HOW THE MODEL IS WIRED (edit blue cells only)
B12: • IC Summary — one-page holdco dashboard: net IRR / MOIC / proceeds / KS-PME by hold x scenario, sleeve gross MOIC, scenario weights and model integrity checks. Start here. • Assumptions — fund terms + per-name entry marks, checks, ownership, and Base/Bull/Bear CAGRs. TSMC-Shock CAGR is computed from the Supercycle tab.
B13: • Defense Supercycle — strategic scoring matrix, axis weights, shock calibration levers, and the four scenario probability weights. This is the thesis engine.
B14: • Allocation — nine positions, tranche, ownership, domicile, structuring/CFIUS flags.
B15: • Portfolio Returns — per-name proceeds, MOIC, gross IRR for each hold x four scenarios.
B16: • Fund Economics — gross->net waterfall (2% fee, 8% pref, 20% carry) per vehicle x scenario, plus prob-weighted Expected.
... B35: • All IRR / Direct-Alpha formulas are guarded: a wipe-out returns -100% rather than #NUM!. Stale sleeve CAGR memos replaced by live links. Redundant same-sheet references removed. See the Change Log tab for the cell-level list.

Sheet Change Log
A1: CHANGE LOG — v3 OPTIMIZATION PASS (02-Oct-2026)
A2: Cell-level record of every edit made by the optimization script. 'Value impact' flags the only places where numbers moved; everything else is structural and was verified cell-by-cell against the prior version after a full recalculation.
A4: # | B4: Tab | C4: Range | D4: Change | E4: Value impact
A5: 1 | B5: Assumptions | C5: A4 | D5: Relabelled fund-terms block: these terms drive the holdco AND every sleeve waterfall, not just IQT. | E5: None
A6: 2 | B6: Assumptions | C6: E4:G7 | D6: NEW hold-period levers (5/7/10 yrs) with named ranges Hold_Short / Hold_Mid / Hold_Long. Every block header, hold exponent, fee-year multiplier and IRR root in the model now references these cells. | E6: None
A7: 3 | B7: Assumptions | C7: A29 | D7: NEW check: initial deployment + follow-on reserve must equal committed capital. | E7: None
A8: 4 | B8: Workbook | C8: Defined names | D8: NEW named ranges for every lever: Hold_Short, Hold_Mid, Hold_Long, IQT_Committed, Mgmt_Fee, Carry, Pref, Ret_IQT_Short, Ret_IQT_Mid, Ret_IQT_Long, Ret_Wpn_Short, Ret_Wpn_Mid, Ret_Wpn_Long, Ret_Con_Short, Ret_Con_Mid, Ret_Con_Long, P_Base, P_Bull, P_Bear, P_Shock, Holdco_Size, IQT_Size, Wpn_Size, Con_Size, SPX_CAGR, NDX_CAGR, Basket_CAGR. | E8: None
A9: 5 | B9: All tabs | C9: formulas | D9: Replaced 1424 repeated lever references with named ranges and removed 63 redundant same-sheet references (e.g. 'Holdco Summary'!$B$9 inside Holdco Summary). Pure readability; values unchanged. | E9: None
A10: 6 | B10: PME, DPI & Sensitivity | C10: B73:D73, B81:D81, B87:D94, B99:D100 | D10: Holdco PME / sensitivity blocks and the Weapons PME hold-year inputs now read the Hold_* levers instead of hard-coded 5 / 7 / 10. | E10: None
A11: 7 | B11: All model tabs | C11: hold blocks | D11: Rewrote 1062 hard-coded hold-period literals (^5, *7, (1/10) ...) to the Hold_Short / Hold_Mid / Hold_Long levers. Change a hold period once on Assumptions and every proceeds, pref, fee, IRR, PME and sensitivity formula follows. | E11: None
A12: 8 | B12: All tabs | C12: section labels | D12: 66 block headers / row labels that embedded '5-YEAR', '7-Year', 'Retention @ 10yr' etc. are now formulas driven by the hold levers, so labels can never drift from the maths. | E12: None
A13: 9 | B13: All model tabs | C13: IRR / Direct Alpha cells | D13: Guarded 498 IRR and Direct-Alpha formulas: a wipe-out (net proceeds <= 0) now returns -100% instead of #NUM!, so Expected columns and checks never break in a severe Bear case. | E13: None
A14: 10 | B14: Holdco Summary | C14: A14:F19 | D14: Stale hard-coded sleeve CAGR memos (Weapons 22/34/5/32%, Consumer 14/25/-10/-4%) replaced by live links to the bottom-up sleeve IRRs for all three sleeves; note moved to A19. | E14: Memo rows only
A15: 11 | B15: Holdco Summary | C15: F32:F37, F53:F58, F74:F79 | D15: Expected column now probability-weights each NET waterfall line (same method as Fund Economics / Scenario Summary). Rows F32/F33/F36 are constant across scenarios, F34/F35 were already weighted; the whole block is now written one way. | E15: None in this version (F34/F35 were already weighted); block is now uniformly weighted
A16: 12 | B16: Holdco Summary | C16: A3 | D16: Live model-integrity status pulled from the new Checks tab. | E16: None
... A24: 19 | B24: Cover | C24: whole tab | D24: NEW cover sheet: Leviathan logo, vehicle title, live integrity status and hyperlinked tab navigation. | E24: None

Sheet Checks
A1: MODEL INTEGRITY CHECKS
A2: Every structural identity the model relies on. Status flows to Holdco Summary!A3. Blue = target input.
A3: OVERALL STATUS | B3: =IF(COUNTIF(C8:C28,"ERROR")=0,"MODEL INTEGRITY: ALL "&COUNTA(A8:A28)&" CHECKS PASS","MODEL INTEGRITY: "&COUNTIF(C8:C28,"ERROR")&" OF "&COUNTA(A8:A28)&" CHECKS FAILING") -> MODEL INTEGRITY: ALL 21 CHECKS PASS
A5: Holdco target size ($M) | B5: 840 | D5: Sleeve sizes on Holdco Summary must add to this.
A7: Check | B7: Value | C7: Status | D7: What it protects
A8: Holdco sleeve sizes sum to target | B8: =Holdco_Size-$B$5 -> 0 | C8: =IF(ABS(B8)<0.5,"OK","ERROR") -> OK | D8: Holdco Summary B6:B9 vs target
A9: IQT sleeve: checks sum to sleeve size | B9: =Assumptions!C27-IQT_Size -> 0 | C9: =IF(ABS(B9)<0.5,"OK","ERROR") -> OK | D9: Assumptions C18:C26
A10: Weapons sleeve: checks sum to sleeve size | B10: ='Weapons Sleeve'!C21-Wpn_Size -> 0 | C10: =IF(ABS(B10)<0.5,"OK","ERROR") -> OK | D10: Weapons Sleeve C12:C18
A11: Consumer sleeve: checks sum to sleeve size | B11: ='Consumer Sleeve'!C21-Con_Size -> 0 | C11: =IF(ABS(B11)<0.5,"OK","ERROR") -> OK | D11: Consumer Sleeve C12:C20
A12: IQT: initial deployment + reserve = committed | B12: =Assumptions!B6+Assumptions!B7-IQT_Committed -> 0 | C12: =IF(ABS(B12)<0.5,"OK","ERROR") -> OK | D12: Assumptions B5:B7
A13: Strategic axis weights sum to 100% | B13: ='Defense Supercycle'!B10 -> 1 | C13: =IF(ABS(B13-1)<0.0001,"OK","ERROR") -> OK | D13: Defense Supercycle B5:B9
A14: Scenario probabilities sum to 100% | B14: ='Defense Supercycle'!B21 -> 1 | C14: =IF(ABS(B14-1)<0.0001,"OK","ERROR") -> OK | D14: Defense Supercycle B17:B20
A15: Hold periods positive and strictly increasing | B15: =Hold_Short&" < "&Hold_Mid&" < "&Hold_Long -> 5 < 7 < 10 | C15: =IF(AND(Hold_Short>0,Hold_Mid>Hold_Short,Hold_Long>Hold_Mid),"OK","ERROR") -> OK | D15: Assumptions F5:F7
A16: IQT retention in (0,1] and non-increasing with hold | B16: =TEXT(Ret_IQT_Short,"0%")&" ≥ "&TEXT(Ret_IQT_Mid,"0%")&" ≥ "&TEXT(Ret_IQT_Long,"0%") -> 85% ≥ 78% ≥ 68% | C16: =IF(AND(Ret_IQT_Short<=1,Ret_IQT_Short>=Ret_IQT_Mid,Ret_IQT_Mid>=Ret_IQT_Long,Ret_IQT_Long>0),"OK","ERROR") -> OK | D16: Assumptions B11:B13
A17: Weapons retention in (0,1] and non-increasing with hold | B17: =TEXT(Ret_Wpn_Short,"0%")&" ≥ "&TEXT(Ret_Wpn_Mid,"0%")&" ≥ "&TEXT(Ret_Wpn_Long,"0%") -> 92% ≥ 88% ≥ 82% | C17: =IF(AND(Ret_Wpn_Short<=1,Ret_Wpn_Short>=Ret_Wpn_Mid,Ret_Wpn_Mid>=Ret_Wpn_Long,Ret_Wpn_Long>0),"OK","ERROR") -> OK | D17: Weapons Sleeve B6:B8
A18: Consumer retention in (0,1] and non-increasing with hold | B18: =TEXT(Ret_Con_Short,"0%")&" ≥ "&TEXT(Ret_Con_Mid,"0%")&" ≥ "&TEXT(Ret_Con_Long,"0%") -> 90% ≥ 84% ≥ 75% | C18: =IF(AND(Ret_Con_Short<=1,Ret_Con_Short>=Ret_Con_Mid,Ret_Con_Mid>=Ret_Con_Long,Ret_Con_Long>0),"OK","ERROR") -> OK | D18: Consumer Sleeve B6:B8
A19: Fee, carry and pref each within [0%, 100%) | B19: =TEXT(Mgmt_Fee,"0.0%")&" / "&TEXT(Carry,"0%")&" / "&TEXT(Pref,"0%") -> 2.0% / 20% / 8% | C19: =IF(AND(Mgmt_Fee>=0,Mgmt_Fee<1,Carry>=0,Carry<1,Pref>=0,Pref<1),"OK","ERROR") -> OK | D19: Assumptions B8:B10
A20: Allocation tab total = Assumptions deployed total | B20: =Allocation!B14-Assumptions!C27 -> 0 | C20: =IF(ABS(B20)<0.5,"OK","ERROR") -> OK | D20: Allocation B5:B14
A21: IQT Clusters total = Assumptions deployed total | B21: ='IQT Clusters'!C10-Assumptions!C27 -> 0 | C21: =IF(ABS(B21)<0.5,"OK","ERROR") -> OK | D21: IQT Clusters C6:C10
A22: Sleeve Economics IQT net = Fund Economics net (all holds, all cases) | B22: =SUMPRODUCT(ABS('Fund Economics'!B12:F12-'Sleeve Economics'!B12:F12))+SUMPRODUCT(ABS('Fund Economics'!B28:F28-'Sleeve Economics'!B29:F29))+SUMPRODUCT(ABS('Fund Economics'!B44:F44-'Sleeve Economics'!B46:F46)) -> 0 | C22: =IF(ABS(B22)<0.01,"OK","ERROR") -> OK | D22: Two independent waterfalls of the same sleeve must agree
A23: Holdco gross proceeds = sum of sleeve gross (all holds, all cases) | B23: =SUMPRODUCT(ABS('Holdco Summary'!B31:F31-('Sleeve Economics'!B6:F6+'Sleeve Economics'!H6:L6+'Sleeve Economics'!N6:R6)))+SUMPRODUCT(ABS('Holdco Summary'!B52:F52-('Sleeve Economics'!B23:F23+'Sleeve Economics'!H23:L23+'Sleeve Economics'!N23:R23)))+SUMPRODUCT(ABS('Holdco Summary'!B73:F73-('Sleeve Economics'!B40:F40+'Sleeve Economics'!H40:L40+'Sleeve Economics'!N40:R40))) -> 0 | C23: =IF(ABS(B23)<0.01,"OK","ERROR") -> OK | D23: Roll-up links point at the right sleeve rows
A24: Fact-sheet holdings register sums to holdco size | B24: ='Fact Sheet Data'!C85-Holdco_Size -> 0 | C24: =IF(ABS(B24)<0.5,"OK","ERROR") -> OK | D24: Every holding is tagged exactly once
A25: Fact-sheet breakdowns each sum to 100% | B25: =ABS('Fact Sheet Data'!C92-1)+ABS('Fact Sheet Data'!C106-1)+ABS('Fact Sheet Data'!C114-1)+ABS('Fact Sheet Data'!C123-1) -> 1.110223e-16 | C25: =IF(ABS(B25)<0.0001,"OK","ERROR") -> OK | D25: No untagged / mistyped sector, region or stage
A26: Consumer cohort weights sum to 100% | B26: ='Consumer Sleeve'!T8 -> 1 | C26: =IF(ABS(B26-1)<0.0001,"OK","ERROR") -> OK | D26: Consumer Sleeve T5:T7
A27: IC Summary integrity block reports ALL PASS | B27: ='IC Summary'!D80 -> ALL PASS | C27: =IF(B27="ALL PASS","OK","ERROR") -> OK | D27: The pre-existing 8-check block on IC Summary
A28: No formula errors on output tabs | B28: =SUMPRODUCT(ISERROR('Holdco Summary'!B28:F86)*1)+SUMPRODUCT(ISERROR('Fund Economics'!B6:F49)*1)+SUMPRODUCT(ISERROR('Sleeve Economics'!B6:R53)*1)+SUMPRODUCT(ISERROR('Scenario Summary'!B6:F22)*1)+SUMPRODUCT(ISERROR('PME, DPI & Sensitivity'!B13:F69)*1)+SUMPRODUCT(ISERROR('Fact Sheet Data'!B5:N143)*1)+SUMPRODUCT(ISERROR('IC Summary'!B6:F81)*1) -> 0 | C28: =IF(B28=0,"OK","ERROR") -> OK | D28: Count of #DIV/0!, #NUM!, #REF! etc. across all output ranges

Sheet IC Summary
A1: LEVIATHAN CORE PE HOLDCO — IC SUMMARY
A2: $840M tripartite holdco (IQT-mirror / Weapons / Consumer-Value). USD $M. Expected = probability-weighted across Base/Bull/Bear/TSMC-Shock (weights on Defense Supercycle tab). Every figure links live to the model — no inputs on this page.
A4: ="HEADLINE — RECOMMENDED "&Hold_Mid&"-YEAR VEHICLE (Expected case, net to LP)" -> HEADLINE — RECOMMENDED 7-YEAR VEHICLE (Expected case, net to LP)
A5: Metric | B5: Net IRR | C5: Net MOIC | D5: Net proceeds | E5: KS-PME basket | F5: KS-PME SPX
A6: Holdco — 7-yr, probability-weighted | B6: ='Holdco Summary'!F61 -> 0.19871158 | C6: ='Holdco Summary'!F59 -> 3.556337 | D6: ='Holdco Summary'!F58 -> 2987.3231 | E6: ='Holdco Summary'!F64 -> 1.3369588 | F6: ='Holdco Summary'!F62 -> 1.9454381
A8: HOLDCO NET IRR TO LP
A9: Vehicle | B9: Base | C9: Bull | D9: Bear | E9: TSMC-Shock | F9: Expected
A10: =Hold_Short&"-Year Hold" -> 5-Year Hold | B10: ='Holdco Summary'!B40 -> 0.16099973 | C10: ='Holdco Summary'!C40 -> 0.28032381 | D10: ='Holdco Summary'!D40 -> -0.047351614 | E10: ='Holdco Summary'!E40 -> 0.21405233 | F10: ='Holdco Summary'!F40 -> 0.18357543
A11: =Hold_Mid&"-Year Hold" -> 7-Year Hold | B11: ='Holdco Summary'!B61 -> 0.16509984 | C11: ='Holdco Summary'!C61 -> 0.28959836 | D11: ='Holdco Summary'!D61 -> -0.044375165 | E11: ='Holdco Summary'!E61 -> 0.23378367 | F11: ='Holdco Summary'!F61 -> 0.19871158
A12: =Hold_Long&"-Year Hold" -> 10-Year Hold | B12: ='Holdco Summary'!B82 -> 0.17091166 | C12: ='Holdco Summary'!C82 -> 0.30129185 | D12: ='Holdco Summary'!D82 -> -0.039722227 | E12: ='Holdco Summary'!E82 -> 0.25664155 | F12: ='Holdco Summary'!F82 -> 0.21881304
A14: HOLDCO NET MOIC TO LP
A15: Vehicle | B15: Base | C15: Bull | D15: Bear | E15: TSMC-Shock | F15: Expected
A16: =Hold_Short&"-Year Hold" -> 5-Year Hold | B16: ='Holdco Summary'!B38 -> 2.1094081 | C16: ='Holdco Summary'!C38 -> 3.4403221 | D16: ='Holdco Summary'!D38 -> 0.78462688 | E16: ='Holdco Summary'!E38 -> 2.637467 | F16: ='Holdco Summary'!F38 -> 2.3226282
A17: =Hold_Mid&"-Year Hold" -> 7-Year Hold | B17: ='Holdco Summary'!B59 -> 2.914352 | C17: ='Holdco Summary'!C59 -> 5.9317292 | D17: ='Holdco Summary'!D59 -> 0.7277999 | E17: ='Holdco Summary'!E59 -> 4.3518419 | F17: ='Holdco Summary'!F59 -> 3.556337
A18: =Hold_Long&"-Year Hold" -> 10-Year Hold | B18: ='Holdco Summary'!B80 -> 4.8444146 | C18: ='Holdco Summary'!C80 -> 13.923458 | D18: ='Holdco Summary'!D80 -> 0.66675881 | E18: ='Holdco Summary'!E80 -> 9.8200601 | F18: ='Holdco Summary'!F80 -> 7.2338739
A20: HOLDCO NET PROCEEDS TO LP ($M)
A21: Vehicle | B21: Base | C21: Bull | D21: Bear | E21: TSMC-Shock | F21: Expected
A22: =Hold_Short&"-Year Hold" -> 5-Year Hold | B22: ='Holdco Summary'!B37 -> 1771.9028 | C22: ='Holdco Summary'!C37 -> 2889.8706 | D22: ='Holdco Summary'!D37 -> 659.08658 | E22: ='Holdco Summary'!E37 -> 2215.4723 | F22: ='Holdco Summary'!F37 -> 1951.0077
A23: =Hold_Mid&"-Year Hold" -> 7-Year Hold | B23: ='Holdco Summary'!B58 -> 2448.0557 | C23: ='Holdco Summary'!C58 -> 4982.6525 | D23: ='Holdco Summary'!D58 -> 611.35192 | E23: ='Holdco Summary'!E58 -> 3655.5472 | F23: ='Holdco Summary'!F58 -> 2987.3231
A24: =Hold_Long&"-Year Hold" -> 10-Year Hold | B24: ='Holdco Summary'!B79 -> 4069.3083 | C24: ='Holdco Summary'!C79 -> 11695.705 | D24: ='Holdco Summary'!D79 -> 560.0774 | E24: ='Holdco Summary'!E79 -> 8248.8505 | F24: ='Holdco Summary'!F79 -> 6076.4541
A26: KS-PME vs DEFENSE+SEMIS BASKET (>1.00x = beat the thematic ETFs)
A27: Vehicle | B27: Base | C27: Bull | D27: Bear | E27: TSMC-Shock | F27: Expected
A28: =Hold_Short&"-Year Hold" -> 5-Year Hold | B28: ='Holdco Summary'!B43 -> 1.0487486 | C28: ='Holdco Summary'!C43 -> 1.7104481 | D28: ='Holdco Summary'!D43 -> 0.39009823 | E28: ='Holdco Summary'!E43 -> 1.3112872 | F28: ='Holdco Summary'!F43 -> 1.1547567
A29: =Hold_Mid&"-Year Hold" -> 7-Year Hold | B29: ='Holdco Summary'!B64 -> 1.0956129 | C29: ='Holdco Summary'!C64 -> 2.2299567 | D29: ='Holdco Summary'!D64 -> 0.27360694 | E29: ='Holdco Summary'!E64 -> 1.6360186 | F29: ='Holdco Summary'!F64 -> 1.3369588
A30: =Hold_Long&"-Year Hold" -> 10-Year Hold | B30: ='Holdco Summary'!B85 -> 1.1974652 | C30: ='Holdco Summary'!C85 -> 3.4416659 | D30: ='Holdco Summary'!D85 -> 0.16481258 | E30: ='Holdco Summary'!E85 -> 2.4273687 | F30: ='Holdco Summary'!F85 -> 1.788103
A32: KS-PME vs S&P 500 (>1.00x = beat)
A33: Vehicle | B33: Base | C33: Bull | D33: Bear | E33: TSMC-Shock | F33: Expected
A34: =Hold_Short&"-Year Hold" -> 5-Year Hold | B34: ='Holdco Summary'!B41 -> 1.3709705 | C34: ='Holdco Summary'!C41 -> 2.2359733 | D34: ='Holdco Summary'!D41 -> 0.50995363 | E34: ='Holdco Summary'!E41 -> 1.7141726 | F34: ='Holdco Summary'!F41 -> 1.509549
A35: =Hold_Mid&"-Year Hold" -> 7-Year Hold | B35: ='Holdco Summary'!B62 -> 1.5942504 | C35: ='Holdco Summary'!C62 -> 3.244859 | D35: ='Holdco Summary'!D62 -> 0.39813147 | E35: ='Holdco Summary'!E62 -> 2.3806066 | F35: ='Holdco Summary'!F62 -> 1.9454381
A36: =Hold_Long&"-Year Hold" -> 10-Year Hold | B36: ='Holdco Summary'!B83 -> 2.0463331 | C36: ='Holdco Summary'!C83 -> 5.8814191 | D36: ='Holdco Summary'!D83 -> 0.28164613 | E36: ='Holdco Summary'!E83 -> 4.1480995 | F36: ='Holdco Summary'!F83 -> 3.0556665
A38: SLEEVE SIZING
A39: Sleeve | B39: Size ($M) | C39: % Holdco | D39: # Positions
A40: ='Holdco Summary'!A6 -> IQT-mirror (deep-tech) | B40: ='Holdco Summary'!B6 -> 250 | C40: ='Holdco Summary'!C6 -> 0.29761905 | D40: =COUNT(Assumptions!C18:C26) -> 9
A41: ='Holdco Summary'!A7 -> Weapons (physical layer) | B41: ='Holdco Summary'!B7 -> 390 | C41: ='Holdco Summary'!C7 -> 0.46428571 | D41: =COUNT('Weapons Sleeve'!C12:C20) -> 9
A42: ='Holdco Summary'!A8 -> Consumer / Value | B42: ='Holdco Summary'!B8 -> 200 | C42: ='Holdco Summary'!C8 -> 0.23809524 | D42: =COUNT('Consumer Sleeve'!C12:C20) -> 9
A43: Total holdco | B43: =SUM(B40:B42) -> 840 | C43: =SUM(C40:C42) -> 1 | D43: =SUM(D40:D42) -> 27
A45: ="SLEEVE GROSS MOIC — "&Hold_Short&"-YEAR HOLD (gross proceeds / committed)" -> SLEEVE GROSS MOIC — 5-YEAR HOLD (gross proceeds / committed)
A46: Sleeve | B46: Base | C46: Bull | D46: Bear | E46: TSMC-Shock | F46: Expected
A47: IQT-mirror | B47: ='Holdco Summary'!B28/IQT_Size -> 2.2633231 | C47: ='Holdco Summary'!C28/IQT_Size -> 3.6174457 | D47: ='Holdco Summary'!D28/IQT_Size -> 0.5051741 | E47: ='Holdco Summary'!E28/IQT_Size -> 3.6616253 | F47: ='Holdco Summary'!F28/IQT_Size -> 2.5478767
A48: Weapons | B48: ='Holdco Summary'!B29/Wpn_Size -> 2.3992931 | C48: ='Holdco Summary'!C29/Wpn_Size -> 3.9652435 | D48: ='Holdco Summary'!D29/Wpn_Size -> 1.1367545 | E48: ='Holdco Summary'!E29/Wpn_Size -> 3.9733723 | F48: ='Holdco Summary'!F29/Wpn_Size -> 2.8375118
...

Sheet Holdco Summary
A1: LEVIATHAN — CORE PE HOLDCO ($840M) — TRIPARTITE ROLL-UP
A2: Three sub-funds rolled up to a blended holdco return. Blue = lever. All three sleeves — IQT-mirror, Weapons, Consumer/Value — flow in bottom-up. Expected = probability-weighted net (consistent with Fund Economics).
A3: =Checks!$B$3 -> MODEL INTEGRITY: ALL 21 CHECKS PASS
A4: HOLDCO STRUCTURE & SIZING
A5: Sub-fund | B5: Size ($M) | C5: % Holdco | D5: Return driver | E5: Duration | F5: Role
A6: IQT-mirror (deep-tech) | B6: 250 | C6: =B6/$B$9 -> 0.29761905 | D6: Onshoring capex + Taiwan tail | E6: Longest | F6: Convex optionality / tail hedge
A7: Weapons (physical layer) | B7: 390 | C7: =B7/$B$9 -> 0.46428571 | D7: Defense opex — budgets, conflict | E7: Medium | F7: Cash-generative supercycle core
A8: Consumer / Value | B8: 200 | C8: =B8/$B$9 -> 0.23809524 | D8: Consumer cycle + DTC/wellness | E8: Shortest | F8: Ballast + near-term DPI engine
A9: TOTAL (must = $840M) | B9: =SUM(B6:B8) -> 840 | C9: =SUM(C6:C8) -> 1
A10: IQT-mirror: Substrate, EUV Tech, ThinTronics, EdgeCortix, Syntiant, Infleqtion, Diraq, Mueon, DefendEye
A11: Weapons: Epirus, Elta, Israel Aerospace Industries, Saronic, Helicon Chemical, Applied Research Associates, Heckler & Koch, The Ellwood Group, Superior & Grand Valley
A12: Consumer/Value: Quince, Thrive Market, The Farmer's Dog, Whoop, Plunge, Made In Cookware, Polymarket, Goat Group, Stripe
A14: ="SLEEVE RETURN SUMMARY — implied gross IRR on checks at the "&Hold_Short&"-yr hold, net of dilution (live links to the sleeve tabs)" -> SLEEVE RETURN SUMMARY — implied gross IRR on checks at the 5-yr hold, net of dilution (live links to the sleeve tabs)
A15: Sleeve | B15: Base | C15: Bull | D15: Bear | E15: TSMC-Shock
A16: IQT-mirror (bottom-up, live) | B16: ='Portfolio Returns'!E15 -> 0.17746854 | C16: ='Portfolio Returns'!H15 -> 0.29324379 | D16: ='Portfolio Returns'!K15 -> -0.12765512 | E16: ='Portfolio Returns'!N15 -> 0.29638733
A17: Weapons (bottom-up, live) | B17: ='Weapons Sleeve'!E34 -> 0.19128771 | C17: ='Weapons Sleeve'!H34 -> 0.31720683 | D17: ='Weapons Sleeve'!K34 -> 0.025966861 | E17: ='Weapons Sleeve'!N34 -> 0.31774644
A18: Consumer / Value (bottom-up, live) | B18: ='Consumer Sleeve'!E34 -> 0.20577955 | C18: ='Consumer Sleeve'!H34 -> 0.36793243 | D18: ='Consumer Sleeve'!K34 -> -0.028073832 | E18: ='Consumer Sleeve'!N34 -> -0.12813027
A19: Memo only — these rows are live reads of the sleeve tabs (gross IRR on checks at the short hold). The sleeve tabs are the source of truth; nothing downstream references this block.
A20: BENCHMARKS (KS-PME > 1.0x = beat)
A21: S&P 500 (SPX) total-return CAGR | B21: =SPX_CAGR -> 0.09
A22: Nasdaq-100 (NDX) total-return CAGR | B22: =NDX_CAGR -> 0.13
A23: Defense+Semis thematic basket CAGR (ITA/SOXX blend) | B23: 0.15
A24: Forward-tempered: 50/50 ITA/SOXX trailing 5yr is ~26% (ITA 18.2% / SOXX 34.5% to Jun-26), inflated by the AI+rearmament run; 15% forward. See Macro Overlay for comps & drivers.
A26: =Hold_Short&"-YEAR HOLDCO ROLL-UP" -> 5-YEAR HOLDCO ROLL-UP
A27: Line item ($M) | B27: Base | C27: Bull | D27: Bear | E27: TSMC-Shock | F27: Expected
A28: IQT-mirror gross | B28: ='Fund Economics'!B6 -> 565.83078 | C28: ='Fund Economics'!C6 -> 904.36142 | D28: ='Fund Economics'!D6 -> 126.29353 | E28: ='Fund Economics'!E6 -> 915.40631 | F28: ='Fund Economics'!F6 -> 636.96918
A29: Weapons gross | B29: ='Weapons Sleeve'!C34 -> 935.7243 | C29: ='Weapons Sleeve'!F34 -> 1546.445 | D29: ='Weapons Sleeve'!I34 -> 443.33424 | E29: ='Weapons Sleeve'!L34 -> 1549.6152 | F29: =B29*P_Base+C29*P_Bull+D29*P_Bear+E29*P_Shock -> 1106.6296
A30: Consumer/Value gross | B30: ='Consumer Sleeve'!C34 -> 509.76448 | C30: ='Consumer Sleeve'!F34 -> 957.97292 | D30: ='Consumer Sleeve'!I34 -> 173.45881 | E30: ='Consumer Sleeve'!L34 -> 100.75996 | F30: =B30*P_Base+C30*P_Bull+D30*P_Bear+E30*P_Shock -> 510.02006
A31: HOLDCO gross proceeds | B31: =B28+B29+B30 -> 2011.3196 | C31: =C28+C29+C30 -> 3408.7793 | D31: =D28+D29+D30 -> 743.08658 | E31: =E28+E29+E30 -> 2565.7815 | F31: =F28+F29+F30 -> 2253.6188
A32: (-) Return of capital | B32: =-Holdco_Size -> -840 | C32: =-Holdco_Size -> -840 | D32: =-Holdco_Size -> -840 | E32: =-Holdco_Size -> -840 | F32: =B32*P_Base+C32*P_Bull+D32*P_Bear+E32*P_Shock -> -840
A33: (-) Preferred (8% comp.) | B33: =-Holdco_Size*((1+Pref)^Hold_Short-1) -> -394.23558 | C33: =-Holdco_Size*((1+Pref)^Hold_Short-1) -> -394.23558 | D33: =-Holdco_Size*((1+Pref)^Hold_Short-1) -> -394.23558 | E33: =-Holdco_Size*((1+Pref)^Hold_Short-1) -> -394.23558 | F33: =B33*P_Base+C33*P_Bull+D33*P_Bear+E33*P_Shock -> -394.23558
A34: Profit above pref | B34: =MAX(0,B31+B32+B33) -> 777.08398 | C34: =MAX(0,C31+C32+C33) -> 2174.5437 | D34: =MAX(0,D31+D32+D33) -> 0 | E34: =MAX(0,E31+E32+E33) -> 1331.5459 | F34: =B34*P_Base+C34*P_Bull+D34*P_Bear+E34*P_Shock -> 1093.0556
A35: (-) Carry (20%) | B35: =-Carry*B34 -> -155.4168 | C35: =-Carry*C34 -> -434.90874 | D35: =-Carry*D34 -> 0 | E35: =-Carry*E34 -> -266.30917 | F35: =B35*P_Base+C35*P_Bull+D35*P_Bear+E35*P_Shock -> -218.61112
A36: (-) Mgmt fees (2%/yr) | B36: =-Holdco_Size*Mgmt_Fee*Hold_Short -> -84 | C36: =-Holdco_Size*Mgmt_Fee*Hold_Short -> -84 | D36: =-Holdco_Size*Mgmt_Fee*Hold_Short -> -84 | E36: =-Holdco_Size*Mgmt_Fee*Hold_Short -> -84 | F36: =B36*P_Base+C36*P_Bull+D36*P_Bear+E36*P_Shock -> -84
A37: NET proceeds to LP | B37: =B31+B35+B36 -> 1771.9028 | C37: =C31+C35+C36 -> 2889.8706 | D37: =D31+D35+D36 -> 659.08658 | E37: =E31+E35+E36 -> 2215.4723 | F37: =B37*P_Base+C37*P_Bull+D37*P_Bear+E37*P_Shock -> 1951.0077
A38: Net MOIC | B38: =B37/Holdco_Size -> 2.1094081 | C38: =C37/Holdco_Size -> 3.4403221 | D38: =D37/Holdco_Size -> 0.78462688 | E38: =E37/Holdco_Size -> 2.637467 | F38: =F37/Holdco_Size -> 2.3226282
A39: Net DPI (=TVPI at exit) | B39: =B37/Holdco_Size -> 2.1094081 | C39: =C37/Holdco_Size -> 3.4403221 | D39: =D37/Holdco_Size -> 0.78462688 | E39: =E37/Holdco_Size -> 2.637467 | F39: =F37/Holdco_Size -> 2.3226282
A40: Net IRR | B40: =IF((B37/Holdco_Size)<=0,-1,(B37/Holdco_Size)^(1/Hold_Short)-1) -> 0.16099973 | C40: =IF((C37/Holdco_Size)<=0,-1,(C37/Holdco_Size)^(1/Hold_Short)-1) -> 0.28032381 | D40: =IF((D37/Holdco_Size)<=0,-1,(D37/Holdco_Size)^(1/Hold_Short)-1) -> -0.047351614 | E40: =IF((E37/Holdco_Size)<=0,-1,(E37/Holdco_Size)^(1/Hold_Short)-1) -> 0.21405233 | F40: =IF((F37/Holdco_Size)<=0,-1,(F37/Holdco_Size)^(1/Hold_Short)-1) -> 0.18357543
A41: KS-PME vs SPX | B41: =B38/(1+SPX_CAGR)^Hold_Short -> 1.3709705 | C41: =C38/(1+SPX_CAGR)^Hold_Short -> 2.2359733 | D41: =D38/(1+SPX_CAGR)^Hold_Short -> 0.50995363 | E41: =E38/(1+SPX_CAGR)^Hold_Short -> 1.7141726 | F41: =F38/(1+SPX_CAGR)^Hold_Short -> 1.509549
A42: KS-PME vs NDX | B42: =B38/(1+NDX_CAGR)^Hold_Short -> 1.1449022 | C42: =C38/(1+NDX_CAGR)^Hold_Short -> 1.867269 | D42: =D38/(1+NDX_CAGR)^Hold_Short -> 0.42586403 | E42: =E38/(1+NDX_CAGR)^Hold_Short -> 1.4315114 | F42: =F38/(1+NDX_CAGR)^Hold_Short -> 1.2606296
...

Sheet Macro Overlay
A1: MACRO, GEOPOLITICAL & DEFENSE-SUPERCYCLE OVERLAY
A2: Grounds the sleeve return assumptions in current comps and the geopolitical/macro picture. Figures as of ~Jun-Sep 2026; sourced below.
A4: 1 | PUBLIC & PRIVATE COMPS GROUNDING THE SLEEVE ASSUMPTIONS
A5: Comparable | B5: Metric | C5: Value | D5: Note / relevance
A6: ITA (US Aero & Defense ETF) | B6: Total return 1/5/10-yr | C6: 29.3% / 18.2% / 15.7% | D6: Defense supercycle already priced into public primes (as of Jun-26)
A7: SOXX (Semiconductor ETF) | B7: Total return 1/5/10-yr | C7: 169.6% / 34.5% / 36.6% | D7: AI-driven surge; forward mean-reversion risk off a huge base
A8: 50/50 ITA/SOXX basket | B8: Trailing 5-yr blend | C8: ~26.3% | D8: Thematic hurdle; model uses 15% FORWARD (tempered)
A9: SPX / NDX | B9: Forward CAGR (model) | C9: 9.0% / 13.0% | D9: Broad-market floor benchmarks
A10: Rheinmetall (RHM) | B10: Rev growth / EV-Rev / EV-EBITDA | C10: 40% / 4.0x / 17.3x | D10: European rearmament bellwether; $54B cap
A11: AeroVironment (AVAV) | B11: TTM rev / YoY | C11: $1.61B / +117% | D11: Drones/loitering munitions (incl. M&A); supercycle demand
A12: L3Harris (LHX) | B12: EV-Rev / EV-EBITDA | C12: 2.6x / 15.1x | D12: Established prime multiple anchor
A13: Saronic (private) | B13: Valuation / 2025 rev | C13: $9.25B / $200M (+1,500%) | D13: Naval autonomy hypergrowth (Series D, Mar-26)
A14: Anduril (private) | B14: Valuation / 2025 rev | C14: $61B / $2.2B (+120%) | D14: Scale-up reference; $20B Army ceiling (Mar-26)
A15: Epirus (private) | B15: Directed energy / HPM | C15: Growth-stage | D15: Counter-drone; Weapons-sleeve holding
A16: Grounded sleeve assumptions (Base/Bull/Bear/Shock gross CAGR): Weapons 22/34/5/32% (original sleeve memo, reference only — model runs bottom-up per name with the munitions/FMS overlay); Consumer modeled bottom-up per-name, two now market-priced via Forge secondary (Quince 28/45/2/-18%, Whoop 27/42/-3/-16%, The Farmer's Dog 22/34/10/-5% @ $3.76B Forge-implied, Made In Cookware 14/26/-10/-14% est., Thrive Market 7/16/-5/-8% @ ~$945M Forge-implied (down from $1.29B Series C), Plunge 20/50/-22/-28% est.); thematic basket 15% fwd. IQT-mirror is bottom-up.
A18: 2 | DEFENSE SUPERCYCLE DRIVERS
A19: • NATO 5%-of-GDP pledge (Hague summit, Jun-2025): 3.5% core defense + 1.5% defense-related, on a path to 2035 — a structural, decade-long step-up, not a cyclical bump.
A20: • European allies + Canada raised defense spending ~20% in 2025 alone; all allies now above the old 2% floor. Rheinmetall growing 40%/yr is the bellwether.
A21: • Munitions/energetics replenishment (Ukraine drawdown) + naval autonomy (Replicator) + counter-drone are the fastest-growing demand pools — directly the Weapons sleeve (Helicon, Saronic, Epirus).
A23: 3 | CHINA & GEOPOLITICAL PICTURE
A24: • China official defense budget ~1.78T yuan (~$245B) for 2025, +7.2% YoY (widely cited; pre-cutoff — confirm 2026 figure) — sustained double-digit real modernization for a decade.
A25: • 'Davidson window' (PLA capability vs. Taiwan by 2027) frames the tail-risk timeline the TSMC-Shock scenario models — the single point of failure is TSMC leading-edge capacity.
A26: • US-China tech decoupling: export controls on advanced semis/tooling, entity-list expansion, and reshoring incentives are the policy tailwind behind the IQT-mirror sleeve's sovereign-chokepoint names.
A28: 4 | GLOBAL MACRO BACKDROP
A29: • Rates/exit markets: the Fed path drives PE exit windows and long-duration deep-tech valuations most — a higher-for-longer regime compresses the IQT sleeve's terminal multiples and delays exits (lengthens duration, lowers DPI timing).
A30: • USD & inflation: a decoupling/Taiwan shock is inflationary (supply shock) and USD-volatile — negative for the Consumer sleeve overall, though now modeled per-name on the Consumer Sleeve tab: import/hardware-exposed names (Quince, Whoop, Made In, Plunge) take the sharper Shock hit via COGS/chip-supply, while staple/subscription names (Farmer's Dog, Thrive Market) are more defensive; Goat Group (discretionary resale demand + cross-border logistics) also skews Shock-worse-than-Bear, while Stripe (fee-based payments infra, not import-exposed) skews milder, in line with its tighter Bear/Shock spread on the Consumer Sleeve tab.
... A39: 5 | DRIVER x SLEEVE MAPPING (direction of impact)
A40: Driver | B40: IQT-mirror | C40: Weapons | D40: Consumer / Value
A41: NATO / EU rearmament | B41: + | C41: + + | D41: 0
A42: US budget / Replicator / munitions | B42: + | C42: + + | D42: 0
A43: Classified / black-budget growth (+14% IC) | B43: + + (IQT = CIA arm) | C43: + + | D43: 0
A44: China modernization / decoupling | B44: + + | C44: + | D44: -
A45: Taiwan / TSMC shock | B45: + + (convex) | C45: + + (conflict demand) | D45: - (inflation/spend)
A46: CHIPS / reshoring capital | B46: + + | C46: + | D46: 0
A47: Higher-for-longer rates | B47: - (long-duration) | C47: - / 0 | D47: -
A48: USD strength / inflation | B48: 0 / - | C48: 0 | D48: - -
A49: Consumer spending cycle | B49: 0 | C49: 0 | D49: + + (primary driver)
A51: 6 | KEY TAKEAWAY
A52: • The supercycle is already loudly priced in PUBLIC comps (ITA +29% 1yr, SOXX +170% 1yr) — so the edge is NOT the theme being undiscovered; it is capturing it at PRIVATE / VC-stage entry before the public re-rate. That is why the scoreboard is KS-PME vs the ITA/SOXX basket, not vs SPX.
A53: • The barbell's logic: Weapons + IQT are both long the geopolitical supercycle (opex + capex legs) and both convex to a Taiwan/TSMC shock; Consumer is the uncorrelated ballast that carries near-term DPI and is the one sleeve hurt by the shock. Net holdco is long the supercycle with a spending-cycle diversifier.
...

Sheet Assumptions
A1: ASSUMPTIONS & INPUTS
A2: Blue = hardcoded input / lever. TSMC-Shock CAGR (col I) is computed on the Defense Supercycle tab. All $M.
A4: FUND TERMS (apply to the holdco and all three sleeves) | E4: VEHICLE HOLD PERIODS (yrs) — blue = lever
A5: Committed capital ($M) | B5: =IQT_Size -> 250 | C5: IQT sleeve = 1 of 3 holdco sub-funds (see Holdco Summary) | E5: Short hold (yrs) | F5: 5 | G5: Drives every 'short-hold' block model-wide
A6: Initial deployment ($M) | B6: 225 | C6: Memo — reserve embedded in retention | E6: Mid hold (yrs) | F6: 7 | G6: Drives every 'mid-hold' block; recommended vehicle
A7: Follow-on reserve ($M) | B7: 25 | C7: Pro-rata defense on winners | E7: Long hold (yrs) | F7: 10 | G7: Drives every 'long-hold' block model-wide
A8: Mgmt fee (% of committed / yr) | B8: 0.02 | C8: Charged over full vehicle life
A9: Carried interest (%) | B9: 0.2 | C9: Over pref, no catch-up modeled
A10: Preferred return (% comp.) | B10: 0.08 | C10: 8% compounded hurdle
A11: ="Retention @ "&Hold_Short&"yr" -> Retention @ 5yr | B11: 0.85 | C11: Ownership kept after dilution
A12: ="Retention @ "&Hold_Mid&"yr" -> Retention @ 7yr | B12: 0.78
A13: ="Retention @ "&Hold_Long&"yr" -> Retention @ 10yr | B13: 0.68
A16: PORTFOLIO — ENTRY MARKS, CHECKS & GROWTH ASSUMPTIONS
A17: Company | B17: Entry post-$M | C17: Check ($M) | D17: Own % | E17: Tranche | F17: Base CAGR | G17: Bull CAGR | H17: Bear CAGR | I17: TSMC-Shock | J17: Valuation basis
A18: Substrate (anchor) | B18: 1050 | C18: 80 | D18: =C18/B18 -> 0.076190476 | E18: Anchor / growth | F18: 0.22 | G18: 0.34 | H18: -0.18 | I18: ='Defense Supercycle'!I24 -> 0.408 | J18: Est. >$1.0B post (Oct-25 round)
A19: EUV Tech | B19: 180 | C19: 30 | D19: =C19/B19 -> 0.16666667 | E19: Growth core | F19: 0.14 | G19: 0.26 | H19: 0.03 | I19: ='Defense Supercycle'!I25 -> 0.304 | J19: Est. — undisclosed (rev-gen niche)
A20: ThinTronics | B20: 120 | C20: 22.5 | D20: =C20/B20 -> 0.1875 | E20: Growth core | F20: 0.26 | G20: 0.38 | H20: -0.1 | I20: ='Defense Supercycle'!I26 -> 0.416 | J20: Est. — undisclosed + $50M CHIPS LOI
A21: EdgeCortix | B21: 350 | C21: 30.5 | D21: =C21/B21 -> 0.087142857 | E21: Growth core | F21: 0.24 | G21: 0.36 | H21: -0.08 | I21: ='Defense Supercycle'!I27 -> 0.264 | J21: Est. — undisclosed (>$110M raised)
A22: Syntiant | B22: 700 | C22: 31.5 | D22: =C22/B22 -> 0.045 | E22: Pre-IPO / liquid | F22: 0.16 | G22: 0.28 | H22: -0.02 | I22: ='Defense Supercycle'!I28 -> 0.22 | J22: $646M Dec-24; S-1 filed (SYTN)
A23: Infleqtion | B23: 3000 | C23: 25 | D23: =C23/B23 -> 0.0083333333 | E23: Public / liquid | F23: 0.15 | G23: 0.27 | H23: -0.1 | I23: ='Defense Supercycle'!I29 -> 0.222 | J23: Public NYSE:INFQ (~$3.0B mkt cap)
A24: Diraq | B24: 150 | C24: 14 | D24: =C24/B24 -> 0.093333333 | E24: Quantum venture | F24: 0.3 | G24: 0.42 | H24: -0.22 | I24: ='Defense Supercycle'!I30 -> 0.384 | J24: Never disclosed (unverified ~$107M)
A25: Mueon | B25: 65 | C25: 10 | D25: =C25/B25 -> 0.15384615 | E25: Seed optionality | F25: 0.32 | G25: 0.44 | H25: -0.28 | I25: ='Defense Supercycle'!I31 -> 0.396 | J25: Est. — undisclosed ($15.5M seed)
A26: DefendEye | B26: 50 | C26: 6.5 | D26: =C26/B26 -> 0.13 | E26: Seed optionality | F26: 0.28 | G26: 0.4 | H26: -0.25 | I26: ='Defense Supercycle'!I32 -> 0.216 | J26: Est. — undisclosed seed
A27: TOTAL DEPLOYED | C27: =SUM(C18:C26) -> 250
A28: ="Check: deployed capital (C27) "&TEXT(C27,"$#,##0")&"M vs committed (B5) "&TEXT(B5,"$#,##0")&"M — "&IF(ABS(C27-B5)<0.5,"OK","MISMATCH") -> Check: deployed capital (C27) $250M vs committed (B5) $250M — OK
A29: ="Check: deployment (B6) + reserve (B7) = "&TEXT(B6+B7,"$#,##0")&"M vs committed (B5) "&TEXT(B5,"$#,##0")&"M — "&IF(ABS(B6+B7-B5)<0.5,"OK","MISMATCH") -> Check: deployment (B6) + reserve (B7) = $250M vs committed (B5) $250M — OK

Sheet Defense Supercycle
A1: DEFENSE SUPERCYCLE — STRATEGIC SCORING & SHOCK ENGINE
A2: Winning the US-China AI/semiconductor race + insulating against a Taiwan / loss-of-TSMC scenario. Blue = lever.
A4: STRATEGIC AXIS WEIGHTS (must sum to 100%)
A5: China AI/semi-race criticality | B5: 0.25 | C5: Advances US lead in AI compute / advanced nodes
A6: Taiwan / TSMC-insulation value | B6: 0.3 | C6: Reduces US dependence on Taiwan-based fabrication
A7: Government / defense embeddedness | B7: 0.15 | C7: IQT + DoD/DIU/DARPA/CHIPS pull
A8: CFIUS-clean / US-sovereign | B8: 0.15 | C8: US domicile & ownership; acquirable by US gov/primes
A9: Supply-chain chokepoint leverage | B9: 0.15 | C9: Sole/near-sole source at a critical node
A10: Sum (check = 100%) | B10: =SUM(B5:B9) -> 1
A12: TSMC-SHOCK CALIBRATION
A13: Pivot score (neutral) | B13: 2.5 | C13: Composite above pivot -> positive re-rating; below -> drag
A14: Premium per point (CAGR) | B14: 0.08 | C14: CAGR uplift per composite point above pivot, added to Base CAGR
A16: SCENARIO PROBABILITY WEIGHTS (must sum to 100%)
A17: Base | B17: 0.45
A18: Bull | B18: 0.25
A19: Bear | B19: 0.15
A20: TSMC-Shock | B20: 0.15
A21: Sum (check = 100%) | B21: =SUM(B17:B20) -> 1
A22: STRATEGIC SCORING MATRIX (1 = low, 5 = high; blue = lever)
A23: Company | B23: China Race | C23: TSMC Insul. | D23: Gov/Defense | E23: CFIUS-Clean | F23: Chokepoint | G23: Composite | H23: Shock prem. | I23: Shock CAGR
A24: Substrate (anchor) | B24: 5 | C24: 5 | D24: 4 | E24: 5 | F24: 5 | G24: =B24*$B$5+C24*$B$6+D24*$B$7+E24*$B$8+F24*$B$9 -> 4.85 | H24: =(G24-$B$13)*$B$14 -> 0.188 | I24: =Assumptions!F18+H24 -> 0.408
A25: EUV Tech | B25: 5 | C25: 4 | D25: 4 | E25: 5 | F25: 5 | G25: =B25*$B$5+C25*$B$6+D25*$B$7+E25*$B$8+F25*$B$9 -> 4.55 | H25: =(G25-$B$13)*$B$14 -> 0.164 | I25: =Assumptions!F19+H25 -> 0.304
A26: ThinTronics | B26: 4 | C26: 5 | D26: 4 | E26: 5 | F26: 4 | G26: =B26*$B$5+C26*$B$6+D26*$B$7+E26*$B$8+F26*$B$9 -> 4.45 | H26: =(G26-$B$13)*$B$14 -> 0.156 | I26: =Assumptions!F20+H26 -> 0.416
A27: EdgeCortix | B27: 4 | C27: 2 | D27: 4 | E27: 2 | F27: 2 | G27: =B27*$B$5+C27*$B$6+D27*$B$7+E27*$B$8+F27*$B$9 -> 2.8 | H27: =(G27-$B$13)*$B$14 -> 0.024 | I27: =Assumptions!F21+H27 -> 0.264
A28: Syntiant | B28: 4 | C28: 2 | D28: 4 | E28: 5 | F28: 2 | G28: =B28*$B$5+C28*$B$6+D28*$B$7+E28*$B$8+F28*$B$9 -> 3.25 | H28: =(G28-$B$13)*$B$14 -> 0.06 | I28: =Assumptions!F22+H28 -> 0.22
A29: Infleqtion | B29: 4 | C29: 2 | D29: 4 | E29: 5 | F29: 3 | G29: =B29*$B$5+C29*$B$6+D29*$B$7+E29*$B$8+F29*$B$9 -> 3.4 | H29: =(G29-$B$13)*$B$14 -> 0.072 | I29: =Assumptions!F23+H29 -> 0.222
A30: Diraq | B30: 4 | C30: 4 | D30: 4 | E30: 2 | F30: 3 | G30: =B30*$B$5+C30*$B$6+D30*$B$7+E30*$B$8+F30*$B$9 -> 3.55 | H30: =(G30-$B$13)*$B$14 -> 0.084 | I30: =Assumptions!F24+H30 -> 0.384
A31: Mueon | B31: 3 | C31: 3 | D31: 4 | E31: 5 | F31: 3 | G31: =B31*$B$5+C31*$B$6+D31*$B$7+E31*$B$8+F31*$B$9 -> 3.45 | H31: =(G31-$B$13)*$B$14 -> 0.076 | I31: =Assumptions!F25+H31 -> 0.396
A32: DefendEye | B32: 2 | C32: 1 | D32: 3 | E32: 2 | F32: 1 | G32: =B32*$B$5+C32*$B$6+D32*$B$7+E32*$B$8+F32*$B$9 -> 1.7 | H32: =(G32-$B$13)*$B$14 -> -0.064 | I32: =Assumptions!F26+H32 -> 0.216
A33: Avg / weighted | G33: =AVERAGE(G24:G32) -> 3.5555556
A35: SCENARIO NARRATIVE — TSMC SHOCK / TAIWAN CONTINGENCY
A36: • Trigger: a Taiwan blockade/quarantine, kinetic event, or hard US-China tech decoupling that removes or severely constrains access to TSMC's leading-edge capacity — the single point of failure in the AI-compute supply chain.
A37: • Winners (large re-rate): the US sovereign-chokepoint names. Substrate (domestic X-ray litho / fabs), EUV Tech (at-wavelength EUV metrology — no fab qualifies without it), ThinTronics (US ABF/substrate materials vs Japan's Ajinomoto monopoly). Onshoring becomes a national-security imperative; demand + pricing power inflect.
A38: • Partial winners: Mueon (US advanced packaging / rack density), Infleqtion & Diraq (quantum race convexity — the 'next' compute paradigm if classical leading-edge is contested), Syntiant (US-fab-flexible edge inference).
A39: • Laggards / drag: EdgeCortix (Japan HQ + TSMC-Kumamoto fab exposure, near-term supply hit and CFIUS ceiling) and DefendEye (foreign-nexus, low semiconductor-sovereignty relevance).
A40: • Portfolio design implication: the book is intentionally overweight the sovereign core, so a tail event that would hurt a generic tech portfolio is where this one is most convex. That asymmetry is the thesis.
A42: IQT WARTIME-FUNCTION MAP — SUBSTRATE-ANCHORED SLEEVE (from uploaded IQT strategic analysis)
A43: Strategic cluster | B43: Holdings | D43: Wartime function / why IQT funds it
A44: TSMC-alternative: packaging & substrates | B44: Substrate, ThinTronics, EUV Tech | D44: Build & package chips domestically if Taiwan is blockaded — X-ray litho (Substrate), CoWoS-alternative insulators for advanced packaging (ThinTronics, + $50M CHIPS LOI Jul-26), at-wavelength EUV metrology to keep domestic litho running (EUV Tech).
A45: Denied-environment edge AI | B45: Syntiant, EdgeCortix | D45: Onboard AI for autonomous weapons when GPS / cloud / comms are jammed by PLA electronic warfare — ultra-low-power SWaP-constrained inference on drones, missiles, naval sensors. Syntiant signed a Nov-2025 IQT strategic technology-development agreement; EdgeCortix's DNA accelerator targets defense/aerospace at the tactical edge.
...

Sheet Allocation
A1: ALLOCATION & POSITION STRUCTURE
A2: Green = linked. Composite pulled from Defense Supercycle tab. Ownership >15% = significant minority (seek board seat / observer).
A4: Company | B4: Check ($M) | C4: Own % | D4: % Fund | E4: Supercycle | F4: Tranche | G4: Domicile | H4: Structuring / diligence flag
A5: =Assumptions!A18 -> Substrate (anchor) | B5: =Assumptions!C18 -> 80 | C5: =Assumptions!D18 -> 0.076190476 | D5: =Assumptions!C18/IQT_Committed -> 0.32 | E5: ='Defense Supercycle'!G24 -> 4.85 | F5: =Assumptions!E18 -> Anchor / growth | G5: USA (SF, CA) | H5: Anchor. Binary tech risk — capped ~32% of fund; the core sovereign-litho bet.
A6: =Assumptions!A19 -> EUV Tech | B6: =Assumptions!C19 -> 30 | C6: =Assumptions!D19 -> 0.16666667 | D6: =Assumptions!C19/IQT_Committed -> 0.12 | E6: ='Defense Supercycle'!G25 -> 4.55 | F6: =Assumptions!E19 -> Growth core | G6: USA (CA) | H6: Rev-generating niche leader — best risk-adjusted. ~17% stake = significant minority; seek a board seat.
A7: =Assumptions!A20 -> ThinTronics | B7: =Assumptions!C20 -> 22.5 | C7: =Assumptions!D20 -> 0.1875 | D7: =Assumptions!C20/IQT_Committed -> 0.09 | E7: ='Defense Supercycle'!G26 -> 4.45 | F7: =Assumptions!E20 -> Growth core | G7: USA (CA) | H7: CHIPS $50M LOI catalyst. ~19% stake = significant minority; likely primary + secondary blend.
A8: =Assumptions!A21 -> EdgeCortix | B8: =Assumptions!C21 -> 30.5 | C8: =Assumptions!D21 -> 0.087142857 | D8: =Assumptions!C21/IQT_Committed -> 0.122 | E8: ='Defense Supercycle'!G27 -> 2.8 | F8: =Assumptions!E21 -> Growth core | G8: JAPAN (Tokyo) | H8: CFIUS/allied flag — minority only. Renesas natural acquirer. TSMC-Kumamoto fab exposure.
A9: =Assumptions!A22 -> Syntiant | B9: =Assumptions!C22 -> 31.5 | C9: =Assumptions!D22 -> 0.045 | D9: =Assumptions!C22/IQT_Committed -> 0.126 | E9: ='Defense Supercycle'!G28 -> 3.25 | F9: =Assumptions!E22 -> Pre-IPO / liquid | G9: USA (CA) | H9: Pre-IPO secondary or SYTN cornerstone. Watch pricing vs $646M Dec-24 mark.
A10: =Assumptions!A23 -> Infleqtion | B10: =Assumptions!C23 -> 25 | C10: =Assumptions!D23 -> 0.0083333333 | D10: =Assumptions!C23/IQT_Committed -> 0.1 | E10: ='Defense Supercycle'!G29 -> 3.4 | F10: =Assumptions!E23 -> Public / liquid | G10: USA (CO) | H10: Public (INFQ). PIPE/secondary. Listed quantum benchmark for Diraq.
A11: =Assumptions!A24 -> Diraq | B11: =Assumptions!C24 -> 14 | C11: =Assumptions!D24 -> 0.093333333 | D11: =Assumptions!C24/IQT_Committed -> 0.056 | E11: ='Defense Supercycle'!G30 -> 3.55 | F11: =Assumptions!E24 -> Quantum venture | G11: AUSTRALIA (Sydney) | H11: Allied flag — minority. NRFC sovereignty covenants. AUKUS-aligned quantum optionality.
A12: =Assumptions!A25 -> Mueon | B12: =Assumptions!C25 -> 10 | C12: =Assumptions!D25 -> 0.15384615 | D12: =Assumptions!C25/IQT_Committed -> 0.04 | E12: ='Defense Supercycle'!G31 -> 3.45 | F12: =Assumptions!E25 -> Seed optionality | G12: USA (OR) | H12: Seed. Milestone-gated. Needs a shipping Cubelet design-win to scale exposure.
A13: =Assumptions!A26 -> DefendEye | B13: =Assumptions!C26 -> 6.5 | C13: =Assumptions!D26 -> 0.13 | D13: =Assumptions!C26/IQT_Committed -> 0.026 | E13: ='Defense Supercycle'!G32 -> 1.7 | F13: =Assumptions!E26 -> Seed optionality | G13: USA (FL)+POLAND | H13: EU cap table + Krakow mfg — Blue UAS/NDAA provenance diligence before US-defense thesis.
A14: TOTAL | B14: =SUM(B5:B13) -> 250 | D14: =SUM(D5:D13) -> 1

Sheet Portfolio Returns
A1: PORTFOLIO RETURNS BY HOLD & SCENARIO
A2: Proceeds = Check x (1+CAGR)^Hold x Retention. MOIC = Proceeds/Check. Gross IRR = MOIC^(1/Hold)-1.
A4: =Hold_Short&"-YEAR HOLD VEHICLE" -> 5-YEAR HOLD VEHICLE
A5: Company | B5: Check ($M) | C5: Base $ | D5: Base MOIC | E5: Base IRR | F5: Bull $ | G5: Bull MOIC | H5: Bull IRR | I5: Bear $ | J5: Bear MOIC | K5: Bear IRR | L5: Shock $ | M5: Shock MOIC | N5: Shock IRR
A6: =Assumptions!A18 -> Substrate (anchor) | B6: =Assumptions!C18 -> 80 | C6: =Assumptions!C18*(1+Assumptions!F18)^Hold_Short*Ret_IQT_Short -> 183.78416 | D6: =C6/B6 -> 2.2973019 | E6: =IF((C6/B6)<=0,-1,(C6/B6)^(1/Hold_Short)-1) -> 0.18098292 | F6: =Assumptions!C18*(1+Assumptions!G18)^Hold_Short*Ret_IQT_Short -> 293.78722 | G6: =F6/B6 -> 3.6723403 | H6: =IF((F6/B6)<=0,-1,(F6/B6)^(1/Hold_Short)-1) -> 0.29714517 | I6: =Assumptions!C18*(1+Assumptions!H18)^Hold_Short*Ret_IQT_Short -> 25.210309 | J6: =I6/B6 -> 0.31512887 | K6: =IF((I6/B6)<=0,-1,(I6/B6)^(1/Hold_Short)-1) -> -0.2062246 | L6: =Assumptions!C18*(1+Assumptions!I18)^Hold_Short*Ret_IQT_Short -> 376.28958 | M6: =L6/B6 -> 4.7036197 | N6: =IF((L6/B6)<=0,-1,(L6/B6)^(1/Hold_Short)-1) -> 0.36297045
A7: =Assumptions!A19 -> EUV Tech | B7: =Assumptions!C19 -> 30 | C7: =Assumptions!C19*(1+Assumptions!F19)^Hold_Short*Ret_IQT_Short -> 49.098072 | D7: =C7/B7 -> 1.6366024 | E7: =IF((C7/B7)<=0,-1,(C7/B7)^(1/Hold_Short)-1) -> 0.10354141 | F7: =Assumptions!C19*(1+Assumptions!G19)^Hold_Short*Ret_IQT_Short -> 80.982822 | G7: =F7/B7 -> 2.6994274 | H7: =IF((F7/B7)<=0,-1,(F7/B7)^(1/Hold_Short)-1) -> 0.21970367 | I7: =Assumptions!C19*(1+Assumptions!H19)^Hold_Short*Ret_IQT_Short -> 29.561489 | J7: =I7/B7 -> 0.98538296 | K7: =IF((I7/B7)<=0,-1,(I7/B7)^(1/Hold_Short)-1) -> -0.0029406514 | L7: =Assumptions!C19*(1+Assumptions!I19)^Hold_Short*Ret_IQT_Short -> 96.145317 | M7: =L7/B7 -> 3.2048439 | N7: =IF((L7/B7)<=0,-1,(L7/B7)^(1/Hold_Short)-1) -> 0.2622965
A8: =Assumptions!A20 -> ThinTronics | B8: =Assumptions!C20 -> 22.5 | C8: =Assumptions!C20*(1+Assumptions!F20)^Hold_Short*Ret_IQT_Short -> 60.737116 | D8: =C8/B8 -> 2.6994274 | E8: =IF((C8/B8)<=0,-1,(C8/B8)^(1/Hold_Short)-1) -> 0.21970367 | F8: =Assumptions!C20*(1+Assumptions!G20)^Hold_Short*Ret_IQT_Short -> 95.718719 | G8: =F8/B8 -> 4.2541653 | H8: =IF((F8/B8)<=0,-1,(F8/B8)^(1/Hold_Short)-1) -> 0.33586592 | I8: =Assumptions!C20*(1+Assumptions!H20)^Hold_Short*Ret_IQT_Short -> 11.293121 | J8: =I8/B8 -> 0.5019165 | K8: =IF((I8/B8)<=0,-1,(I8/B8)^(1/Hold_Short)-1) -> -0.12878309 | L8: =Assumptions!C20*(1+Assumptions!I20)^Hold_Short*Ret_IQT_Short -> 108.87238 | M8: =L8/B8 -> 4.8387724 | N8: =IF((L8/B8)<=0,-1,(L8/B8)^(1/Hold_Short)-1) -> 0.3707146
A9: =Assumptions!A21 -> EdgeCortix | B9: =Assumptions!C21 -> 30.5 | C9: =Assumptions!C21*(1+Assumptions!F21)^Hold_Short*Ret_IQT_Short -> 76.00238 | D9: =C9/B9 -> 2.4918813 | E9: =IF((C9/B9)<=0,-1,(C9/B9)^(1/Hold_Short)-1) -> 0.20034329 | F9: =Assumptions!C21*(1+Assumptions!G21)^Hold_Short*Ret_IQT_Short -> 120.61833 | G9: =F9/B9 -> 3.9546993 | H9: =IF((F9/B9)<=0,-1,(F9/B9)^(1/Hold_Short)-1) -> 0.31650555 | I9: =Assumptions!C21*(1+Assumptions!H21)^Hold_Short*Ret_IQT_Short -> 17.086688 | J9: =I9/B9 -> 0.56021929 | K9: =IF((I9/B9)<=0,-1,(I9/B9)^(1/Hold_Short)-1) -> -0.10942272 | L9: =Assumptions!C21*(1+Assumptions!I21)^Hold_Short*Ret_IQT_Short -> 83.647725 | M9: =L9/B9 -> 2.7425484 | N9: =IF((L9/B9)<=0,-1,(L9/B9)^(1/Hold_Short)-1) -> 0.22357574
A10: =Assumptions!A22 -> Syntiant | B10: =Assumptions!C22 -> 31.5 | C10: =Assumptions!C22*(1+Assumptions!F22)^Hold_Short*Ret_IQT_Short -> 56.236648 | D10: =C10/B10 -> 1.7852904 | E10: =IF((C10/B10)<=0,-1,(C10/B10)^(1/Hold_Short)-1) -> 0.12290179 | F10: =Assumptions!C22*(1+Assumptions!G22)^Hold_Short*Ret_IQT_Short -> 91.998199 | G10: =F10/B10 -> 2.9205778 | H10: =IF((F10/B10)<=0,-1,(F10/B10)^(1/Hold_Short)-1) -> 0.23906404 | I10: =Assumptions!C22*(1+Assumptions!H22)^Hold_Short*Ret_IQT_Short -> 24.202479 | J10: =I10/B10 -> 0.76833268 | K10: =IF((I10/B10)<=0,-1,(I10/B10)^(1/Hold_Short)-1) -> -0.051341591 | L10: =Assumptions!C22*(1+Assumptions!I22)^Hold_Short*Ret_IQT_Short -> 72.365011 | M10: =L10/B10 -> 2.2973019 | N10: =IF((L10/B10)<=0,-1,(L10/B10)^(1/Hold_Short)-1) -> 0.18098292
A11: =Assumptions!A23 -> Infleqtion | B11: =Assumptions!C23 -> 25 | C11: =Assumptions!C23*(1+Assumptions!F23)^Hold_Short*Ret_IQT_Short -> 42.74134 | D11: =C11/B11 -> 1.7096536 | E11: =IF((C11/B11)<=0,-1,(C11/B11)^(1/Hold_Short)-1) -> 0.1132216 | F11: =Assumptions!C23*(1+Assumptions!G23)^Hold_Short*Ret_IQT_Short -> 70.206535 | G11: =F11/B11 -> 2.8082614 | H11: =IF((F11/B11)<=0,-1,(F11/B11)^(1/Hold_Short)-1) -> 0.22938386 | I11: =Assumptions!C23*(1+Assumptions!H23)^Hold_Short*Ret_IQT_Short -> 12.547913 | J11: =I11/B11 -> 0.5019165 | K11: =IF((I11/B11)<=0,-1,(I11/B11)^(1/Hold_Short)-1) -> -0.12878309 | L11: =Assumptions!C23*(1+Assumptions!I23)^Hold_Short*Ret_IQT_Short -> 57.904853 | M11: =L11/B11 -> 2.3161941 | N11: =IF((L11/B11)<=0,-1,(L11/B11)^(1/Hold_Short)-1) -> 0.18291896
A12: =Assumptions!A24 -> Diraq | B12: =Assumptions!C24 -> 14 | C12: =Assumptions!C24*(1+Assumptions!F24)^Hold_Short*Ret_IQT_Short -> 44.183867 | D12: =C12/B12 -> 3.1559905 | E12: =IF((C12/B12)<=0,-1,(C12/B12)^(1/Hold_Short)-1) -> 0.25842442 | F12: =Assumptions!C24*(1+Assumptions!G24)^Hold_Short*Ret_IQT_Short -> 68.705054 | G12: =F12/B12 -> 4.9075038 | H12: =IF((F12/B12)<=0,-1,(F12/B12)^(1/Hold_Short)-1) -> 0.37458667 | I12: =Assumptions!C24*(1+Assumptions!H24)^Hold_Short*Ret_IQT_Short -> 3.4357375 | J12: =I12/B12 -> 0.24540982 | K12: =IF((I12/B12)<=0,-1,(I12/B12)^(1/Hold_Short)-1) -> -0.24494535 | L12: =Assumptions!C24*(1+Assumptions!I24)^Hold_Short*Ret_IQT_Short -> 60.426496 | M12: =L12/B12 -> 4.3161783 | N12: =IF((L12/B12)<=0,-1,(L12/B12)^(1/Hold_Short)-1) -> 0.339738
A13: =Assumptions!A25 -> Mueon | B13: =Assumptions!C25 -> 10 | C13: =Assumptions!C25*(1+Assumptions!F25)^Hold_Short*Ret_IQT_Short -> 34.063446 | D13: =C13/B13 -> 3.4063446 | E13: =IF((C13/B13)<=0,-1,(C13/B13)^(1/Hold_Short)-1) -> 0.2777848 | F13: =Assumptions!C25*(1+Assumptions!G25)^Hold_Short*Ret_IQT_Short -> 52.62976 | G13: =F13/B13 -> 5.262976 | H13: =IF((F13/B13)<=0,-1,(F13/B13)^(1/Hold_Short)-1) -> 0.39394705 | I13: =Assumptions!C25*(1+Assumptions!H25)^Hold_Short*Ret_IQT_Short -> 1.64468 | J13: =I13/B13 -> 0.164468 | K13: =IF((I13/B13)<=0,-1,(I13/B13)^(1/Hold_Short)-1) -> -0.30302647 | L13: =Assumptions!C25*(1+Assumptions!I25)^Hold_Short*Ret_IQT_Short -> 45.065689 | M13: =L13/B13 -> 4.5065689 | N13: =IF((L13/B13)<=0,-1,(L13/B13)^(1/Hold_Short)-1) -> 0.35135422
A14: =Assumptions!A26 -> DefendEye | B14: =Assumptions!C26 -> 6.5 | C14: =Assumptions!C26*(1+Assumptions!F26)^Hold_Short*Ret_IQT_Short -> 18.983755 | D14: =C14/B14 -> 2.9205778 | E14: =IF((C14/B14)<=0,-1,(C14/B14)^(1/Hold_Short)-1) -> 0.23906404 | F14: =Assumptions!C26*(1+Assumptions!G26)^Hold_Short*Ret_IQT_Short -> 29.714776 | G14: =F14/B14 -> 4.571504 | H14: =IF((F14/B14)<=0,-1,(F14/B14)^(1/Hold_Short)-1) -> 0.3552263 | I14: =Assumptions!C26*(1+Assumptions!H26)^Hold_Short*Ret_IQT_Short -> 1.3111084 | J14: =I14/B14 -> 0.20170898 | K14: =IF((I14/B14)<=0,-1,(I14/B14)^(1/Hold_Short)-1) -> -0.27398591 | L14: =Assumptions!C26*(1+Assumptions!I26)^Hold_Short*Ret_IQT_Short -> 14.689268 | M14: =L14/B14 -> 2.2598874 | N14: =IF((L14/B14)<=0,-1,(L14/B14)^(1/Hold_Short)-1) -> 0.17711084
A15: FUND TOTAL | B15: =SUM(B6:B14) -> 250 | C15: =SUM(C6:C14) -> 565.83078 | D15: =C15/B15 -> 2.2633231 | E15: =IF((C15/B15)<=0,-1,(C15/B15)^(1/Hold_Short)-1) -> 0.17746854 | F15: =SUM(F6:F14) -> 904.36142 | G15: =F15/B15 -> 3.6174457 | H15: =IF((F15/B15)<=0,-1,(F15/B15)^(1/Hold_Short)-1) -> 0.29324379 | I15: =SUM(I6:I14) -> 126.29353 | J15: =I15/B15 -> 0.5051741 | K15: =IF((I15/B15)<=0,-1,(I15/B15)^(1/Hold_Short)-1) -> -0.12765512 | L15: =SUM(L6:L14) -> 915.40631 | M15: =L15/B15 -> 3.6616253 | N15: =IF((L15/B15)<=0,-1,(L15/B15)^(1/Hold_Short)-1) -> 0.29638733
A18: =Hold_Mid&"-YEAR HOLD VEHICLE" -> 7-YEAR HOLD VEHICLE
A19: Company | B19: Check ($M) | C19: Base $ | D19: Base MOIC | E19: Base IRR | F19: Bull $ | G19: Bull MOIC | H19: Bull IRR | I19: Bear $ | J19: Bear MOIC | K19: Bear IRR | L19: Shock $ | M19: Shock MOIC | N19: Shock IRR
A20: =Assumptions!A18 -> Substrate (anchor) | B20: =Assumptions!C18 -> 80 | C20: =Assumptions!C18*(1+Assumptions!F18)^Hold_Mid*Ret_IQT_Mid -> 251.01716 | D20: =C20/B20 -> 3.1377144 | E20: =IF((C20/B20)<=0,-1,(C20/B20)^(1/Hold_Mid)-1) -> 0.17745624 | F20: =Assumptions!C18*(1+Assumptions!G18)^Hold_Mid*Ret_IQT_Mid -> 484.08116 | G20: =F20/B20 -> 6.0510145 | H20: =IF((F20/B20)<=0,-1,(F20/B20)^(1/Hold_Mid)-1) -> 0.2932716 | I20: =Assumptions!C18*(1+Assumptions!H18)^Hold_Mid*Ret_IQT_Mid -> 15.555413 | J20: =I20/B20 -> 0.19444267 | K20: =IF((I20/B20)<=0,-1,(I20/B20)^(1/Hold_Mid)-1) -> -0.20859499 | L20: =Assumptions!C18*(1+Assumptions!I18)^Hold_Mid*Ret_IQT_Mid -> 684.54685 | M20: =L20/B20 -> 8.5568356 | N20: =IF((L20/B20)<=0,-1,(L20/B20)^(1/Hold_Mid)-1) -> 0.35890031
A21: =Assumptions!A19 -> EUV Tech | B21: =Assumptions!C19 -> 30 | C21: =Assumptions!C19*(1+Assumptions!F19)^Hold_Mid*Ret_IQT_Mid -> 58.55309 | D21: =C21/B21 -> 1.9517697 | E21: =IF((C21/B21)<=0,-1,(C21/B21)^(1/Hold_Mid)-1) -> 0.10024599 | F21: =Assumptions!C19*(1+Assumptions!G19)^Hold_Mid*Ret_IQT_Mid -> 117.98035 | G21: =F21/B21 -> 3.9326783 | H21: =IF((F21/B21)<=0,-1,(F21/B21)^(1/Hold_Mid)-1) -> 0.21606136 | I21: =Assumptions!C19*(1+Assumptions!H19)^Hold_Mid*Ret_IQT_Mid -> 28.779048 | J21: =I21/B21 -> 0.95930162 | K21: =IF((I21/B21)<=0,-1,(I21/B21)^(1/Hold_Mid)-1) -> -0.0059180963 | L21: =Assumptions!C19*(1+Assumptions!I19)^Hold_Mid*Ret_IQT_Mid -> 150.0234 | M21: =L21/B21 -> 5.0007799 | N21: =IF((L21/B21)<=0,-1,(L21/B21)^(1/Hold_Mid)-1) -> 0.25852699
A22: =Assumptions!A20 -> ThinTronics | B22: =Assumptions!C20 -> 22.5 | C22: =Assumptions!C20*(1+Assumptions!F20)^Hold_Mid*Ret_IQT_Mid -> 88.485261 | D22: =C22/B22 -> 3.9326783 | E22: =IF((C22/B22)<=0,-1,(C22/B22)^(1/Hold_Mid)-1) -> 0.21606136 | F22: =Assumptions!C20*(1+Assumptions!G20)^Hold_Mid*Ret_IQT_Mid -> 167.27488 | G22: =F22/B22 -> 7.4344391 | H22: =IF((F22/B22)<=0,-1,(F22/B22)^(1/Hold_Mid)-1) -> 0.33187673 | I22: =Assumptions!C20*(1+Assumptions!H20)^Hold_Mid*Ret_IQT_Mid -> 8.3941106 | J22: =I22/B22 -> 0.37307158 | K22: =IF((I22/B22)<=0,-1,(I22/B22)^(1/Hold_Mid)-1) -> -0.13138474 | L22: =Assumptions!C20*(1+Assumptions!I20)^Hold_Mid*Ret_IQT_Mid -> 200.31796 | M22: =L22/B22 -> 8.9030206 | N22: =IF((L22/B22)<=0,-1,(L22/B22)^(1/Hold_Mid)-1) -> 0.36662134
A23: =Assumptions!A21 -> EdgeCortix | B23: =Assumptions!C21 -> 30.5 | C23: =Assumptions!C21*(1+Assumptions!F21)^Hold_Mid*Ret_IQT_Mid -> 107.23739 | D23: =C23/B23 -> 3.51598 | E23: =IF((C23/B23)<=0,-1,(C23/B23)^(1/Hold_Mid)-1) -> 0.1967588 | F23: =Assumptions!C21*(1+Assumptions!G21)^Hold_Mid*Ret_IQT_Mid -> 204.72308 | G23: =F23/B23 -> 6.712232 | H23: =IF((F23/B23)<=0,-1,(F23/B23)^(1/Hold_Mid)-1) -> 0.31257416 | I23: =Assumptions!C21*(1+Assumptions!H21)^Hold_Mid*Ret_IQT_Mid -> 13.271171 | J23: =I23/B23 -> 0.43512035 | K23: =IF((I23/B23)<=0,-1,(I23/B23)^(1/Hold_Mid)-1) -> -0.11208218 | L23: =Assumptions!C21*(1+Assumptions!I21)^Hold_Mid*Ret_IQT_Mid -> 122.63769 | M23: =L23/B23 -> 4.0209079 | N23: =IF((L23/B23)<=0,-1,(L23/B23)^(1/Hold_Mid)-1) -> 0.21992187
A24: =Assumptions!A22 -> Syntiant | B24: =Assumptions!C22 -> 31.5 | C24: =Assumptions!C22*(1+Assumptions!F22)^Hold_Mid*Ret_IQT_Mid -> 69.440219 | D24: =C24/B24 -> 2.2044514 | E24: =IF((C24/B24)<=0,-1,(C24/B24)^(1/Hold_Mid)-1) -> 0.11954855 | F24: =Assumptions!C22*(1+Assumptions!G22)^Hold_Mid*Ret_IQT_Mid -> 138.3168 | G24: =F24/B24 -> 4.3910096 | H24: =IF((F24/B24)<=0,-1,(F24/B24)^(1/Hold_Mid)-1) -> 0.23536392 | I24: =Assumptions!C22*(1+Assumptions!H22)^Hold_Mid*Ret_IQT_Mid -> 21.329844 | J24: =I24/B24 -> 0.67713792 | K24: =IF((I24/B24)<=0,-1,(I24/B24)^(1/Hold_Mid)-1) -> -0.054174499 | L24: =Assumptions!C22*(1+Assumptions!I22)^Hold_Mid*Ret_IQT_Mid -> 98.838005 | M24: =L24/B24 -> 3.1377144 | N24: =IF((L24/B24)<=0,-1,(L24/B24)^(1/Hold_Mid)-1) -> 0.17745624
A25: =Assumptions!A23 -> Infleqtion | B25: =Assumptions!C23 -> 25 | C25: =Assumptions!C23*(1+Assumptions!F23)^Hold_Mid*Ret_IQT_Mid -> 51.870388 | D25: =C25/B25 -> 2.0748155 | E25: =IF((C25/B25)<=0,-1,(C25/B25)^(1/Hold_Mid)-1) -> 0.10989727 | F25: =Assumptions!C23*(1+Assumptions!G23)^Hold_Mid*Ret_IQT_Mid -> 103.91079 | G25: =F25/B25 -> 4.1564317 | H25: =IF((F25/B25)<=0,-1,(F25/B25)^(1/Hold_Mid)-1) -> 0.22571264 | I25: =Assumptions!C23*(1+Assumptions!H23)^Hold_Mid*Ret_IQT_Mid -> 9.3267896 | J25: =I25/B25 -> 0.37307158 | K25: =IF((I25/B25)<=0,-1,(I25/B25)^(1/Hold_Mid)-1) -> -0.13138474 | L25: =Assumptions!C23*(1+Assumptions!I23)^Hold_Mid*Ret_IQT_Mid -> 79.347464 | M25: =L25/B25 -> 3.1738986 | N25: =IF((L25/B25)<=0,-1,(L25/B25)^(1/Hold_Mid)-1) -> 0.17938649
