Workbook

Sheet IC Summary
A1: LEVIATHAN — 10-YR INFRASTRUCTURE & SMALL BUSINESS ROLL-UP VEHICLE
A2: Position: East Coast Marine Diesel Engine & Service Center Roll-Up | Leviathan equity cap $15M | Exit lens: Blackstone Infrastructure (Safe Harbor) / MarineMax
A4: Live scenario | B4: =Assumptions!C4 -> Base
A5: Selected exit route / year | B5: =Assumptions!$B$91 -> 1 | C5: =Assumptions!$B$90 -> 7
A7: HEADLINE (selected route & year)
A8: Leviathan equity drawn | B8: ='Exit & Returns'!C82 -> 15
A9: Gross value to Leviathan (exit + interim distributions) | B9: ='Exit & Returns'!C85 -> 203.58352
A10: Gross MOIC | B10: ='Exit & Returns'!C86 -> 13.572234
A11: Gross IRR | B11: ='Exit & Returns'!C87 -> 0.67672747
A12: Net MOIC to LPs (after 2% fee / 8% pref / 20% carry) | B12: ='Exit & Returns'!C93 -> 9.8671398
A13: Net IRR to LPs | B13: ='Exit & Returns'!C96 -> 0.60319562
A15: PLATFORM TRAJECTORY
A16: Metric | B16: Close | C16: Y3 (2029) | D16: Y5 (2031) | E16: Y7 (2033) | F16: Y10 (2036)
A17: Revenue | B17: ='Roll-Up Model'!C28 -> 10 | C17: ='Roll-Up Model'!F28 -> 38.12565 | D17: ='Roll-Up Model'!H28 -> 73.414379 | E17: ='Roll-Up Model'!J28 -> 106.96681 | F17: ='Roll-Up Model'!M28 -> 151.8704
A18: Adjusted EBITDA | B18: ='Roll-Up Model'!C40 -> 1.8 | C18: ='Roll-Up Model'!F40 -> 6.4385044 | D18: ='Roll-Up Model'!H40 -> 14.441766 | E18: ='Roll-Up Model'!J40 -> 21.52728 | F18: ='Roll-Up Model'!M40 -> 31.008694
A19: EBITDA margin | B19: ='Roll-Up Model'!C42 -> 0.18 | C19: ='Roll-Up Model'!F42 -> 0.16887593 | D19: ='Roll-Up Model'!H42 -> 0.19671577 | E19: ='Roll-Up Model'!J42 -> 0.20125196 | F19: ='Roll-Up Model'!M42 -> 0.20417865
A20: Locations | B20: ='Roll-Up Model'!C11 -> 2 | C20: ='Roll-Up Model'!F11 -> 10 | D20: ='Roll-Up Model'!H11 -> 16 | E20: ='Roll-Up Model'!J11 -> 20 | F20: ='Roll-Up Model'!M11 -> 23
A21: Contracted % of revenue | B21: ='Roll-Up Model'!C32 -> 0.15 | C21: ='Roll-Up Model'!F32 -> 0.26954275 | D21: ='Roll-Up Model'!H32 -> 0.37412893 | E21: ='Roll-Up Model'!J32 -> 0.44228914 | F21: ='Roll-Up Model'!M32 -> 0.45833662
A22: Safe Harbor embedded bays | B22: ='Roll-Up Model'!C26 -> 0 | C22: ='Roll-Up Model'!F26 -> 3.75 | D22: ='Roll-Up Model'!H26 -> 11.25 | E22: ='Roll-Up Model'!J26 -> 18.75 | F22: ='Roll-Up Model'!M26 -> 30
A23: Total leverage | B23: ='Roll-Up Model'!C86 -> 2.775 | C23: ='Roll-Up Model'!F86 -> 1.6004378 | D23: ='Roll-Up Model'!H86 -> 0.8367502 | E23: ='Roll-Up Model'!J86 -> 0.67171872 | F23: ='Roll-Up Model'!M86 -> 0.4676342
A24: Cumulative Leviathan equity | B24: ='Roll-Up Model'!C94 -> 2.9705 | C24: ='Roll-Up Model'!F94 -> 8.9657475 | D24: ='Roll-Up Model'!H94 -> 12.549817 | E24: ='Roll-Up Model'!J94 -> 15 | F24: ='Roll-Up Model'!M94 -> 15
A25: Leviathan ownership | B25: ='Roll-Up Model'!C101 -> 0.67695989 | C25: ='Roll-Up Model'!F101 -> 0.76775583 | D25: ='Roll-Up Model'!H101 -> 0.77300854 | E25: ='Roll-Up Model'!J101 -> 0.7744942 | F25: ='Roll-Up Model'!M101 -> 0.77232085
A27: RETURNS MATRIX (gross to Leviathan)
A28: Route | B28: MOIC Y5 | C28: MOIC Y7 | D28: MOIC Y10 | E28: IRR Y7 | F28: IRR Y10
A29: ='Exit & Returns'!A74 -> Route 1 — BX Infra sale | B29: ='Exit & Returns'!C74 -> 10.053404 | C29: ='Exit & Returns'!D74 -> 13.572234 | D29: ='Exit & Returns'!E74 -> 21.121384 | E29: ='Exit & Returns'!G74 -> 0.67672747 | F29: ='Exit & Returns'!H74 -> 0.50374645
A30: ='Exit & Returns'!A75 -> Route 2 — Spin/partial to BX | B30: ='Exit & Returns'!C75 -> 13.074358 | C30: ='Exit & Returns'!D75 -> 15.624069 | D30: ='Exit & Returns'!E75 -> 21.121384 | E30: ='Exit & Returns'!G75 -> 0.59966145 | F30: ='Exit & Returns'!H75 -> 0.50374645
A31: ='Exit & Returns'!A76 -> Route 3 — MarineMax | B31: ='Exit & Returns'!C76 -> 7.0394867 | C31: ='Exit & Returns'!D76 -> 9.6028716 | D31: ='Exit & Returns'!E76 -> 15.491814 | E31: ='Exit & Returns'!G76 -> 0.58226755 | F31: ='Exit & Returns'!H76 -> 0.4553353
A32: ='Exit & Returns'!A77 -> Route 4 — Sponsor | B32: ='Exit & Returns'!C77 -> 7.4061024 | C32: ='Exit & Returns'!D77 -> 10.135466 | D32: ='Exit & Returns'!E77 -> 16.424583 | E32: ='Exit & Returns'!G77 -> 0.5967823 | F32: ='Exit & Returns'!H77 -> 0.4643514
A34: INTEGRITY CHECKS (1 = OK)
A35: Sources = uses at close | B35: =IF(ABS('Sources & Uses'!C24)<0.001,1,0) -> 1
A36: Leviathan equity at close <= $15M | B36: =IF('Sources & Uses'!C22<=Assumptions!$B$23,1,0) -> 1
A37: Covenant, cap and min-cash checks (all years) | B37: ='Roll-Up Model'!C106 -> 1
A39: HOW TO USE
A40: • Edit blue cells only. Key levers are in yellow on Assumptions: scenario switch (B4), $15M cap, exit year, exit route.
A41: • Thesis Review: line-by-line critique of the CIM and the optimized assumptions used here. Synergies: platform operating synergies (feed EBITDA) and buyer synergies (feed exit premium).
A42: • Roll-Up Model: acquisitions -> revenue -> EBITDA -> FCF -> funding waterfall (cash, then Leviathan equity up to the cap, then revolver) -> debt -> units / ownership.
A43: • Exit & Returns: all four routes for every exit year, an IRR engine, and the net-to-LP waterfall for the selected case. Sensitivity: live grids. Scenario Summary: pasted snapshot of all four cases.
A44: • Sources: Safe Harbor / Blackstone Infrastructure ($5.65B, 138 marinas, closed Apr-2025); MarineMax FY26 filings (120+ locations, 65 marinas/storage, FY26 adj. EBITDA guide $110-125M). Marina-bay economics, MarineMax routable volume and infra multiples are estimates, flagged as such.

Sheet Thesis Review
A1: MARINE DIESEL ROLL-UP — THESIS REVIEW & OPTIMIZATION
A2: Source: 'Marine Diesel Engine & Service Center Roll-Up Platform' CIM, Aug-2026 (17 pp). Re-underwritten for Leviathan's 10-Year Infrastructure & Small Business Roll-Up vehicle.
A4: Area | B4: CIM position | C4: Issue / gap | D4: Optimized thesis (as modeled) | E4: Model lever
A5: Capital required | B5: ~$80M cumulative capital by Y5 (p.12); platform $7-22M EV. | C5: 5x+ the $15M mandate. CIM never shows a capital stack. | D5: Hard $15M Leviathan cap. Stack: 2.25x senior + DDTL (40% of add-on EV) + seller notes (10-15%) + rollover (5-15%) + earnouts (10%) + retained FCF. Revolver only after cap is exhausted. | E5: Assumptions B-col capital block; Sources & Uses
A6: Platform size | B6: $8-15M revenue, 18-25% margin, 5-6x. | C6: Top of range unaffordable under the cap. | D6: $10M revenue / 18% normalized margin (QoE haircut) / 5.25x. ~$2.4M Leviathan check at close leaves ~$12.6M for add-ons. | E6: plat_rev, plat_margin, plat_mult
A7: Margins | B7: Blended EBITDA 20% -> 25% by Y5; parts GM 40-60%. | C7: Owner-operated marine shops normalize to 12-18%. OEM parts GM is closer to 30-40%. | D7: Platform 18% / add-ons 14% standalone + bottom-up synergies (~5.5 pts) less a real HQ cost line ($1.0M growing 8%). | E7: Synergies tab part A; oh1
A8: Synergy math | B8: Overhead 25-30% -> 18-22%; utilization 65-75% -> 85-95%. | C8: Double-counts: overhead savings with no HQ cost; 85-95% utilization means technicians relocate seasonally. | D8: Back-office +3 pts net; utilization 70% -> 80% with 25% flow-through; procurement 10% on parts COGS. | E8: Synergies C5:D12
A9: Return math | B9: '$213M EV vs $80M capital = 2.7x' (p.12). | C9: Compares EV to capital and ignores debt, seller paper, earnouts, rollover dilution and MIP. | D9: Equity-level waterfall: EV - net debt - exit costs - MIP, times Leviathan's fully-diluted ownership (units priced at fair-value marks). | E9: Exit & Returns
A10: Exit multiple | B10: 9-12x generic 'platform exit'. | C10: No named buyer and no reason for a premium. | D10: Blended multiple: services (10x) on transactional cash flows, infra (15x) on contracted / marina-embedded cash flows. Contracted share goes from 15% to 35% by Y7 in Base. | E10: svc_mult, infra_mult, contract_tgt
A11: Exit path | B11: Not specified. | C11: Exit is the main value driver of a roll-up. | D11: Pre-wire Blackstone Infrastructure: a Safe Harbor preferred-provider agreement in Y2 and embedded service bays from Y3 (30 marinas by Y10). Four modeled routes: 100% BX sale; spin/partial with 40% retained inside Safe Harbor; MarineMax strategic; sponsor. | E11: sh_target, route, exit_yr
A12: Geography | B12: S. Florida -> Mid-Atlantic -> Northeast by phase. | C12: Sequenced by vessel counts, not by where the exit buyer operates. | D12: Same phases, with a new screening rule: favor targets within ~25 miles of a Safe Harbor or MarineMax location (FL, Chesapeake, LI Sound, New England). | E12: Time-series schedule
A13: Market sizing | B13: $5.1B global MRO; 12.7-yr merchant-fleet age. | C13: Global / merchant-fleet data says little about East Coast recreational and workboat diesel. | D13: Bottom-up East Coast TAM below: registered vessels x diesel share x annual spend, plus commercial and workboat. | E13: TAM block below
A14: Sponsor framing | B14: Branded Blackstone Tactical Opportunities as sponsor. | C14: Conflict: BX is the intended buyer. Sponsor-to-affiliate sales need an independent process and fairness opinion. | D14: Leviathan is the sponsor and BX Infra is the buyer. Run a real auction (BX vs MarineMax vs sponsors); that competition is where the seller's synergy share comes from. | E14: syn_share
A15: Key risks | B15: Technician retention rated Moderate-High. | C15: This is the binding constraint. OEM authorization transfer is a gating item. | D15: Rollover + MIP (10% of gains) for GMs and lead techs; OEM consent as a closing condition; earnouts tied to technician retention. | E15: mip, p_ro, eo_ach
A16: 10-yr vehicle fit | B16: 5-year hold. | C16: The vehicle has a 10-year life, so there is time for a two-step exit. | D16: Route 2: sell 60% to BX Infra at Y5-7 for DPI and keep 40% compounding inside Safe Harbor to Y10. | E16: ret_pct, post_g
A18: BOTTOM-UP EAST COAST TAM (replaces global MRO figure)
A19: Registered vessels — East Coast corridor (#) | B19: 1800000 | C19: CIM Appendix A: S.FL 300k + C/N FL 600k + Mid-Atl 500k + NE 400k.
A20: Diesel-powered share of recreational fleet | B20: 0.07 | C20: Estimate: inboard diesel skews to 30ft+ vessels. Verify against NMMA / USCG data.
A21: Annual diesel service + parts spend per vessel ($) | B21: 7000 | C21: Estimate: annual service, impellers, injectors, plus amortized overhaul.
A22: Recreational diesel TAM ($M) | B22: =B19*B20*B21/1000000 -> 882
A23: Commercial / workboat / fishing / government diesel TAM ($M) | B23: 600 | C23: Estimate: Hampton Roads, New Bedford, Gulf-of-Maine fleets, ferries, tugs.
A24: TOTAL East Coast addressable ($M) | B24: =B22+B23 -> 1482
A25: Platform Y10 revenue share of TAM | B25: ='Roll-Up Model'!M28/B24 -> 0.10247665

Sheet Assumptions
A1: ASSUMPTIONS & SCENARIO LEVERS
A2: Blue = hardcoded input. Black = formula. Yellow = key lever. $M unless noted. Column B is the LIVE value used by the model.
A4: Active scenario (1 = Base, 2 = Upside / Infra Re-Rate, 3 = Downside, 4 = Aggressive) | B4: 1 | C4: =INDEX(C7:F7,$B$4) -> Base | N4: Change this one cell to flip every scenario-driven input below.
A6: SCENARIO-DRIVEN INPUTS
A7: Lever | B7: LIVE | C7: Base | D7: Upside | E7: Downside | F7: Aggressive | N7: Rationale / source
A8: Organic revenue growth (same-store) | B8: =INDEX(C8:F8,$B$4) -> 0.05 | C8: 0.05 | D8: 0.07 | E8: 0.02 | F8: 0.08 | N8: CIM 5-8%. Base at low end; Downside = recession boating cycle.
A9: Platform entry multiple (x EBITDA) | B9: =INDEX(C9:F9,$B$4) -> 5.25 | C9: 5.25 | D9: 5 | E9: 6 | F9: 4.75 | N9: CIM 5-6x. $15M cap forces the smaller end of the platform range.
A10: Add-on entry multiple (x EBITDA) | B10: =INDEX(C10:F10,$B$4) -> 4.25 | C10: 4.25 | D10: 4 | E10: 5 | F10: 3.75 | N10: CIM 4-5x for $2-10M revenue shops.
A11: Add-on pace multiplier (x base schedule) | B11: =INDEX(C11:F11,$B$4) -> 1 | C11: 1 | D11: 1.25 | E11: 0.6 | F11: 1.5 | N11: Scales the year-by-year deal schedule at the bottom of this tab.
A12: Add-on standalone EBITDA margin | B12: =INDEX(C12:F12,$B$4) -> 0.14 | C12: 0.14 | D12: 0.15 | E12: 0.12 | F12: 0.15 | N12: CIM 12-22%. Small shops normalize to low-mid teens after owner add-backs.
A13: Operating-synergy realization (% of Synergies tab) | B13: =INDEX(C13:F13,$B$4) -> 1 | C13: 1 | D13: 1.2 | E13: 0.5 | F13: 1.4 | N13: Applied to bottom-up mature margin uplift on Synergies tab.
A14: Contracted / recurring share of core revenue by Y7 | B14: =INDEX(C14:F14,$B$4) -> 0.35 | C14: 0.35 | D14: 0.45 | E14: 0.2 | F14: 0.5 | N14: Fleet MSAs, extended service plans, IoT monitoring subs. Drives the infra-multiple blend.
A15: Safe Harbor marinas with embedded service bay by Y10 (#) | B15: =INDEX(C15:F15,$B$4) -> 30 | C15: 30 | D15: 45 | E15: 10 | F15: 60 | N15: Preferred-provider agreement with Safe Harbor (138 marinas). Pre-wires the BX Infra exit.
A16: Exit multiple — services cash flows (x EBITDA) | B16: =INDEX(C16:F16,$B$4) -> 10 | C16: 10 | D16: 11 | E16: 8 | F16: 12 | N16: CIM 9-12x. Scaled multi-site industrial services.
A17: Exit multiple — contracted / infra-like cash flows (x EBITDA) | B17: =INDEX(C17:F17,$B$4) -> 15 | C17: 15 | D17: 17 | E17: 12 | F17: 18 | N17: Infra buyers capitalize contracted, marina-embedded cash flows like Safe Harbor itself. Estimate.
A18: Share of buyer synergies paid to seller | B18: =INDEX(C18:F18,$B$4) -> 0.35 | C18: 0.35 | D18: 0.45 | E18: 0.2 | F18: 0.5 | N18: Competitive tension: BX Infra vs MarineMax vs sponsors.
A19: Base rate (SOFR) | B19: =INDEX(C19:F19,$B$4) -> 0.04 | C19: 0.04 | D19: 0.035 | E19: 0.05 | F19: 0.0325 | N19: Floating-rate reference for senior, DDTL and revolver.
A20: Earnout achievement (% of max paid) | B20: =INDEX(C20:F20,$B$4) -> 0.75 | C20: 0.75 | D20: 1 | E20: 0.4 | F20: 1 | N20: Higher achievement = more cash out, but only when EBITDA delivered.
A22: CAPITAL & DEAL STRUCTURE (all scenarios)
A23: Leviathan equity commitment — HARD CAP ($M) | B23: 15 | N23: User mandate: no more than $15M to start. Model never draws above this.
A24: Platform LTM revenue ($M) | B24: 10 | N24: CIM platform range $8-15M; sized to the $15M cap.
A25: Platform normalized EBITDA margin | B25: 0.18 | N25: CIM 18-25%. Haircut to low end after QoE normalization.
A26: Platform locations (#) | B26: 2 | N26: CIM Year 1: 1-2 locations.
A27: Platform transaction costs (% of EV) | B27: 0.04 | N27: Legal, QoE, OEM consent, financing fees.
A28: Add-on transaction costs (% of EV) | B28: 0.05 | N28: Smaller deals carry higher % costs.
A29: Minimum operating cash ($M) | B29: 0.5
A30: Senior term loan at close (x platform EBITDA) | B30: 2.25 | N30: Lower-middle-market unitranche / SBA-adjacent capacity.
A31: Platform seller note (% of EV) | B31: 0.1 | N31: CIM: earnout 15-25%, rollover 10-20%. Optimized toward seller paper.
A32: Platform seller rollover equity (% of EV) | B32: 0.15
A33: Platform earnout — max (% of EV) | B33: 0.1 | N33: Paid after lag x achievement.
A34: Add-on: delayed-draw term loan (% of EV) | B34: 0.35 | N34: Lender sizing ~3.5-4.0x pro forma EBITDA at platform level.
A35: Add-on: minimum sponsor equity (% of EV) while commitment remains | B35: 0.25 | N35: Lender equity-cushion requirement; this also forces the $15M to be put to work.
A36: Add-on: seller note (% of EV) | B36: 0.15
A37: Add-on: seller rollover (% of EV) | B37: 0.05 | N37: CIM 0-10%.
A38: Add-on: earnout — max (% of EV) | B38: 0.1 | N38: CIM 10-20%.
A39: Earnout payment lag (years) | B39: 2
A40: Avg add-on revenue in Y1 ($M) | B40: 3.5 | N40: CIM add-on range $2-10M.
A41: Avg add-on size growth / yr | B41: 0.04 | N41: Later Northeast targets larger / premium-priced.
A42: Mid-year convention (share of acquired revenue in deal year) | B42: 0.5
A44: OPERATIONS, CONTRACTED REVENUE & SAFE HARBOR PROGRAM
...

Sheet Sources & Uses
A1: PLATFORM SOURCES & USES (Y0) + 10-YEAR CAPITAL STACK
A2: $M. Leviathan equity is the plug at close and must stay inside the $15M commitment.
A4: PLATFORM CLOSE — USES
A5: Platform LTM revenue | C5: =Assumptions!$B$24 -> 10
A6: Normalized EBITDA margin | C6: =Assumptions!$B$25 -> 0.18
A7: Platform EBITDA | C7: =C5*C6 -> 1.8
A8: Entry multiple | C8: =Assumptions!$B$9 -> 5.25
A9: Purchase enterprise value | C9: =C7*C8 -> 9.45
A10: Transaction costs | C10: =C9*Assumptions!$B$27 -> 0.378
A11: Cash to balance sheet | C11: =Assumptions!$B$29 -> 0.5
A12: TOTAL USES | C12: =C9+C10+C11 -> 10.328
A13: Less: earnout (contingent, paid later) | C13: =-C21 -> -0.945
A14: Cash uses at close | C14: =C12+C13 -> 9.383
A16: PLATFORM CLOSE — SOURCES
A17: Source | C17: $M | D17: % of EV | E17: Note
A18: Senior term loan | C18: =Assumptions!$B$30*C7 -> 4.05 | D18: =C18/$C$9 -> 0.42857143 | E18: x platform EBITDA
A19: Seller note | C19: =Assumptions!$B$31*C9 -> 0.945 | D19: =C19/$C$9 -> 0.1 | E19: Subordinated, 7% fixed, 4-yr straight-line
A20: Seller rollover equity | C20: =Assumptions!$B$32*C9 -> 1.4175 | D20: =C20/$C$9 -> 0.15 | E20: Same unit price as Leviathan at close
A21: Earnout (deferred, max) | C21: =Assumptions!$B$33*C9 -> 0.945 | D21: =C21/$C$9 -> 0.1 | E21: Paid Y2 x achievement
A22: LEVIATHAN EQUITY (plug) | C22: =C12-C18-C19-C20-C21 -> 2.9705 | D22: =C22/$C$9 -> 0.31433862 | E22: Must be <= $15M cap
A23: TOTAL SOURCES | C23: =SUM(C18:C22) -> 10.328
A24: Check: sources = uses (0 = OK) | C24: =ROUND(C23-C12,6) -> 0
A25: Total debt at close / EBITDA | C25: =(C18+C19)/C7 -> 2.775
A26: Leviathan equity at close vs $15M cap | C26: =C22/Assumptions!$B$23 -> 0.19803333
A27: Reserved for add-ons (remaining commitment) | C27: =Assumptions!$B$23-C22 -> 12.0295
A29: 10-YEAR PROGRAM CAPITAL STACK — how $15M controls the platform
A30: Funding source (Y0-Y10 cumulative) | C30: $M | D30: % total | E30: Note
A31: Leviathan equity (capped) | C31: =SUM('Roll-Up Model'!C63:M63) -> 15 | D31: =IF($C$40=0,0,C31/$C$40) -> 0.23706606
A32: Seller rollover equity | C32: =SUM('Roll-Up Model'!C96:M96) -> 3.9387145 | D32: =IF($C$40=0,0,C32/$C$40) -> 0.062249034
A33: Senior term loan (at close) | C33: =C18 -> 4.05 | D33: =IF($C$40=0,0,C33/$C$40) -> 0.064007835
A34: DDTL draws | C34: =SUM('Roll-Up Model'!D76:M76) -> 17.648501 | D34: =IF($C$40=0,0,C34/$C$40) -> 0.27892404
A35: Seller notes issued | C35: =SUM('Roll-Up Model'!C80:M80) -> 8.5086434 | D35: =IF($C$40=0,0,C35/$C$40) -> 0.13447404
A36: Earnouts (max, contingent) | C36: =SUM('Roll-Up Model'!C88:M88) -> 5.9874289 | D36: =IF($C$40=0,0,C36/$C$40) -> 0.094627744
A37: Revolver draws | C37: =SUM('Roll-Up Model'!D64:M64) -> 0 | D37: =IF($C$40=0,0,C37/$C$40) -> 0
A38: Internally generated cash (plug) | C38: =C40-SUM(C31:C37) -> 8.1402157 | D38: =IF($C$40=0,0,C38/$C$40) -> 0.12865126 | E38: FCF retained and reinvested into add-ons (and cash on hand).
A40: TOTAL ACQUISITION SPEND (EV + costs + platform cash) | C40: =C12+SUM('Roll-Up Model'!D15:M15)+SUM('Roll-Up Model'!D16:M16) -> 63.273504
A41: Acquisition spend per $1 of Leviathan equity | C41: =IF(C31=0,0,C40/C31) -> 4.2182336

Sheet Roll-Up Model
A1: ROLL-UP OPERATING, FUNDING & DEBT MODEL
A2: Annual. Y0 = close (LTM). $M. Green = link to Assumptions. Interest on beginning balances (no circularity).
A5: $M | C5: Close | D5: 2027 | E5: 2028 | F5: 2029 | G5: 2030 | H5: 2031 | I5: 2032 | J5: 2033 | K5: 2034 | L5: 2035 | M5: 2036
A6: Year index | C6: 0 | D6: 1 | E6: 2 | F6: 3 | G6: 4 | H6: 5 | I6: 6 | J6: 7 | K6: 8 | L6: 9 | M6: 10
A7: Phase | C7: =Assumptions!C$96 -> Platform | D7: =Assumptions!D$96 -> I S.FL | E7: =Assumptions!E$96 -> I/II | F7: =Assumptions!F$96 -> II Mid-Atl | G7: =Assumptions!G$96 -> II/III | H7: =Assumptions!H$96 -> III NE | I7: =Assumptions!I$96 -> III NE | J7: =Assumptions!J$96 -> Fill-in | ... M7: =Assumptions!M$96 -> Exit prep
A8: 1. ACQUISITION PROGRAM
A9: Add-ons closed (#) | C9: 0 | D9: =ROUND(Assumptions!D$95*Assumptions!$B$11,0) -> 2 | E9: =ROUND(Assumptions!E$95*Assumptions!$B$11,0) -> 3 | F9: =ROUND(Assumptions!F$95*Assumptions!$B$11,0) -> 3 | G9: =ROUND(Assumptions!G$95*Assumptions!$B$11,0) -> 3 | H9: =ROUND(Assumptions!H$95*Assumptions!$B$11,0) -> 3 | I9: =ROUND(Assumptions!I$95*Assumptions!$B$11,0) -> 2 | J9: =ROUND(Assumptions!J$95*Assumptions!$B$11,0) -> 2 | K9: =ROUND(Assumptions!K$95*Assumptions!$B$11,0) -> 2 | ... M9: =ROUND(Assumptions!M$95*Assumptions!$B$11,0) -> 0
A10: Cumulative add-ons (#) | C10: 0 | D10: =C10+D9 -> 2 | E10: =D10+E9 -> 5 | F10: =E10+F9 -> 8 | G10: =F10+G9 -> 11 | H10: =G10+H9 -> 14 | I10: =H10+I9 -> 16 | J10: =I10+J9 -> 18 | K10: =J10+K9 -> 20 | ... M10: =L10+M9 -> 21
A11: Locations (#) | C11: =Assumptions!$B$26 -> 2 | D11: =Assumptions!$B$26+D10 -> 4 | E11: =Assumptions!$B$26+E10 -> 7 | F11: =Assumptions!$B$26+F10 -> 10 | G11: =Assumptions!$B$26+G10 -> 13 | H11: =Assumptions!$B$26+H10 -> 16 | I11: =Assumptions!$B$26+I10 -> 18 | J11: =Assumptions!$B$26+J10 -> 20 | K11: =Assumptions!$B$26+K10 -> 22 | ... M11: =Assumptions!$B$26+M10 -> 23
A12: Avg add-on revenue ($M) | D12: =Assumptions!$B$40*(1+Assumptions!$B$41)^(D6-1) -> 3.5 | E12: =Assumptions!$B$40*(1+Assumptions!$B$41)^(E6-1) -> 3.64 | F12: =Assumptions!$B$40*(1+Assumptions!$B$41)^(F6-1) -> 3.7856 | G12: =Assumptions!$B$40*(1+Assumptions!$B$41)^(G6-1) -> 3.937024 | H12: =Assumptions!$B$40*(1+Assumptions!$B$41)^(H6-1) -> 4.094505 | I12: =Assumptions!$B$40*(1+Assumptions!$B$41)^(I6-1) -> 4.2582852 | J12: =Assumptions!$B$40*(1+Assumptions!$B$41)^(J6-1) -> 4.4286166 | K12: =Assumptions!$B$40*(1+Assumptions!$B$41)^(K6-1) -> 4.6057612 | ... M12: =Assumptions!$B$40*(1+Assumptions!$B$41)^(M6-1) -> 4.9815913
A13: New acquired revenue — run-rate | D13: =D9*D12 -> 7 | E13: =E9*E12 -> 10.92 | F13: =F9*F12 -> 11.3568 | G13: =G9*G12 -> 11.811072 | H13: =H9*H12 -> 12.283515 | I13: =I9*I12 -> 8.5165703 | J13: =J9*J12 -> 8.8572331 | K13: =K9*K12 -> 9.2115225 | ... M13: =M9*M12 -> 0
A14: New acquired EBITDA — run-rate | D14: =D13*Assumptions!$B$12 -> 0.98 | E14: =E13*Assumptions!$B$12 -> 1.5288 | F14: =F13*Assumptions!$B$12 -> 1.589952 | G14: =G13*Assumptions!$B$12 -> 1.6535501 | H14: =H13*Assumptions!$B$12 -> 1.7196921 | I14: =I13*Assumptions!$B$12 -> 1.1923198 | J14: =J13*Assumptions!$B$12 -> 1.2400126 | K14: =K13*Assumptions!$B$12 -> 1.2896131 | ... M14: =M13*Assumptions!$B$12 -> 0
A15: Add-on purchase EV | D15: =D14*Assumptions!$B$10 -> 4.165 | E15: =E14*Assumptions!$B$10 -> 6.4974 | F15: =F14*Assumptions!$B$10 -> 6.757296 | G15: =G14*Assumptions!$B$10 -> 7.0275878 | H15: =H14*Assumptions!$B$10 -> 7.3086914 | I15: =I14*Assumptions!$B$10 -> 5.0673593 | J15: =J14*Assumptions!$B$10 -> 5.2700537 | K15: =K14*Assumptions!$B$10 -> 5.4808559 | ... M15: =M14*Assumptions!$B$10 -> 0
A16: Add-on transaction costs | D16: =D15*Assumptions!$B$28 -> 0.20825 | E16: =E15*Assumptions!$B$28 -> 0.32487 | F16: =F15*Assumptions!$B$28 -> 0.3378648 | G16: =G15*Assumptions!$B$28 -> 0.35137939 | H16: =H15*Assumptions!$B$28 -> 0.36543457 | I16: =I15*Assumptions!$B$28 -> 0.25336797 | J16: =J15*Assumptions!$B$28 -> 0.26350269 | K16: =K15*Assumptions!$B$28 -> 0.27404279 | ... M16: =M15*Assumptions!$B$28 -> 0
A17: Funded by DDTL | D17: =D15*Assumptions!$B$34 -> 1.45775 | E17: =E15*Assumptions!$B$34 -> 2.27409 | F17: =F15*Assumptions!$B$34 -> 2.3650536 | G17: =G15*Assumptions!$B$34 -> 2.4596557 | H17: =H15*Assumptions!$B$34 -> 2.558042 | I17: =I15*Assumptions!$B$34 -> 1.7735758 | J17: =J15*Assumptions!$B$34 -> 1.8445188 | K17: =K15*Assumptions!$B$34 -> 1.9182996 | ... M17: =M15*Assumptions!$B$34 -> 0
A18: Funded by seller notes | D18: =D15*Assumptions!$B$36 -> 0.62475 | E18: =E15*Assumptions!$B$36 -> 0.97461 | F18: =F15*Assumptions!$B$36 -> 1.0135944 | G18: =G15*Assumptions!$B$36 -> 1.0541382 | H18: =H15*Assumptions!$B$36 -> 1.0963037 | I18: =I15*Assumptions!$B$36 -> 0.7601039 | J18: =J15*Assumptions!$B$36 -> 0.79050806 | K18: =K15*Assumptions!$B$36 -> 0.82212838 | ... M18: =M15*Assumptions!$B$36 -> 0
A19: Funded by seller rollover equity | D19: =D15*Assumptions!$B$37 -> 0.20825 | E19: =E15*Assumptions!$B$37 -> 0.32487 | F19: =F15*Assumptions!$B$37 -> 0.3378648 | G19: =G15*Assumptions!$B$37 -> 0.35137939 | H19: =H15*Assumptions!$B$37 -> 0.36543457 | I19: =I15*Assumptions!$B$37 -> 0.25336797 | J19: =J15*Assumptions!$B$37 -> 0.26350269 | K19: =K15*Assumptions!$B$37 -> 0.27404279 | ... M19: =M15*Assumptions!$B$37 -> 0
A20: Deferred via earnout (max) | D20: =D15*Assumptions!$B$38 -> 0.4165 | E20: =E15*Assumptions!$B$38 -> 0.64974 | F20: =F15*Assumptions!$B$38 -> 0.6757296 | G20: =G15*Assumptions!$B$38 -> 0.70275878 | H20: =H15*Assumptions!$B$38 -> 0.73086914 | I20: =I15*Assumptions!$B$38 -> 0.50673593 | J20: =J15*Assumptions!$B$38 -> 0.52700537 | K20: =K15*Assumptions!$B$38 -> 0.54808559 | ... M20: =M15*Assumptions!$B$38 -> 0
A21: Cash required at close (cash / equity / revolver) | D21: =D15+D16-D17-D18-D19-D20 -> 1.666 | E21: =E15+E16-E17-E18-E19-E20 -> 2.59896 | F21: =F15+F16-F17-F18-F19-F20 -> 2.7029184 | G21: =G15+G16-G17-G18-G19-G20 -> 2.8110351 | H21: =H15+H16-H17-H18-H19-H20 -> 2.9234765 | I21: =I15+I16-I17-I18-I19-I20 -> 2.0269437 | J21: =J15+J16-J17-J18-J19-J20 -> 2.1080215 | K21: =K15+K16-K17-K18-K19-K20 -> 2.1923423 | ... M21: =M15+M16-M17-M18-M19-M20 -> 0
A22: 2. REVENUE BUILD
A23: Platform run-rate revenue | C23: =Assumptions!$B$24 -> 10 | D23: =C23*(1+Assumptions!$B$8) -> 10.5 | E23: =D23*(1+Assumptions!$B$8) -> 11.025 | F23: =E23*(1+Assumptions!$B$8) -> 11.57625 | G23: =F23*(1+Assumptions!$B$8) -> 12.155062 | H23: =G23*(1+Assumptions!$B$8) -> 12.762816 | I23: =H23*(1+Assumptions!$B$8) -> 13.400956 | J23: =I23*(1+Assumptions!$B$8) -> 14.071004 | K23: =J23*(1+Assumptions!$B$8) -> 14.774554 | ... M23: =L23*(1+Assumptions!$B$8) -> 16.288946
A24: Acquired run-rate revenue (cumulative) | C24: 0 | D24: =C24*(1+Assumptions!$B$8)+D13 -> 7 | E24: =D24*(1+Assumptions!$B$8)+E13 -> 18.27 | F24: =E24*(1+Assumptions!$B$8)+F13 -> 30.5403 | G24: =F24*(1+Assumptions!$B$8)+G13 -> 43.878387 | H24: =G24*(1+Assumptions!$B$8)+H13 -> 58.355821 | I24: =H24*(1+Assumptions!$B$8)+I13 -> 69.790183 | J24: =I24*(1+Assumptions!$B$8)+J13 -> 82.136925 | K24: =J24*(1+Assumptions!$B$8)+K13 -> 95.455294 | ... M24: =L24*(1+Assumptions!$B$8)+M13 -> 110.26895
A25: Core revenue — reported (mid-year convention) | C25: =Assumptions!$B$24 -> 10 | D25: =D23+C24*(1+Assumptions!$B$8)+D13*Assumptions!$B$42 -> 14 | E25: =E23+D24*(1+Assumptions!$B$8)+E13*Assumptions!$B$42 -> 23.835 | F25: =F23+E24*(1+Assumptions!$B$8)+F13*Assumptions!$B$42 -> 36.43815 | G25: =G23+F24*(1+Assumptions!$B$8)+G13*Assumptions!$B$42 -> 50.127913 | H25: =H23+G24*(1+Assumptions!$B$8)+H13*Assumptions!$B$42 -> 64.976879 | I25: =I23+H24*(1+Assumptions!$B$8)+I13*Assumptions!$B$42 -> 78.932854 | J25: =J23+I24*(1+Assumptions!$B$8)+J13*Assumptions!$B$42 -> 91.779313 | K25: =K23+J24*(1+Assumptions!$B$8)+K13*Assumptions!$B$42 -> 105.62409 | ... M25: =M23+L24*(1+Assumptions!$B$8)+M13*Assumptions!$B$42 -> 126.5579
A26: Safe Harbor marinas with embedded bay (#, end of yr) | C26: 0 | D26: =IF(D6<Assumptions!$B$49,0,MIN(Assumptions!$B$15,Assumptions!$B$15*(D6-Assumptions!$B$49+1)/(10-Assumptions!$B$49+1))) -> 0 | E26: =IF(E6<Assumptions!$B$49,0,MIN(Assumptions!$B$15,Assumptions!$B$15*(E6-Assumptions!$B$49+1)/(10-Assumptions!$B$49+1))) -> 0 | F26: =IF(F6<Assumptions!$B$49,0,MIN(Assumptions!$B$15,Assumptions!$B$15*(F6-Assumptions!$B$49+1)/(10-Assumptions!$B$49+1))) -> 3.75 | G26: =IF(G6<Assumptions!$B$49,0,MIN(Assumptions!$B$15,Assumptions!$B$15*(G6-Assumptions!$B$49+1)/(10-Assumptions!$B$49+1))) -> 7.5 | H26: =IF(H6<Assumptions!$B$49,0,MIN(Assumptions!$B$15,Assumptions!$B$15*(H6-Assumptions!$B$49+1)/(10-Assumptions!$B$49+1))) -> 11.25 | I26: =IF(I6<Assumptions!$B$49,0,MIN(Assumptions!$B$15,Assumptions!$B$15*(I6-Assumptions!$B$49+1)/(10-Assumptions!$B$49+1))) -> 15 | J26: =IF(J6<Assumptions!$B$49,0,MIN(Assumptions!$B$15,Assumptions!$B$15*(J6-Assumptions!$B$49+1)/(10-Assumptions!$B$49+1))) -> 18.75 | K26: =IF(K6<Assumptions!$B$49,0,MIN(Assumptions!$B$15,Assumptions!$B$15*(K6-Assumptions!$B$49+1)/(10-Assumptions!$B$49+1))) -> 22.5 | ... M26: =IF(M6<Assumptions!$B$49,0,MIN(Assumptions!$B$15,Assumptions!$B$15*(M6-Assumptions!$B$49+1)/(10-Assumptions!$B$49+1))) -> 30
A27: Safe Harbor embedded-service revenue | C27: 0 | D27: =AVERAGE(C26,D26)*Assumptions!$B$50 -> 0 | E27: =AVERAGE(D26,E26)*Assumptions!$B$50 -> 0 | F27: =AVERAGE(E26,F26)*Assumptions!$B$50 -> 1.6875 | G27: =AVERAGE(F26,G26)*Assumptions!$B$50 -> 5.0625 | H27: =AVERAGE(G26,H26)*Assumptions!$B$50 -> 8.4375 | I27: =AVERAGE(H26,I26)*Assumptions!$B$50 -> 11.8125 | J27: =AVERAGE(I26,J26)*Assumptions!$B$50 -> 15.1875 | K27: =AVERAGE(J26,K26)*Assumptions!$B$50 -> 18.5625 | ... M27: =AVERAGE(L26,M26)*Assumptions!$B$50 -> 25.3125
A28: TOTAL REVENUE | C28: =C25+C27 -> 10 | D28: =D25+D27 -> 14 | E28: =E25+E27 -> 23.835 | F28: =F25+F27 -> 38.12565 | G28: =G25+G27 -> 55.190413 | H28: =H25+H27 -> 73.414379 | I28: =I25+I27 -> 90.745354 | J28: =J25+J27 -> 106.96681 | ... M28: =M25+M27 -> 151.8704
A29: Growth % | D29: =IF(C28=0,0,D28/C28-1) -> 0.4 | E29: =IF(D28=0,0,E28/D28-1) -> 0.7025 | F29: =IF(E28=0,0,F28/E28-1) -> 0.59956576 | G29: =IF(F28=0,0,G28/F28-1) -> 0.44759272 | H29: =IF(G28=0,0,H28/G28-1) -> 0.33020166 | I29: =IF(H28=0,0,I28/H28-1) -> 0.23607057 | J29: =IF(I28=0,0,J28/I28-1) -> 0.17875801 | K29: =IF(J28=0,0,K28/J28-1) -> 0.1609824 | ... M29: =IF(L28=0,0,M28/L28-1) -> 0.084216744
A30: Contracted share of core revenue | C30: =Assumptions!$B$45 -> 0.15 | D30: =Assumptions!$B$45+(Assumptions!$B$14-Assumptions!$B$45)*MIN(1,D6/Assumptions!$B$46) -> 0.17857143 | E30: =Assumptions!$B$45+(Assumptions!$B$14-Assumptions!$B$45)*MIN(1,E6/Assumptions!$B$46) -> 0.20714286 | F30: =Assumptions!$B$45+(Assumptions!$B$14-Assumptions!$B$45)*MIN(1,F6/Assumptions!$B$46) -> 0.23571429 | G30: =Assumptions!$B$45+(Assumptions!$B$14-Assumptions!$B$45)*MIN(1,G6/Assumptions!$B$46) -> 0.26428571 | H30: =Assumptions!$B$45+(Assumptions!$B$14-Assumptions!$B$45)*MIN(1,H6/Assumptions!$B$46) -> 0.29285714 | I30: =Assumptions!$B$45+(Assumptions!$B$14-Assumptions!$B$45)*MIN(1,I6/Assumptions!$B$46) -> 0.32142857 | J30: =Assumptions!$B$45+(Assumptions!$B$14-Assumptions!$B$45)*MIN(1,J6/Assumptions!$B$46) -> 0.35 | K30: =Assumptions!$B$45+(Assumptions!$B$14-Assumptions!$B$45)*MIN(1,K6/Assumptions!$B$46) -> 0.35 | ... M30: =Assumptions!$B$45+(Assumptions!$B$14-Assumptions!$B$45)*MIN(1,M6/Assumptions!$B$46) -> 0.35
A31: Contracted / infra-like revenue | C31: =C25*C30+C27 -> 1.5 | D31: =D25*D30+D27 -> 2.5 | E31: =E25*E30+E27 -> 4.93725 | F31: =F25*F30+F27 -> 10.276492 | G31: =G25*G30+G27 -> 18.310591 | H31: =H25*H30+H27 -> 27.466443 | I31: =I25*I30+I27 -> 37.183774 | J31: =J25*J30+J27 -> 47.310259 | ... M31: =M25*M30+M27 -> 69.607765
A32: Contracted % of total revenue (drives exit multiple) | C32: =IF(C28=0,0,C31/C28) -> 0.15 | D32: =IF(D28=0,0,D31/D28) -> 0.17857143 | E32: =IF(E28=0,0,E31/E28) -> 0.20714286 | F32: =IF(F28=0,0,F31/F28) -> 0.26954275 | G32: =IF(G28=0,0,G31/G28) -> 0.33177123 | H32: =IF(H28=0,0,H31/H28) -> 0.37412893 | I32: =IF(I28=0,0,I31/I28) -> 0.40975954 | J32: =IF(J28=0,0,J31/J28) -> 0.44228914 | ... M32: =IF(M28=0,0,M31/M28) -> 0.45833662
A33: 3. EBITDA BUILD
A34: Standalone margin (run-rate weighted platform / add-ons) | C34: =(C23*Assumptions!$B$25+C24*Assumptions!$B$12)/(C23+C24) -> 0.18 | D34: =(D23*Assumptions!$B$25+D24*Assumptions!$B$12)/(D23+D24) -> 0.164 | E34: =(E23*Assumptions!$B$25+E24*Assumptions!$B$12)/(E23+E24) -> 0.15505376 | F34: =(F23*Assumptions!$B$25+F24*Assumptions!$B$12)/(F23+F24) -> 0.15099449 | G34: =(G23*Assumptions!$B$25+G24*Assumptions!$B$12)/(G23+G24) -> 0.148677 | H34: =(H23*Assumptions!$B$25+H24*Assumptions!$B$12)/(H23+H24) -> 0.14717832 | I34: =(I23*Assumptions!$B$25+I24*Assumptions!$B$12)/(I23+I24) -> 0.14644345 | J34: =(J23*Assumptions!$B$25+J24*Assumptions!$B$12)/(J23+J24) -> 0.14585025 | ... M34: =(M23*Assumptions!$B$25+M24*Assumptions!$B$12)/(M23+M24) -> 0.1451483
A35: Core EBITDA — standalone | C35: =C25*C34 -> 1.8 | D35: =D25*D34 -> 2.296 | E35: =E25*E34 -> 3.6957065 | F35: =F25*F34 -> 5.5019599 | G35: =G25*G34 -> 7.452868 | H35: =H25*H34 -> 9.5631882 | I35: =I25*I34 -> 11.5592 | J35: =J25*J34 -> 13.386035 | ... M35: =M25*M34 -> 18.369664
A36: Operating-synergy margin uplift | C36: 0 | D36: =Synergies!$C$13*Assumptions!$B$13*MIN(1,D6/Synergies!$C$14) -> 0.014915179 | E36: =Synergies!$C$13*Assumptions!$B$13*MIN(1,E6/Synergies!$C$14) -> 0.029830357 | F36: =Synergies!$C$13*Assumptions!$B$13*MIN(1,F6/Synergies!$C$14) -> 0.044745536 | G36: =Synergies!$C$13*Assumptions!$B$13*MIN(1,G6/Synergies!$C$14) -> 0.059660714 | H36: =Synergies!$C$13*Assumptions!$B$13*MIN(1,H6/Synergies!$C$14) -> 0.059660714 | I36: =Synergies!$C$13*Assumptions!$B$13*MIN(1,I6/Synergies!$C$14) -> 0.059660714 | J36: =Synergies!$C$13*Assumptions!$B$13*MIN(1,J6/Synergies!$C$14) -> 0.059660714 | K36: =Synergies!$C$13*Assumptions!$B$13*MIN(1,K6/Synergies!$C$14) -> 0.059660714 | ... M36: =Synergies!$C$13*Assumptions!$B$13*MIN(1,M6/Synergies!$C$14) -> 0.059660714
A37: Operating-synergy EBITDA | C37: 0 | D37: =D25*D36 -> 0.2088125 | E37: =E25*E36 -> 0.71100656 | F37: =F25*F36 -> 1.6304445 | G37: =G25*G36 -> 2.9906671 | H37: =H25*H36 -> 3.876567 | I37: =I25*I36 -> 4.7091904 | J37: =J25*J36 -> 5.4756193 | K37: =K25*K36 -> 6.3016085 | ... M37: =M25*M36 -> 7.5505346
A38: Safe Harbor embedded-service EBITDA | C38: 0 | D38: =D27*Assumptions!$B$51 -> 0 | E38: =E27*Assumptions!$B$51 -> 0 | F38: =F27*Assumptions!$B$51 -> 0.4725 | G38: =G27*Assumptions!$B$51 -> 1.4175 | H38: =H27*Assumptions!$B$51 -> 2.3625 | I38: =I27*Assumptions!$B$51 -> 3.3075 | J38: =J27*Assumptions!$B$51 -> 4.2525 | K38: =K27*Assumptions!$B$51 -> 5.1975 | ... M38: =M27*Assumptions!$B$51 -> 7.0875
A39: Platform corporate overhead | C39: 0 | D39: =-Assumptions!$B$47*(1+Assumptions!$B$48)^(D6-1) -> -1 | E39: =-Assumptions!$B$47*(1+Assumptions!$B$48)^(E6-1) -> -1.08 | F39: =-Assumptions!$B$47*(1+Assumptions!$B$48)^(F6-1) -> -1.1664 | G39: =-Assumptions!$B$47*(1+Assumptions!$B$48)^(G6-1) -> -1.259712 | H39: =-Assumptions!$B$47*(1+Assumptions!$B$48)^(H6-1) -> -1.360489 | I39: =-Assumptions!$B$47*(1+Assumptions!$B$48)^(I6-1) -> -1.4693281 | J39: =-Assumptions!$B$47*(1+Assumptions!$B$48)^(J6-1) -> -1.5868743 | K39: =-Assumptions!$B$47*(1+Assumptions!$B$48)^(K6-1) -> -1.7138243 | ... M39: =-Assumptions!$B$47*(1+Assumptions!$B$48)^(M6-1) -> -1.9990046
A40: ADJUSTED EBITDA | C40: =C35+C37+C38+C39 -> 1.8 | D40: =D35+D37+D38+D39 -> 1.5048125 | E40: =E35+E37+E38+E39 -> 3.326713 | F40: =F35+F37+F38+F39 -> 6.4385044 | G40: =G35+G37+G38+G39 -> 10.601323 | H40: =H35+H37+H38+H39 -> 14.441766 | I40: =I35+I37+I38+I39 -> 18.106562 | J40: =J35+J37+J38+J39 -> 21.52728 | ... M40: =M35+M37+M38+M39 -> 31.008694
A41: Pro forma run-rate EBITDA (full-year add-ons) | C41: =C40 -> 1.8 | D41: =D40+D14*(1-Assumptions!$B$42) -> 1.9948125 | E41: =E40+E14*(1-Assumptions!$B$42) -> 4.091113 | F41: =F40+F14*(1-Assumptions!$B$42) -> 7.2334804 | G41: =G40+G14*(1-Assumptions!$B$42) -> 11.428098 | H41: =H40+H14*(1-Assumptions!$B$42) -> 15.301612 | I41: =I40+I14*(1-Assumptions!$B$42) -> 18.702722 | J41: =J40+J14*(1-Assumptions!$B$42) -> 22.147287 | K41: =K40+K14*(1-Assumptions!$B$42) -> 25.783752 | ... M41: =M40+M14*(1-Assumptions!$B$42) -> 31.008694
A42: EBITDA margin | C42: =IF(C28=0,0,C40/C28) -> 0.18 | D42: =IF(D28=0,0,D40/D28) -> 0.10748661 | E42: =IF(E28=0,0,E40/E28) -> 0.1395726 | F42: =IF(F28=0,0,F40/F28) -> 0.16887593 | G42: =IF(G28=0,0,G40/G28) -> 0.19208631 | H42: =IF(H28=0,0,H40/H28) -> 0.19671577 | I42: =IF(I28=0,0,I40/I28) -> 0.19953156 | J42: =IF(J28=0,0,J40/J28) -> 0.20125196 | ... M42: =IF(M28=0,0,M40/M28) -> 0.20417865
...

Sheet Synergies
A1: SYNERGIES — PLATFORM OPERATING + BUYER (BX INFRA / SAFE HARBOR, MARINEMAX)
A2: Part A feeds platform EBITDA. Part B is buyer-side value that a strategic shares with the seller at exit.
A4: A. PLATFORM OPERATING SYNERGIES — mature margin uplift (% of core revenue)
A5: OEM parts share of revenue | C5: 0.275 | N5: CIM: 25-30%.
A6: Parts COGS as % of parts revenue | C6: 0.65 | N6: Optimized: OEM parts gross margin ~35%, not CIM's 40-60%.
A7: Procurement savings on parts COGS | C7: 0.1 | N7: CIM 8-15%.
A8: Back-office consolidation (pts of revenue) | C8: 0.02 | N8: CIM implies 6-8 pts (25-30% -> 18-22%); haircut to 2 pts. HQ cost is modeled separately.
A9: Labor share of revenue | C9: 0.5 | N9: Maintenance/repair + repower + mobile.
A10: Technician utilization: standalone -> platform | C10: 0.7 | D10: 0.8 | N10: CIM 65-75% -> 85-95%. Optimized target 80% (cell D10).
A11: Flow-through of incremental billable hours | C11: 0.2 | N11: Techs are paid more under platform comp plans.
A12: Pricing / mix (ESPs, e-commerce parts, IoT subs) (pts) | C12: 0.0075
A13: TOTAL mature margin uplift (pre-scenario scaling) | C13: =C5*C6*C7+C8+C9*(D10/C10-1)*C11+C12 -> 0.059660714
A14: Years to full run-rate (integration ramp) | C14: 4
A15: Procurement component | C15: =C5*C6*C7 -> 0.017875
A16: Back-office component | C16: =C8 -> 0.02
A17: Utilization component | C17: =C9*(D10/C10-1)*C11 -> 0.014285714
A18: Pricing / mix component | C18: =C12 -> 0.0075
A20: B. BUYER SYNERGIES BY EXIT YEAR ($M EBITDA, run-rate at exit)
A21: Blackstone Infrastructure (Safe Harbor integration) | C21: Close | D21: 2027 | E21: 2028 | F21: 2029 | G21: 2030 | H21: 2031 | I21: 2032 | J21: 2033 | K21: 2034 | L21: 2035 | M21: 2036
A22: Safe Harbor marinas a buyer could equip (#) | D22: =Assumptions!$B$76*Assumptions!$B$77 -> 55.2 | E22: =Assumptions!$B$76*Assumptions!$B$77 -> 55.2 | F22: =Assumptions!$B$76*Assumptions!$B$77 -> 55.2 | G22: =Assumptions!$B$76*Assumptions!$B$77 -> 55.2 | H22: =Assumptions!$B$76*Assumptions!$B$77 -> 55.2 | I22: =Assumptions!$B$76*Assumptions!$B$77 -> 55.2 | J22: =Assumptions!$B$76*Assumptions!$B$77 -> 55.2 | K22: =Assumptions!$B$76*Assumptions!$B$77 -> 55.2 | ... M22: =Assumptions!$B$76*Assumptions!$B$77 -> 55.2
A23: Incremental marinas = MIN(open network, 1 per platform location) | D23: =MIN(MAX(0,D22-'Roll-Up Model'!D26),'Roll-Up Model'!D11) -> 4 | E23: =MIN(MAX(0,E22-'Roll-Up Model'!E26),'Roll-Up Model'!E11) -> 7 | F23: =MIN(MAX(0,F22-'Roll-Up Model'!F26),'Roll-Up Model'!F11) -> 10 | G23: =MIN(MAX(0,G22-'Roll-Up Model'!G26),'Roll-Up Model'!G11) -> 13 | H23: =MIN(MAX(0,H22-'Roll-Up Model'!H26),'Roll-Up Model'!H11) -> 16 | I23: =MIN(MAX(0,I22-'Roll-Up Model'!I26),'Roll-Up Model'!I11) -> 18 | J23: =MIN(MAX(0,J22-'Roll-Up Model'!J26),'Roll-Up Model'!J11) -> 20 | K23: =MIN(MAX(0,K22-'Roll-Up Model'!K26),'Roll-Up Model'!K11) -> 22 | ... M23: =MIN(MAX(0,M22-'Roll-Up Model'!M26),'Roll-Up Model'!M11) -> 23
A24: Marina-network revenue synergy EBITDA | D24: =D23*Assumptions!$B$50*Assumptions!$B$51 -> 1.008 | E24: =E23*Assumptions!$B$50*Assumptions!$B$51 -> 1.764 | F24: =F23*Assumptions!$B$50*Assumptions!$B$51 -> 2.52 | G24: =G23*Assumptions!$B$50*Assumptions!$B$51 -> 3.276 | H24: =H23*Assumptions!$B$50*Assumptions!$B$51 -> 4.032 | I24: =I23*Assumptions!$B$50*Assumptions!$B$51 -> 4.536 | J24: =J23*Assumptions!$B$50*Assumptions!$B$51 -> 5.04 | K24: =K23*Assumptions!$B$50*Assumptions!$B$51 -> 5.544 | ... M24: =M23*Assumptions!$B$50*Assumptions!$B$51 -> 5.796
A25: BX scale cost synergies (insurance, GPO, fleet) | D25: ='Roll-Up Model'!D28*Assumptions!$B$78 -> 0.21 | E25: ='Roll-Up Model'!E28*Assumptions!$B$78 -> 0.357525 | F25: ='Roll-Up Model'!F28*Assumptions!$B$78 -> 0.57188475 | G25: ='Roll-Up Model'!G28*Assumptions!$B$78 -> 0.8278562 | H25: ='Roll-Up Model'!H28*Assumptions!$B$78 -> 1.1012157 | I25: ='Roll-Up Model'!I28*Assumptions!$B$78 -> 1.3611803 | J25: ='Roll-Up Model'!J28*Assumptions!$B$78 -> 1.6045022 | K25: ='Roll-Up Model'!K28*Assumptions!$B$78 -> 1.8627988 | ... M25: ='Roll-Up Model'!M28*Assumptions!$B$78 -> 2.278056
A26: MarineMax channel agreement (prob-weighted, scaled to footprint) | D26: =Assumptions!$B$79*Assumptions!$B$80*Assumptions!$B$82*MIN(1,'Roll-Up Model'!D11/Assumptions!$B$81) -> 0.44 | E26: =Assumptions!$B$79*Assumptions!$B$80*Assumptions!$B$82*MIN(1,'Roll-Up Model'!E11/Assumptions!$B$81) -> 0.77 | F26: =Assumptions!$B$79*Assumptions!$B$80*Assumptions!$B$82*MIN(1,'Roll-Up Model'!F11/Assumptions!$B$81) -> 1.1 | G26: =Assumptions!$B$79*Assumptions!$B$80*Assumptions!$B$82*MIN(1,'Roll-Up Model'!G11/Assumptions!$B$81) -> 1.43 | H26: =Assumptions!$B$79*Assumptions!$B$80*Assumptions!$B$82*MIN(1,'Roll-Up Model'!H11/Assumptions!$B$81) -> 1.76 | I26: =Assumptions!$B$79*Assumptions!$B$80*Assumptions!$B$82*MIN(1,'Roll-Up Model'!I11/Assumptions!$B$81) -> 1.98 | J26: =Assumptions!$B$79*Assumptions!$B$80*Assumptions!$B$82*MIN(1,'Roll-Up Model'!J11/Assumptions!$B$81) -> 2.2 | K26: =Assumptions!$B$79*Assumptions!$B$80*Assumptions!$B$82*MIN(1,'Roll-Up Model'!K11/Assumptions!$B$81) -> 2.2 | ... M26: =Assumptions!$B$79*Assumptions!$B$80*Assumptions!$B$82*MIN(1,'Roll-Up Model'!M11/Assumptions!$B$81) -> 2.2
A27: TOTAL BX Infra buyer synergy EBITDA | D27: =SUM(D24:D26) -> 1.658 | E27: =SUM(E24:E26) -> 2.891525 | F27: =SUM(F24:F26) -> 4.1918847 | G27: =SUM(G24:G26) -> 5.5338562 | H27: =SUM(H24:H26) -> 6.8932157 | I27: =SUM(I24:I26) -> 7.8771803 | J27: =SUM(J24:J26) -> 8.8445022 | K27: =SUM(K24:K26) -> 9.6067988 | ... M27: =SUM(M24:M26) -> 10.274056
A28: Synergy value paid to seller (x infra mult x haircut x share) | D28: =D27*Assumptions!$B$17*Assumptions!$B$75*Assumptions!$B$18 -> 5.2227 | E28: =E27*Assumptions!$B$17*Assumptions!$B$75*Assumptions!$B$18 -> 9.1083037 | F28: =F27*Assumptions!$B$17*Assumptions!$B$75*Assumptions!$B$18 -> 13.204437 | G28: =G27*Assumptions!$B$17*Assumptions!$B$75*Assumptions!$B$18 -> 17.431647 | H28: =H27*Assumptions!$B$17*Assumptions!$B$75*Assumptions!$B$18 -> 21.713629 | I28: =I27*Assumptions!$B$17*Assumptions!$B$75*Assumptions!$B$18 -> 24.813118 | J28: =J27*Assumptions!$B$17*Assumptions!$B$75*Assumptions!$B$18 -> 27.860182 | K28: =K27*Assumptions!$B$17*Assumptions!$B$75*Assumptions!$B$18 -> 30.261416 | ... M28: =M27*Assumptions!$B$17*Assumptions!$B$75*Assumptions!$B$18 -> 32.363276
A30: MarineMax (strategic dealer-group buyer)
A31: Routed MarineMax service / repower EBITDA (scaled to footprint) | D31: =Assumptions!$B$79*Assumptions!$B$80*MIN(1,'Roll-Up Model'!D11/Assumptions!$B$81) -> 0.88 | E31: =Assumptions!$B$79*Assumptions!$B$80*MIN(1,'Roll-Up Model'!E11/Assumptions!$B$81) -> 1.54 | F31: =Assumptions!$B$79*Assumptions!$B$80*MIN(1,'Roll-Up Model'!F11/Assumptions!$B$81) -> 2.2 | G31: =Assumptions!$B$79*Assumptions!$B$80*MIN(1,'Roll-Up Model'!G11/Assumptions!$B$81) -> 2.86 | H31: =Assumptions!$B$79*Assumptions!$B$80*MIN(1,'Roll-Up Model'!H11/Assumptions!$B$81) -> 3.52 | I31: =Assumptions!$B$79*Assumptions!$B$80*MIN(1,'Roll-Up Model'!I11/Assumptions!$B$81) -> 3.96 | J31: =Assumptions!$B$79*Assumptions!$B$80*MIN(1,'Roll-Up Model'!J11/Assumptions!$B$81) -> 4.4 | K31: =Assumptions!$B$79*Assumptions!$B$80*MIN(1,'Roll-Up Model'!K11/Assumptions!$B$81) -> 4.4 | ... M31: =Assumptions!$B$79*Assumptions!$B$80*MIN(1,'Roll-Up Model'!M11/Assumptions!$B$81) -> 4.4
A32: Parts purchasing cost synergies | D32: ='Roll-Up Model'!D28*Assumptions!$B$84 -> 0.105 | E32: ='Roll-Up Model'!E28*Assumptions!$B$84 -> 0.1787625 | F32: ='Roll-Up Model'!F28*Assumptions!$B$84 -> 0.28594238 | G32: ='Roll-Up Model'!G28*Assumptions!$B$84 -> 0.4139281 | H32: ='Roll-Up Model'!H28*Assumptions!$B$84 -> 0.55060785 | I32: ='Roll-Up Model'!I28*Assumptions!$B$84 -> 0.68059015 | J32: ='Roll-Up Model'!J28*Assumptions!$B$84 -> 0.80225109 | K32: ='Roll-Up Model'!K28*Assumptions!$B$84 -> 0.9313994 | ... M32: ='Roll-Up Model'!M28*Assumptions!$B$84 -> 1.139028
A33: TOTAL MarineMax buyer synergy EBITDA | D33: =D31+D32 -> 0.985 | E33: =E31+E32 -> 1.7187625 | F33: =F31+F32 -> 2.4859424 | G33: =G31+G32 -> 3.2739281 | H33: =H31+H32 -> 4.0706078 | I33: =I31+I32 -> 4.6405902 | J33: =J31+J32 -> 5.2022511 | K33: =K31+K32 -> 5.3313994 | ... M33: =M31+M32 -> 5.539028
A34: Synergy value paid to seller (x HZO mult x haircut x share) | D34: =D33*Assumptions!$B$83*Assumptions!$B$75*Assumptions!$B$18 -> 1.86165 | E34: =E33*Assumptions!$B$83*Assumptions!$B$75*Assumptions!$B$18 -> 3.2484611 | F34: =F33*Assumptions!$B$83*Assumptions!$B$75*Assumptions!$B$18 -> 4.6984311 | G34: =G33*Assumptions!$B$83*Assumptions!$B$75*Assumptions!$B$18 -> 6.1877241 | H34: =H33*Assumptions!$B$83*Assumptions!$B$75*Assumptions!$B$18 -> 7.6934488 | I34: =I33*Assumptions!$B$83*Assumptions!$B$75*Assumptions!$B$18 -> 8.7707154 | J34: =J33*Assumptions!$B$83*Assumptions!$B$75*Assumptions!$B$18 -> 9.8322546 | K34: =K33*Assumptions!$B$83*Assumptions!$B$75*Assumptions!$B$18 -> 10.076345 | ... M34: =M33*Assumptions!$B$83*Assumptions!$B$75*Assumptions!$B$18 -> 10.468763
A36: C. WHY BX INFRA IS THE NATURAL OWNER
A37: 1. Safe Harbor (BX Infra, $5.65B, 138 marinas, closed Apr-2025) owns the slips; the platform owns the engine-room. Embedding service bays converts ad-hoc repair into marina-contracted, infra-like revenue.
A38: 2. Every Safe Harbor slip holder with a diesel is a captive service customer; the platform's own embedded-bay program (Roll-Up Model row 'Safe Harbor marinas') is the proof-of-concept a buyer underwrites.
A39: 3. MarineMax (120+ locations, 65 marinas/storage, IGY superyacht marinas) is both a channel (repower, warranty overflow, superyacht diesel work) and the competing strategic bidder that keeps BX honest on price.
A40: 4. Infra capital prices contracted cash flows at a premium to services multiples; the model blends exit multiple by contracted revenue share, so the thesis is to 'infrastructure-ize' revenue before exit.

Sheet Exit & Returns
A1: EXIT ROUTES & LEVIATHAN RETURNS
A2: Routes: (1) 100% sale to Blackstone Infrastructure / Safe Harbor (2) Spin / partial: 60% to BX Infra, 40% retained to Y10 (3) MarineMax strategic (4) Sponsor-to-sponsor. $M.
A3: Year index | C3: 0 | D3: 1 | E3: 2 | F3: 3 | G3: 4 | H3: 5 | I3: 6 | J3: 7 | K3: 8 | L3: 9 | M3: 10
A4: Exit valuation if sold at end of year | C4: Close | D4: 2027 | E4: 2028 | F4: 2029 | G4: 2030 | H4: 2031 | I4: 2032 | J4: 2033 | K4: 2034 | L4: 2035 | M4: 2036
A5: Adjusted EBITDA | D5: ='Roll-Up Model'!D40 -> 1.5048125 | E5: ='Roll-Up Model'!E40 -> 3.326713 | F5: ='Roll-Up Model'!F40 -> 6.4385044 | G5: ='Roll-Up Model'!G40 -> 10.601323 | H5: ='Roll-Up Model'!H40 -> 14.441766 | I5: ='Roll-Up Model'!I40 -> 18.106562 | J5: ='Roll-Up Model'!J40 -> 21.52728 | K5: ='Roll-Up Model'!K40 -> 25.138945 | ... M5: ='Roll-Up Model'!M40 -> 31.008694
A6: Contracted % of revenue | D6: ='Roll-Up Model'!D32 -> 0.17857143 | E6: ='Roll-Up Model'!E32 -> 0.20714286 | F6: ='Roll-Up Model'!F32 -> 0.26954275 | G6: ='Roll-Up Model'!G32 -> 0.33177123 | H6: ='Roll-Up Model'!H32 -> 0.37412893 | I6: ='Roll-Up Model'!I32 -> 0.40975954 | J6: ='Roll-Up Model'!J32 -> 0.44228914 | K6: ='Roll-Up Model'!K32 -> 0.44715723 | ... M6: ='Roll-Up Model'!M32 -> 0.45833662
A7: Blended standalone multiple (services x (1-c) + infra x c) | D7: =Assumptions!$B$16*(1-D6)+Assumptions!$B$17*D6 -> 10.892857 | E7: =Assumptions!$B$16*(1-E6)+Assumptions!$B$17*E6 -> 11.035714 | F7: =Assumptions!$B$16*(1-F6)+Assumptions!$B$17*F6 -> 11.347714 | G7: =Assumptions!$B$16*(1-G6)+Assumptions!$B$17*G6 -> 11.658856 | H7: =Assumptions!$B$16*(1-H6)+Assumptions!$B$17*H6 -> 11.870645 | I7: =Assumptions!$B$16*(1-I6)+Assumptions!$B$17*I6 -> 12.048798 | J7: =Assumptions!$B$16*(1-J6)+Assumptions!$B$17*J6 -> 12.211446 | K7: =Assumptions!$B$16*(1-K6)+Assumptions!$B$17*K6 -> 12.235786 | ... M7: =Assumptions!$B$16*(1-M6)+Assumptions!$B$17*M6 -> 12.291683
A8: Net debt | D8: ='Roll-Up Model'!D85 -> 6.13875 | E8: ='Roll-Up Model'!E85 -> 8.719625 | F8: ='Roll-Up Model'!F85 -> 11.076735 | G8: ='Roll-Up Model'!G85 -> 11.62378 | H8: ='Roll-Up Model'!H85 -> 12.303627 | I8: ='Roll-Up Model'!I85 -> 13.294332 | J8: ='Roll-Up Model'!J85 -> 14.376747 | K8: ='Roll-Up Model'!K85 -> 15.556688 | ... M8: ='Roll-Up Model'!M85 -> 14.000726
A9: Cumulative contributed equity (Leviathan + rollover) | D9: ='Roll-Up Model'!D97 -> 6.1884438 | E9: ='Roll-Up Model'!E97 -> 8.9012742 | F9: ='Roll-Up Model'!F97 -> 11.254232 | G9: ='Roll-Up Model'!G97 -> 13.362509 | H9: ='Roll-Up Model'!H97 -> 15.555116 | I9: ='Roll-Up Model'!I97 -> 17.075324 | J9: ='Roll-Up Model'!J97 -> 18.522169 | K9: ='Roll-Up Model'!K97 -> 18.796212 | ... M9: ='Roll-Up Model'!M97 -> 18.938714
A10: Leviathan ownership | D10: ='Roll-Up Model'!D101 -> 0.71465286 | E10: ='Roll-Up Model'!E101 -> 0.75728318 | F10: ='Roll-Up Model'!F101 -> 0.76775583 | G10: ='Roll-Up Model'!G101 -> 0.77107402 | H10: ='Roll-Up Model'!H101 -> 0.77300854 | I10: ='Roll-Up Model'!I101 -> 0.77396056 | J10: ='Roll-Up Model'!J101 -> 0.7744942 | K10: ='Roll-Up Model'!K101 -> 0.77298815 | ... M10: ='Roll-Up Model'!M101 -> 0.77232085
A11: Cumulative Leviathan equity drawn | D11: ='Roll-Up Model'!D94 -> 4.5626938 | E11: ='Roll-Up Model'!E94 -> 6.9506542 | F11: ='Roll-Up Model'!F94 -> 8.9657475 | G11: ='Roll-Up Model'!G94 -> 10.722645 | H11: ='Roll-Up Model'!H94 -> 12.549817 | I11: ='Roll-Up Model'!I94 -> 13.816657 | J11: ='Roll-Up Model'!J94 -> 15 | K11: ='Roll-Up Model'!K94 -> 15 | ... M11: ='Roll-Up Model'!M94 -> 15
A12: Cumulative interim distributions to Leviathan (Y5+) | D12: ='Roll-Up Model'!D103 -> 0 | E12: ='Roll-Up Model'!E103 -> 0 | F12: ='Roll-Up Model'!F103 -> 0 | G12: ='Roll-Up Model'!G103 -> 0 | H12: ='Roll-Up Model'!H103 -> 1.8395078 | I12: ='Roll-Up Model'!I103 -> 6.9319251 | J12: ='Roll-Up Model'!J103 -> 13.565008 | K12: ='Roll-Up Model'!K103 -> 21.11476 | ... M12: ='Roll-Up Model'!M103 -> 43.410622
A14: ROUTE 1 — 100% SALE TO BLACKSTONE INFRASTRUCTURE (Safe Harbor tuck-in)
A15: Enterprise value | D15: =D5*D7+Synergies!D28 -> 21.614408 | E15: =E5*E7+Synergies!E28 -> 45.820958 | F15: =F5*F7+Synergies!F28 -> 86.266742 | G15: =G5*G7+Synergies!G28 -> 141.03095 | H15: =H5*H7+Synergies!H28 -> 193.14671 | I15: =I5*I7+Synergies!I28 -> 242.97542 | J15: =J5*J7+Synergies!J28 -> 290.7394 | K15: =K5*K7+Synergies!K28 -> 337.85618 | ... M15: =M5*M7+Synergies!M28 -> 413.51231
A16: Implied EV / EBITDA | D16: =IF(D5=0,0,D15/D5) -> 14.363522 | E16: =IF(E5=0,0,E15/E5) -> 13.773643 | F16: =IF(F5=0,0,F15/F5) -> 13.398568 | G16: =IF(G5=0,0,G15/G5) -> 13.303146 | H16: =IF(H5=0,0,H15/H5) -> 13.374175 | I16: =IF(I5=0,0,I15/I5) -> 13.419191 | J16: =IF(J5=0,0,J15/J5) -> 13.505626 | K16: =IF(K5=0,0,K15/K5) -> 13.439552 | ... M16: =IF(M5=0,0,M15/M5) -> 13.335367
A17: Equity value (EV - net debt - exit costs) | D17: =D15*(1-Assumptions!$B$74)-D8 -> 15.043369 | E17: =E15*(1-Assumptions!$B$74)-E8 -> 36.184914 | F17: =F15*(1-Assumptions!$B$74)-F8 -> 73.464672 | G17: =G15*(1-Assumptions!$B$74)-G8 -> 126.58655 | H17: =H15*(1-Assumptions!$B$74)-H8 -> 176.98014 | I17: =I15*(1-Assumptions!$B$74)-I8 -> 224.82158 | J17: =J15*(1-Assumptions!$B$74)-J8 -> 270.54786 | K17: =K15*(1-Assumptions!$B$74)-K8 -> 315.54236 | ... M17: =M15*(1-Assumptions!$B$74)-M8 -> 391.24134
A18: Less: management incentive pool | D18: =-Assumptions!$B$73*MAX(0,D17-D9) -> -0.88549256 | E18: =-Assumptions!$B$73*MAX(0,E17-E9) -> -2.728364 | F18: =-Assumptions!$B$73*MAX(0,F17-F9) -> -6.221044 | G18: =-Assumptions!$B$73*MAX(0,G17-G9) -> -11.322404 | H18: =-Assumptions!$B$73*MAX(0,H17-H9) -> -16.142503 | I18: =-Assumptions!$B$73*MAX(0,I17-I9) -> -20.774626 | J18: =-Assumptions!$B$73*MAX(0,J17-J9) -> -25.202569 | K18: =-Assumptions!$B$73*MAX(0,K17-K9) -> -29.674615 | ... M18: =-Assumptions!$B$73*MAX(0,M17-M9) -> -37.230263
A19: LEVIATHAN GROSS PROCEEDS | D19: =MAX(0,(D17+D18)*D10) -> 10.117967 | E19: =MAX(0,(E17+E18)*E10) -> 25.336082 | F19: =MAX(0,(F17+F18)*F10) -> 51.626687 | G19: =MAX(0,(G17+G18)*G10) -> 88.877188 | H19: =MAX(0,(H17+H18)*H10) -> 124.32887 | I19: =MAX(0,(I17+I18)*I10) -> 157.9243 | J19: =MAX(0,(J17+J18)*J10) -> 190.01851 | K19: =MAX(0,(K17+K18)*K10) -> 220.97238 | ... M19: =MAX(0,(M17+M18)*M10) -> 273.41014
A20: Gross MOIC (incl. interim distributions) | D20: =IF(D11=0,0,(D19+D12)/D11) -> 2.2175424 | E20: =IF(E11=0,0,(E19+E12)/E11) -> 3.6451364 | F20: =IF(F11=0,0,(F19+F12)/F11) -> 5.7582134 | G20: =IF(G11=0,0,(G19+G12)/G11) -> 8.2887378 | H20: =IF(H11=0,0,(H19+H12)/H11) -> 10.053404 | I20: =IF(I11=0,0,(I19+I12)/I11) -> 11.931701 | J20: =IF(J11=0,0,(J19+J12)/J11) -> 13.572234 | K20: =IF(K11=0,0,(K19+K12)/K11) -> 16.139143 | ... M20: =IF(M11=0,0,(M19+M12)/M11) -> 21.121384
A22: ROUTE 2 — SPIN / PARTIAL: 60% SOLD TO BX INFRA, 40% RETAINED TO Y10
A23: Proceeds on 60% sold at exit year (Route 1 pricing) | D23: =D19*(1-Assumptions!$B$85) -> 6.0707803 | E23: =E19*(1-Assumptions!$B$85) -> 15.201649 | F23: =F19*(1-Assumptions!$B$85) -> 30.976012 | G23: =G19*(1-Assumptions!$B$85) -> 53.326313 | H23: =H19*(1-Assumptions!$B$85) -> 74.597322 | I23: =I19*(1-Assumptions!$B$85) -> 94.754578 | J23: =J19*(1-Assumptions!$B$85) -> 114.0111 | K23: =K19*(1-Assumptions!$B$85) -> 132.58343 | ... M23: =M19*(1-Assumptions!$B$85) -> 164.04608
A24: Retained 40% value carried to Y10 | D24: =D19*Assumptions!$B$85*(1+Assumptions!$B$86)^(10-D$3) -> 11.223168 | E24: =E19*Assumptions!$B$85*(1+Assumptions!$B$86)^(10-E$3) -> 25.092483 | F24: =F19*Assumptions!$B$85*(1+Assumptions!$B$86)^(10-F$3) -> 45.652063 | G24: =G19*Assumptions!$B$85*(1+Assumptions!$B$86)^(10-G$3) -> 70.171124 | H24: =H19*Assumptions!$B$85*(1+Assumptions!$B$86)^(10-H$3) -> 87.64398 | I24: =I19*Assumptions!$B$85*(1+Assumptions!$B$86)^(10-I$3) -> 99.398775 | J24: =J19*Assumptions!$B$85*(1+Assumptions!$B$86)^(10-J$3) -> 106.78493 | K24: =K19*Assumptions!$B$85*(1+Assumptions!$B$86)^(10-K$3) -> 110.8751 | ... M24: =M19*Assumptions!$B$85*(1+Assumptions!$B$86)^(10-M$3) -> 109.36406
A25: LEVIATHAN TOTAL VALUE (sold + retained @Y10) | D25: =D23+D24 -> 17.293948 | E25: =E23+E24 -> 40.294132 | F25: =F23+F24 -> 76.628075 | G25: =G23+G24 -> 123.49744 | H25: =H23+H24 -> 162.2413 | I25: =I23+I24 -> 194.15335 | J25: =J23+J24 -> 220.79603 | K25: =K23+K24 -> 243.45853 | ... M25: =M23+M24 -> 273.41014
A26: Gross MOIC (incl. interim distributions) | D26: =IF(D11=0,0,(D25+D12)/D11) -> 3.7902934 | E26: =IF(E11=0,0,(E25+E12)/E11) -> 5.7971712 | F26: =IF(F11=0,0,(F25+F12)/F11) -> 8.5467581 | G26: =IF(G11=0,0,(G25+G12)/G11) -> 11.517442 | H26: =IF(H11=0,0,(H25+H12)/H11) -> 13.074358 | I26: =IF(I11=0,0,(I25+I12)/I11) -> 14.55383 | J26: =IF(J11=0,0,(J25+J12)/J11) -> 15.624069 | K26: =IF(K11=0,0,(K25+K12)/K11) -> 17.63822 | ... M26: =IF(M11=0,0,(M25+M12)/M11) -> 21.121384
A28: ROUTE 3 — STRATEGIC SALE TO MARINEMAX
A29: Enterprise value | D29: =D5*Assumptions!$B$83+Synergies!D34 -> 15.404962 | E29: =E5*Assumptions!$B$83+Synergies!E34 -> 33.188878 | F29: =F5*Assumptions!$B$83+Synergies!F34 -> 62.644971 | G29: =G5*Assumptions!$B$83+Synergies!G34 -> 101.59963 | H29: =H5*Assumptions!$B$83+Synergies!H34 -> 137.66935 | I29: =I5*Assumptions!$B$83+Synergies!I34 -> 171.72977 | J29: =J5*Assumptions!$B$83+Synergies!J34 -> 203.57778 | K29: =K5*Assumptions!$B$83+Synergies!K34 -> 236.32685 | ... M29: =M5*Assumptions!$B$83+Synergies!M34 -> 289.54701
A30: Implied EV / EBITDA | D30: =IF(D5=0,0,D29/D5) -> 10.237131 | E30: =IF(E5=0,0,E29/E5) -> 9.9764777 | F30: =IF(F5=0,0,F29/F5) -> 9.7297395 | G30: =IF(G5=0,0,G29/G5) -> 9.5836747 | H30: =IF(H5=0,0,H29/H5) -> 9.5327222 | I30: =IF(I5=0,0,I29/I5) -> 9.4843943 | J30: =IF(J5=0,0,J29/J5) -> 9.4567346 | K30: =IF(K5=0,0,K29/K5) -> 9.4008261 | ... M30: =IF(M5=0,0,M29/M5) -> 9.3376074
A31: Equity value (EV - net debt - exit costs) | D31: =D29*(1-Assumptions!$B$74)-D8 -> 8.9581133 | E31: =E29*(1-Assumptions!$B$74)-E8 -> 23.805476 | F31: =F29*(1-Assumptions!$B$74)-F8 -> 50.315336 | G31: =G29*(1-Assumptions!$B$74)-G8 -> 87.94386 | H31: =H29*(1-Assumptions!$B$74)-H8 -> 122.61233 | I31: =I29*(1-Assumptions!$B$74)-I8 -> 155.00085 | J31: =J29*(1-Assumptions!$B$74)-J8 -> 185.12948 | K31: =K29*(1-Assumptions!$B$74)-K8 -> 216.04363 | ... M31: =M29*(1-Assumptions!$B$74)-M8 -> 269.75534
A32: Less: management incentive pool | D32: =-Assumptions!$B$73*MAX(0,D31-D9) -> -0.27696694 | E32: =-Assumptions!$B$73*MAX(0,E31-E9) -> -1.4904201 | F32: =-Assumptions!$B$73*MAX(0,F31-F9) -> -3.9061104 | G32: =-Assumptions!$B$73*MAX(0,G31-G9) -> -7.4581351 | H32: =-Assumptions!$B$73*MAX(0,H31-H9) -> -10.705722 | I32: =-Assumptions!$B$73*MAX(0,I31-I9) -> -13.792552 | J32: =-Assumptions!$B$73*MAX(0,J31-J9) -> -16.660731 | K32: =-Assumptions!$B$73*MAX(0,K31-K9) -> -19.724742 | ... M32: =-Assumptions!$B$73*MAX(0,M31-M9) -> -25.081663
A33: LEVIATHAN GROSS PROCEEDS | D33: =MAX(0,(D31+D32)*D10) -> 6.204006 | E33: =MAX(0,(E31+E32)*E10) -> 16.898816 | F33: =MAX(0,(F31+F32)*F10) -> 35.630954 | G33: =MAX(0,(G31+G32)*G10) -> 62.060451 | H33: =MAX(0,(H31+H32)*H10) -> 86.504765 | I33: =MAX(0,(I31+I32)*I10) -> 109.28965 | J33: =MAX(0,(J31+J32)*J10) -> 130.47807 | K33: =MAX(0,(K31+K32)*K10) -> 151.75217 | ... M33: =MAX(0,(M31+M32)*M10) -> 188.96658
A34: Gross MOIC (incl. interim distributions) | D34: =IF(D11=0,0,(D33+D12)/D11) -> 1.3597244 | E34: =IF(E11=0,0,(E33+E12)/E11) -> 2.4312555 | F34: =IF(F11=0,0,(F33+F12)/F11) -> 3.9741197 | G34: =IF(G11=0,0,(G33+G12)/G11) -> 5.7877934 | H34: =IF(H11=0,0,(H33+H12)/H11) -> 7.0394867 | I34: =IF(I11=0,0,(I33+I12)/I11) -> 8.4117001 | J34: =IF(J11=0,0,(J33+J12)/J11) -> 9.6028716 | K34: =IF(K11=0,0,(K33+K12)/K11) -> 11.524462 | ... M34: =IF(M11=0,0,(M33+M12)/M11) -> 15.491814
A36: ROUTE 4 — SPONSOR-TO-SPONSOR (services multiple, no synergies)
A37: Enterprise value | D37: =D5*Assumptions!$B$16 -> 15.048125 | E37: =E5*Assumptions!$B$16 -> 33.26713 | F37: =F5*Assumptions!$B$16 -> 64.385044 | G37: =G5*Assumptions!$B$16 -> 106.01323 | H37: =H5*Assumptions!$B$16 -> 144.41766 | I37: =I5*Assumptions!$B$16 -> 181.06562 | J37: =J5*Assumptions!$B$16 -> 215.2728 | K37: =K5*Assumptions!$B$16 -> 251.38945 | ... M37: =M5*Assumptions!$B$16 -> 310.08694
A38: Implied EV / EBITDA | D38: =IF(D5=0,0,D37/D5) -> 10 | E38: =IF(E5=0,0,E37/E5) -> 10 | F38: =IF(F5=0,0,F37/F5) -> 10 | G38: =IF(G5=0,0,G37/G5) -> 10 | H38: =IF(H5=0,0,H37/H5) -> 10 | I38: =IF(I5=0,0,I37/I5) -> 10 | J38: =IF(J5=0,0,J37/J5) -> 10 | K38: =IF(K5=0,0,K37/K5) -> 10 | ... M38: =IF(M5=0,0,M37/M5) -> 10
A39: Equity value (EV - net debt - exit costs) | D39: =D37*(1-Assumptions!$B$74)-D8 -> 8.6084125 | E39: =E37*(1-Assumptions!$B$74)-E8 -> 23.882163 | F39: =F37*(1-Assumptions!$B$74)-F8 -> 52.020608 | G39: =G37*(1-Assumptions!$B$74)-G8 -> 92.269187 | H39: =H37*(1-Assumptions!$B$74)-H8 -> 129.22568 | I39: =I37*(1-Assumptions!$B$74)-I8 -> 164.14998 | J39: =J37*(1-Assumptions!$B$74)-J8 -> 196.5906 | K39: =K37*(1-Assumptions!$B$74)-K8 -> 230.80498 | ... M39: =M37*(1-Assumptions!$B$74)-M8 -> 289.88447
A40: Less: management incentive pool | D40: =-Assumptions!$B$73*MAX(0,D39-D9) -> -0.24199687 | E40: =-Assumptions!$B$73*MAX(0,E39-E9) -> -1.4980888 | F40: =-Assumptions!$B$73*MAX(0,F39-F9) -> -4.0766376 | G40: =-Assumptions!$B$73*MAX(0,G39-G9) -> -7.8906678 | H40: =-Assumptions!$B$73*MAX(0,H39-H9) -> -11.367057 | I40: =-Assumptions!$B$73*MAX(0,I39-I9) -> -14.707465 | J40: =-Assumptions!$B$73*MAX(0,J39-J9) -> -17.806843 | K40: =-Assumptions!$B$73*MAX(0,K39-K9) -> -21.200876 | ... M40: =-Assumptions!$B$73*MAX(0,M39-M9) -> -27.094576
A41: LEVIATHAN GROSS PROCEEDS | D41: =MAX(0,(D39+D40)*D10) -> 5.9790828 | E41: =MAX(0,(E39+E40)*E10) -> 16.951082 | F41: =MAX(0,(F39+F40)*F10) -> 36.809263 | G41: =MAX(0,(G39+G40)*G10) -> 65.062084 | H41: =MAX(0,(H39+H40)*H10) -> 91.105724 | I41: =MAX(0,(I39+I40)*I10) -> 115.66261 | J41: =MAX(0,(J39+J40)*J10) -> 138.46698 | K41: =MAX(0,(K39+K40)*K10) -> 162.02149 | ... M41: =MAX(0,(M39+M40)*M10) -> 202.95812
A42: Gross MOIC (incl. interim distributions) | D42: =IF(D11=0,0,(D41+D12)/D11) -> 1.3104282 | E42: =IF(E11=0,0,(E41+E12)/E11) -> 2.4387751 | F42: =IF(F11=0,0,(F41+F12)/F11) -> 4.1055431 | G42: =IF(G11=0,0,(G41+G12)/G11) -> 6.0677274 | H42: =IF(H11=0,0,(H41+H12)/H11) -> 7.4061024 | I42: =IF(I11=0,0,(I41+I12)/I11) -> 8.8729519 | J42: =IF(J11=0,0,(J41+J12)/J11) -> 10.135466 | K42: =IF(K11=0,0,(K41+K12)/K11) -> 12.209083 | ... M42: =IF(M11=0,0,(M41+M12)/M11) -> 16.424583
A45: IRR ENGINE — Leviathan gross cash flows by route x exit year (draws negative, proceeds at exit)
A46: Route / exit year | B46: Exit | C46: Close | D46: 2027 | E46: 2028 | F46: 2029 | G46: 2030 | H46: 2031 | I46: 2032 | J46: 2033 | K46: 2034 | L46: 2035 | M46: 2036 | N46: Gross IRR
...

Sheet Sensitivity
A1: SENSITIVITIES — ROUTE 1 (BX INFRA SALE)
A2: Live formulas off the model rows; no data tables. Gross to Leviathan.
