Workbook

Sheet Cover
A1: Project Equity Belt — Investment Model
A2: STAGE 1 MODEL — accelerated timeline. Exit-based returns on deal-team assumptions; full debt schedule, quarterly build and diligence-validated inputs follow in Stage 2.
A3: Project Equity Belt · Blackstone Tactical Opportunities × Infrastructure Partners · Highly Confidential · $ in millions unless noted
A5: STAGE 1 MODEL
A6: This model is in Stage 1 because of the accelerated timeline: Phase 1 capital must be committed before November 3, 2026. Returns are exit-based (entry and exit cash flows) using deal-team assumptions that match the IC memo dated October 5, 2026.
A7: Stage 2 (before the Phase 2 IC in Q1 2027) adds: full OpCo debt schedule and cash sweep, quarterly build by carrier, diligence-validated carrier financials, tax structuring and fee/carry waterfall.
A9: Deal team
A10: Christopher James | B10: Global Head
A11: John Watson | B11: Senior Managing Director
A12: Joseph Cassanelli | B12: Legal & Compliance
A13: Donald B Ritts III | B13: Senior Associate
A15: Key outputs (selected scenario)
A16: Scenario | B16: =Assumptions!F6
A17: Total capitalization ($mm) | B17: ='Sources & Uses'!C12
A18: Tac Opps equity ($mm) | B18: ='Sources & Uses'!G6
A19: BIP equity ($mm) | B19: ='Sources & Uses'!G7
A20: OpCo (Tac Opps) MOIC | B20: =OpCo!C30
A21: OpCo (Tac Opps) IRR | B21: =OpCo!C31
A22: PropCo (BIP) MOIC | B22: =PropCo!C24
A23: PropCo (BIP) IRR | B23: =PropCo!C25
A24: Combined Blackstone IRR | B24: =Returns!C32
A25: Avg payout per employee ($000) | B25: =OpCo!C35
A26: Months of salary | B26: =OpCo!C36
A28: Legend
A29: Blue text | B29: Hard-coded input — edit these on the Assumptions tab
A30: Black text | B30: Formula
A31: Green text | B31: Link to another tab
A32: Yellow fill | B32: Scenario selector (Assumptions!C5): 1 = Downside, 2 = Base, 3 = Upside
A34: Tabs
A35: Assumptions | B35: All inputs, by scenario
A36: Sources & Uses | B36: Capitalization and fund split
A37: OpCo | B37: Tac Opps operating company: EBITDAR build and Exit A returns
A38: PropCo | B38: BIP fleet and terminal property company: lease cash flows and returns
A39: Returns | B39: All scenarios, combined Blackstone view, Exit B (ESOP)
A40: Sensitivities | B40: OpCo IRR grid; diesel exposure grid
A41: Phase 1 | B41: Pre-Nov 3 deployment ($48M) and key dates
A43: Sources: AP (Oct 3, 2026) on Navistar Springfield layoffs; FreightWaves / Newsweek on carrier bankruptcies and $6.37/gal diesel; Blackstone (QTS ownership by BIP and BREIT); internal paper "The Ownership Realignment"; Ownership Works C.H.I. case. All model inputs are deal-team estimates (illustrative, unaudited).

Sheet Assumptions
A1: Assumptions
A2: STAGE 1 MODEL — accelerated timeline. Exit-based returns on deal-team assumptions; full debt schedule, quarterly build and diligence-validated inputs follow in Stage 2.
A3: Project Equity Belt · Blackstone Tactical Opportunities × Infrastructure Partners · Highly Confidential · $ in millions unless noted
A5: Scenario selector (1 = Downside, 2 = Base, 3 = Upside) | C5: 2
A6: Selected scenario | F6: =INDEX(C8:E8,1,$C$5)
A8: Scenario inputs ($mm) | C8: Downside | D8: Base | E8: Upside | F8: Selected | G8: Note
A9: Normalized EBITDAR | C9: 36 | D9: 36 | E9: 36 | F9: =INDEX(C9:E9,1,$C$5) | G9: Platform $15M + six distressed carriers $21M (normalized)
A10: Fuel & procurement synergies (Y4) | C10: 4 | D10: 8 | E10: 12 | F10: =INDEX(C10:E10,1,$C$5) | G10: Base ≈ 2% of ~$350M revenue
A11: Retention savings from employee ownership (Y4) | C11: 2 | D11: 7 | E11: 10 | F11: =INDEX(C11:E11,1,$C$5) | G11: Base cross-check in row 44
A12: Arsenal-1 / QTS dedicated growth (Y4) | C12: 3 | D12: 16 | E12: 32 | F12: =INDEX(C12:E12,1,$C$5) | G12: Requires signed LOIs before Phase 2
A13: Y4 EBITDAR | C13: =SUM(C9:C12) | D13: =SUM(D9:D12) | E13: =SUM(E9:E12) | F13: =INDEX(C13:E13,1,$C$5) | G13: Sum of rows 9–12
A14: Exit multiple on OpCo EBITDA (x) | C14: 6.5 | D14: 8 | E14: 9 | F14: =INDEX(C14:E14,1,$C$5) | G14: Exit A: sale to strategic or sponsor
A15: Exit net debt, OpCo ($mm) | C15: 35 | D15: 20 | E15: 15 | F15: =INDEX(C15:E15,1,$C$5) | G15: Stage 1 input; Stage 2 replaces with debt schedule
A17: Transaction | C17: Value | G17: Note
A18: Platform carrier EBITDA ($mm) | C18: 15 | G18: Healthy flatbed / heavy-haul carrier
A19: Platform entry multiple (x) | C19: 6.5 | G19: Route D
A20: Distressed carriers normalized EBITDA ($mm) | C20: 21 | G20: Six Chapter 11 / 363 targets
A21: Distressed entry multiple (x) | C21: 3 | G21: Routes A/B; 2.5–3.5x range
A22: Chapter 7 fleet & yard purchases ($mm) | C22: 20 | G22: Route C; 50–65% of replacement cost
A23: Turnaround working capital & capex ($mm) | C23: 15
A24: Fees & expenses ($mm) | C24: 10.5 | G24: Memo shows $10M (rounded)
A25: OpCo senior debt ($mm) | C25: 45 | G25: About 2.0x Y0 OpCo EBITDA
A27: PropCo / FleetCo (BIP) | C27: Value | G27: Note
A28: Fleet assets ($mm) | C28: 70 | G28: Tractors and trailers incl. Chapter 7 purchases
A29: Real estate ($mm) | C29: 30 | G29: Terminals, yards, transload, training campus
A30: Lease rate (% of asset value) | C30: 0.13 | G30: Triple-net master lease to OpCo
A31: Lease escalator (annual) | C31: 0.025
A32: PropCo asset-backed debt ($mm) | C32: 55
A33: PropCo interest rate | C33: 0.07
A34: Fleet replacement reserve (% of fleet) | C34: 0.06 | G34: Keeps fleet value flat over hold
A35: Real estate appreciation (annual) | C35: 0.03
A37: Workforce & ownership | C37: Value | G37: Note
A38: Employees | C38: 1500 | G38: Drivers, technicians, dispatch, yard
A39: Average salary ($000) | C39: 65
A40: Employee equity pool (% of exit equity) | C40: 0.18 | G40: Ownership Works target: 6–12 months of salary
A41: Driver turnover — current | C41: 0.6
A42: Driver turnover — target | C42: 0.2
A43: Cost per replacement hire ($000) | C43: 12 | G43: Recruiting, onboarding, lost utilization
A44: Retention savings cross-check ($mm) | C44: =(C41-C42)*C38*C43/1000 | G44: Compare with Base row 11
A46: Hold & exit | C46: Value | G46: Note
...

Sheet Sources & Uses
A1: Sources & Uses
A2: STAGE 1 MODEL — accelerated timeline. Exit-based returns on deal-team assumptions; full debt schedule, quarterly build and diligence-validated inputs follow in Stage 2.
A3: Project Equity Belt · Blackstone Tactical Opportunities × Infrastructure Partners · Highly Confidential · $ in millions unless noted
A5: Uses | C5: $mm | E5: Sources | G5: $mm | H5: % total
A6: Specialized platform carrier | C6: =Assumptions!C18*Assumptions!C19 | E6: Tac Opps equity (OpCo) | G6: =C12-G8-G9-G7 | H6: =G6/$G$12
A7: 6 distressed carriers | C7: =Assumptions!C20*Assumptions!C21 | E7: BIP equity (PropCo) | G7: =Assumptions!C28+Assumptions!C29-Assumptions!C32 | H7: =G7/$G$12
A8: Chapter 7 fleet & yards | C8: =Assumptions!C22 | E8: PropCo asset-backed debt | G8: =Assumptions!C32 | H8: =G8/$G$12
A9: Turnaround working capital & capex | C9: =Assumptions!C23 | E9: OpCo senior debt | G9: =Assumptions!C25 | H9: =G9/$G$12
A10: Fees & expenses | C10: =Assumptions!C24
A12: Total uses | C12: =SUM(C6:C10) | E12: Total sources | G12: =SUM(G6:G9)
A13: All-in entry multiple on normalized EBITDAR | C13: =C12/Assumptions!F9 | E13: Check: sources − uses | G13: =G12-C12
A15: PropCo carve-out (sale-leaseback of hard assets) | E15: Blackstone equity | G15: =G6+G7
A16: Fleet assets | C16: =Assumptions!C28 | E16: Single-fund Tac Opps equity (prior structure) | G16: 111
A17: Real estate | C17: =Assumptions!C29 | E17: Reduction in Tac Opps check | G17: =G16-G6
A18: PropCo assets | C18: =C16+C17
A20: G16 is the Tac Opps equity in the earlier single-fund version of the plan ($206M with $95M of debt), per the IC memo; input from the deal team.

Sheet PropCo
A1: PropCo / FleetCo — Blackstone Infrastructure Partners
A2: STAGE 1 MODEL — accelerated timeline. Exit-based returns on deal-team assumptions; full debt schedule, quarterly build and diligence-validated inputs follow in Stage 2.
A3: Project Equity Belt · Blackstone Tactical Opportunities × Infrastructure Partners · Highly Confidential · $ in millions unless noted
A5: $mm | C5: Y0 | D5: Y1 | E5: Y2 | F5: Y3 | G5: Y4
A6: Year | C6: 0 | D6: 1 | E6: 2 | F6: 3 | G6: 4
A8: Lease income from OpCo | D8: =(Assumptions!$C$28+Assumptions!$C$29)*Assumptions!$C$30*(1+Assumptions!$C$31)^(D6-1) | E8: =(Assumptions!$C$28+Assumptions!$C$29)*Assumptions!$C$30*(1+Assumptions!$C$31)^(E6-1) | F8: =(Assumptions!$C$28+Assumptions!$C$29)*Assumptions!$C$30*(1+Assumptions!$C$31)^(F6-1) | G8: =(Assumptions!$C$28+Assumptions!$C$29)*Assumptions!$C$30*(1+Assumptions!$C$31)^(G6-1)
A9: Less: interest | D9: =-Assumptions!$C$32*Assumptions!$C$33 | E9: =-Assumptions!$C$32*Assumptions!$C$33 | F9: =-Assumptions!$C$32*Assumptions!$C$33 | G9: =-Assumptions!$C$32*Assumptions!$C$33
A10: Less: fleet replacement reserve | D10: =-Assumptions!$C$28*Assumptions!$C$34 | E10: =-Assumptions!$C$28*Assumptions!$C$34 | F10: =-Assumptions!$C$28*Assumptions!$C$34 | G10: =-Assumptions!$C$28*Assumptions!$C$34
A11: Cash to equity | D11: =SUM(D8:D10) | E11: =SUM(E8:E10) | F11: =SUM(F8:F10) | G11: =SUM(G8:G10)
A12: Cash yield on BIP equity | D12: =D11/'Sources & Uses'!$G$7 | E12: =E11/'Sources & Uses'!$G$7 | F12: =F11/'Sources & Uses'!$G$7 | G12: =G11/'Sources & Uses'!$G$7
A14: Exit (Y4)
A15: Fleet value (held flat by reserve) | G15: =Assumptions!C28
A16: Real estate value | G16: =Assumptions!C29*(1+Assumptions!C35)^Assumptions!C47
A17: Less: PropCo debt | G17: =-Assumptions!C32
A18: Exit equity value | G18: =SUM(G15:G17)
A20: BIP equity cash flows | C20: =-'Sources & Uses'!G7 | D20: =D11 | E20: =E11 | F20: =F11 | G20: =G11+G18
A22: Returns
A23: Y1 cash yield | C23: =D12
A24: Gross MOIC | C24: =SUM(D20:G20)/-C20
A25: Gross IRR | C25: =IRR(C20:G20)

Sheet OpCo
A1: OpCo — Tactical Opportunities (Exit A: sale to strategic or sponsor)
A2: STAGE 1 MODEL — accelerated timeline. Exit-based returns on deal-team assumptions; full debt schedule, quarterly build and diligence-validated inputs follow in Stage 2.
A3: Project Equity Belt · Blackstone Tactical Opportunities × Infrastructure Partners · Highly Confidential · $ in millions unless noted
A4: Scenario: | C4: =Assumptions!F6
A5: $mm | C5: Y0 | D5: Y1 | E5: Y2 | F5: Y3 | G5: Y4
A6: Year | C6: 0 | D6: 1 | E6: 2 | F6: 3 | G6: 4
A7: Synergy ramp | C7: 0 | D7: =Assumptions!C63 | E7: =Assumptions!D63 | F7: =Assumptions!E63 | G7: =Assumptions!F63
A9: Normalized EBITDAR | C9: =Assumptions!$F$9 | D9: =Assumptions!$F$9 | E9: =Assumptions!$F$9 | F9: =Assumptions!$F$9 | G9: =Assumptions!$F$9
A10: Fuel & procurement synergies | C10: =Assumptions!$F$10*C$7 | D10: =Assumptions!$F$10*D$7 | E10: =Assumptions!$F$10*E$7 | F10: =Assumptions!$F$10*F$7 | G10: =Assumptions!$F$10*G$7
A11: Retention savings | C11: =Assumptions!$F$11*C$7 | D11: =Assumptions!$F$11*D$7 | E11: =Assumptions!$F$11*E$7 | F11: =Assumptions!$F$11*F$7 | G11: =Assumptions!$F$11*G$7
A12: Arsenal-1 / QTS dedicated growth | C12: =Assumptions!$F$12*C$7 | D12: =Assumptions!$F$12*D$7 | E12: =Assumptions!$F$12*E$7 | F12: =Assumptions!$F$12*F$7 | G12: =Assumptions!$F$12*G$7
A13: EBITDAR | C13: =SUM(C9:C12) | D13: =SUM(D9:D12) | E13: =SUM(E9:E12) | F13: =SUM(F9:F12) | G13: =SUM(G9:G12)
A14: Less: PropCo lease | C14: =-PropCo!D8 | D14: =-PropCo!D8 | E14: =-PropCo!E8 | F14: =-PropCo!F8 | G14: =-PropCo!G8
A15: OpCo EBITDA | C15: =C13+C14 | D15: =D13+D14 | E15: =E13+E14 | F15: =F13+F14 | G15: =G13+G14
A16: Y0 lease shown at Y1 run-rate
A18: Exit A (Y4)
A19: Y4 OpCo EBITDA | C19: =G15
A20: Exit multiple (x) | C20: =Assumptions!F14
A21: Enterprise value | C21: =C19*C20
A22: Less: exit net debt | C22: =-Assumptions!F15
A23: Equity value | C23: =C21+C22
A24: Employee pool (%) | C24: =Assumptions!C40
A25: Employee pool ($mm) | C25: =C23*C24
A26: Proceeds to Tac Opps | C26: =C23-C25
A28: Tac Opps cash flows | C28: =-'Sources & Uses'!G6 | D28: 0 | E28: 0 | F28: 0 | G28: =C26
A30: Gross MOIC | C30: =SUM(D28:G28)/-C28
A31: Gross IRR | C31: =IRR(C28:G28)
A33: Employee ownership payout
A34: Employees | C34: =Assumptions!C38
A35: Average payout per employee ($000) | C35: =C25/C34*1000
A36: Months of salary | C36: =C35/Assumptions!C39*12
A37: Within Ownership Works 6–12 month target? | C37: =IF(AND(C36>=6,C36<=12),"Yes",IF(C36>12,"Above","Below"))

Sheet Returns
A1: Returns — all scenarios, combined Blackstone, Exit B
A2: STAGE 1 MODEL — accelerated timeline. Exit-based returns on deal-team assumptions; full debt schedule, quarterly build and diligence-validated inputs follow in Stage 2.
A3: Project Equity Belt · Blackstone Tactical Opportunities × Infrastructure Partners · Highly Confidential · $ in millions unless noted
A5: Exit A by scenario ($mm) | C5: Downside | D5: Base | E5: Upside
A6: Y4 EBITDAR | C6: =Assumptions!C13 | D6: =Assumptions!D13 | E6: =Assumptions!E13
A7: Less: PropCo lease (Y4) | C7: =-PropCo!$G$8 | D7: =-PropCo!$G$8 | E7: =-PropCo!$G$8
A8: OpCo EBITDA | C8: =C6+C7 | D8: =D6+D7 | E8: =E6+E7
A9: Exit multiple (x) | C9: =Assumptions!C14 | D9: =Assumptions!D14 | E9: =Assumptions!E14
A10: Enterprise value | C10: =C8*C9 | D10: =D8*D9 | E10: =E8*E9
A11: Less: exit net debt | C11: =-Assumptions!C15 | D11: =-Assumptions!D15 | E11: =-Assumptions!E15
A12: Equity value | C12: =C10+C11 | D12: =D10+D11 | E12: =E10+E11
A13: Employee pool ($mm) | C13: =C12*Assumptions!$C$40 | D13: =D12*Assumptions!$C$40 | E13: =E12*Assumptions!$C$40
A14: Average per employee ($000) | C14: =C13/Assumptions!$C$38*1000 | D14: =D13/Assumptions!$C$38*1000 | E14: =E13/Assumptions!$C$38*1000
A15: Months of salary | C15: =C14/Assumptions!$C$39*12 | D15: =D14/Assumptions!$C$39*12 | E15: =E14/Assumptions!$C$39*12
A16: Proceeds to Tac Opps | C16: =C12-C13 | D16: =D12-D13 | E16: =E12-E13
A17: Tac Opps equity | C17: ='Sources & Uses'!$G$6 | D17: ='Sources & Uses'!$G$6 | E17: ='Sources & Uses'!$G$6
A18: Gross MOIC | C18: =C16/C17 | D18: =D16/D17 | E18: =E16/E17
A19: Gross IRR | C19: =IFERROR(C18^(1/Assumptions!$C$47)-1,-1) | D19: =IFERROR(D18^(1/Assumptions!$C$47)-1,-1) | E19: =IFERROR(E18^(1/Assumptions!$C$47)-1,-1)
A20: IRR = MOIC^(1/hold) − 1, equivalent to IRR() for a single entry and single exit cash flow.
A22: Combined Blackstone (selected scenario) | C22: Y0 | D22: Y1 | E22: Y2 | F22: Y3 | G22: Y4
A23: Tac Opps (OpCo) | C23: =OpCo!C28 | D23: =OpCo!D28 | E23: =OpCo!E28 | F23: =OpCo!F28 | G23: =OpCo!G28
A24: BIP (PropCo) | C24: =PropCo!C20 | D24: =PropCo!D20 | E24: =PropCo!E20 | F24: =PropCo!F20 | G24: =PropCo!G20
A25: Combined | C25: =C23+C24 | D25: =D23+D24 | E25: =E23+E24 | F25: =F23+F24 | G25: =G23+G24
A27: Combined Blackstone equity in | C27: =-C25
A28: Combined value out | C28: =SUM(D25:G25)
A31: Combined gross MOIC | C31: =C28/C27
A32: Combined gross IRR | C32: =IRR(C25:G25)
A35: Exit B: 100% S-corp ESOP (selected scenario) | C35: Y0 | D35: Y1 | E35: Y2 | F35: Y3 | G35: Y4 | H35: Y5 | I35: Y6 | J35: Y7 | K35: Y8 | L35: Y9
A36: ESOP purchase multiple (x) | C36: =Assumptions!C48
A37: Equity value to Tac Opps | C37: =OpCo!C19*C36+OpCo!C22
A38: Cash at close | C38: =C37*Assumptions!C49
A39: Seller note | C39: =C37-C38
A40: Annual note payment | C40: =-PMT(Assumptions!C50,Assumptions!C51,C39)
A42: Tac Opps cash flows | C42: =OpCo!C28 | D42: 0 | E42: 0 | F42: 0 | G42: =$C$38 | H42: =IF(5-4<=Assumptions!$C$51,$C$40,0) | I42: =IF(6-4<=Assumptions!$C$51,$C$40,0) | J42: =IF(7-4<=Assumptions!$C$51,$C$40,0) | K42: =IF(8-4<=Assumptions!$C$51,$C$40,0) | L42: =IF(9-4<=Assumptions!$C$51,$C$40,0)
A43: Gross MOIC | C43: =SUM(D42:L42)/-C42
A44: Gross IRR | C44: =IRR(C42:L42)
A45: Under Exit B employees own 100%; no separate pool. A 100% ESOP S-corp pays no federal income tax, so the note is serviced from untaxed cash flow.

Sheet Sensitivities
A1: Sensitivities
A2: STAGE 1 MODEL — accelerated timeline. Exit-based returns on deal-team assumptions; full debt schedule, quarterly build and diligence-validated inputs follow in Stage 2.
A3: Project Equity Belt · Blackstone Tactical Opportunities × Infrastructure Partners · Highly Confidential · $ in millions unless noted
A5: OpCo gross IRR — Y4 EBITDAR (rows) × exit multiple (columns); base-case exit net debt and pool
A6: Y4 EBITDAR ($mm) | B6: 6.5x | C6: 7.0x | D6: 7.5x | E6: 8.0x | F6: 8.5x | G6: 9.0x
A7: Multiple → | B7: 6.5 | C7: 7 | D7: 7.5 | E7: 8 | F7: 8.5 | G7: 9
A8: 45 | B8: =IFERROR(((($A8-PropCo!$G$8)*B$7-Assumptions!$D$15)*(1-Assumptions!$C$40)/'Sources & Uses'!$G$6)^(1/Assumptions!$C$47)-1,-1) | C8: =IFERROR(((($A8-PropCo!$G$8)*C$7-Assumptions!$D$15)*(1-Assumptions!$C$40)/'Sources & Uses'!$G$6)^(1/Assumptions!$C$47)-1,-1) | D8: =IFERROR(((($A8-PropCo!$G$8)*D$7-Assumptions!$D$15)*(1-Assumptions!$C$40)/'Sources & Uses'!$G$6)^(1/Assumptions!$C$47)-1,-1) | E8: =IFERROR(((($A8-PropCo!$G$8)*E$7-Assumptions!$D$15)*(1-Assumptions!$C$40)/'Sources & Uses'!$G$6)^(1/Assumptions!$C$47)-1,-1) | F8: =IFERROR(((($A8-PropCo!$G$8)*F$7-Assumptions!$D$15)*(1-Assumptions!$C$40)/'Sources & Uses'!$G$6)^(1/Assumptions!$C$47)-1,-1) | G8: =IFERROR(((($A8-PropCo!$G$8)*G$7-Assumptions!$D$15)*(1-Assumptions!$C$40)/'Sources & Uses'!$G$6)^(1/Assumptions!$C$47)-1,-1)
A9: 55 | B9: =IFERROR(((($A9-PropCo!$G$8)*B$7-Assumptions!$D$15)*(1-Assumptions!$C$40)/'Sources & Uses'!$G$6)^(1/Assumptions!$C$47)-1,-1) | C9: =IFERROR(((($A9-PropCo!$G$8)*C$7-Assumptions!$D$15)*(1-Assumptions!$C$40)/'Sources & Uses'!$G$6)^(1/Assumptions!$C$47)-1,-1) | D9: =IFERROR(((($A9-PropCo!$G$8)*D$7-Assumptions!$D$15)*(1-Assumptions!$C$40)/'Sources & Uses'!$G$6)^(1/Assumptions!$C$47)-1,-1) | E9: =IFERROR(((($A9-PropCo!$G$8)*E$7-Assumptions!$D$15)*(1-Assumptions!$C$40)/'Sources & Uses'!$G$6)^(1/Assumptions!$C$47)-1,-1) | F9: =IFERROR(((($A9-PropCo!$G$8)*F$7-Assumptions!$D$15)*(1-Assumptions!$C$40)/'Sources & Uses'!$G$6)^(1/Assumptions!$C$47)-1,-1) | G9: =IFERROR(((($A9-PropCo!$G$8)*G$7-Assumptions!$D$15)*(1-Assumptions!$C$40)/'Sources & Uses'!$G$6)^(1/Assumptions!$C$47)-1,-1)
A10: 67 | B10: =IFERROR(((($A10-PropCo!$G$8)*B$7-Assumptions!$D$15)*(1-Assumptions!$C$40)/'Sources & Uses'!$G$6)^(1/Assumptions!$C$47)-1,-1) | C10: =IFERROR(((($A10-PropCo!$G$8)*C$7-Assumptions!$D$15)*(1-Assumptions!$C$40)/'Sources & Uses'!$G$6)^(1/Assumptions!$C$47)-1,-1) | D10: =IFERROR(((($A10-PropCo!$G$8)*D$7-Assumptions!$D$15)*(1-Assumptions!$C$40)/'Sources & Uses'!$G$6)^(1/Assumptions!$C$47)-1,-1) | E10: =IFERROR(((($A10-PropCo!$G$8)*E$7-Assumptions!$D$15)*(1-Assumptions!$C$40)/'Sources & Uses'!$G$6)^(1/Assumptions!$C$47)-1,-1) | F10: =IFERROR(((($A10-PropCo!$G$8)*F$7-Assumptions!$D$15)*(1-Assumptions!$C$40)/'Sources & Uses'!$G$6)^(1/Assumptions!$C$47)-1,-1) | G10: =IFERROR(((($A10-PropCo!$G$8)*G$7-Assumptions!$D$15)*(1-Assumptions!$C$40)/'Sources & Uses'!$G$6)^(1/Assumptions!$C$47)-1,-1)
A11: 80 | B11: =IFERROR(((($A11-PropCo!$G$8)*B$7-Assumptions!$D$15)*(1-Assumptions!$C$40)/'Sources & Uses'!$G$6)^(1/Assumptions!$C$47)-1,-1) | C11: =IFERROR(((($A11-PropCo!$G$8)*C$7-Assumptions!$D$15)*(1-Assumptions!$C$40)/'Sources & Uses'!$G$6)^(1/Assumptions!$C$47)-1,-1) | D11: =IFERROR(((($A11-PropCo!$G$8)*D$7-Assumptions!$D$15)*(1-Assumptions!$C$40)/'Sources & Uses'!$G$6)^(1/Assumptions!$C$47)-1,-1) | E11: =IFERROR(((($A11-PropCo!$G$8)*E$7-Assumptions!$D$15)*(1-Assumptions!$C$40)/'Sources & Uses'!$G$6)^(1/Assumptions!$C$47)-1,-1) | F11: =IFERROR(((($A11-PropCo!$G$8)*F$7-Assumptions!$D$15)*(1-Assumptions!$C$40)/'Sources & Uses'!$G$6)^(1/Assumptions!$C$47)-1,-1) | G11: =IFERROR(((($A11-PropCo!$G$8)*G$7-Assumptions!$D$15)*(1-Assumptions!$C$40)/'Sources & Uses'!$G$6)^(1/Assumptions!$C$47)-1,-1)
A12: 90 | B12: =IFERROR(((($A12-PropCo!$G$8)*B$7-Assumptions!$D$15)*(1-Assumptions!$C$40)/'Sources & Uses'!$G$6)^(1/Assumptions!$C$47)-1,-1) | C12: =IFERROR(((($A12-PropCo!$G$8)*C$7-Assumptions!$D$15)*(1-Assumptions!$C$40)/'Sources & Uses'!$G$6)^(1/Assumptions!$C$47)-1,-1) | D12: =IFERROR(((($A12-PropCo!$G$8)*D$7-Assumptions!$D$15)*(1-Assumptions!$C$40)/'Sources & Uses'!$G$6)^(1/Assumptions!$C$47)-1,-1) | E12: =IFERROR(((($A12-PropCo!$G$8)*E$7-Assumptions!$D$15)*(1-Assumptions!$C$40)/'Sources & Uses'!$G$6)^(1/Assumptions!$C$47)-1,-1) | F12: =IFERROR(((($A12-PropCo!$G$8)*F$7-Assumptions!$D$15)*(1-Assumptions!$C$40)/'Sources & Uses'!$G$6)^(1/Assumptions!$C$47)-1,-1) | G12: =IFERROR(((($A12-PropCo!$G$8)*G$7-Assumptions!$D$15)*(1-Assumptions!$C$40)/'Sources & Uses'!$G$6)^(1/Assumptions!$C$47)-1,-1)
A14: Shaded cell = base case.
A16: Diesel — net annual EBITDA impact ($mm) of a price increase; rows = $/gal move, columns = hedge ratio
A17: Diesel move ($/gal) | B17: 0% | C17: 25% | D17: 50% | E17: 70%
A18: Hedge ratio → | B18: 0 | C18: 0.25 | D18: 0.5 | E18: 0.7
A19: 0.5 | B19: =-Assumptions!$C$59*$A19*(1-Assumptions!$C$57)*(1-B$18) | C19: =-Assumptions!$C$59*$A19*(1-Assumptions!$C$57)*(1-C$18) | D19: =-Assumptions!$C$59*$A19*(1-Assumptions!$C$57)*(1-D$18) | E19: =-Assumptions!$C$59*$A19*(1-Assumptions!$C$57)*(1-E$18)
A20: 1 | B20: =-Assumptions!$C$59*$A20*(1-Assumptions!$C$57)*(1-B$18) | C20: =-Assumptions!$C$59*$A20*(1-Assumptions!$C$57)*(1-C$18) | D20: =-Assumptions!$C$59*$A20*(1-Assumptions!$C$57)*(1-D$18) | E20: =-Assumptions!$C$59*$A20*(1-Assumptions!$C$57)*(1-E$18)
A21: 1.5 | B21: =-Assumptions!$C$59*$A21*(1-Assumptions!$C$57)*(1-B$18) | C21: =-Assumptions!$C$59*$A21*(1-Assumptions!$C$57)*(1-C$18) | D21: =-Assumptions!$C$59*$A21*(1-Assumptions!$C$57)*(1-D$18) | E21: =-Assumptions!$C$59*$A21*(1-Assumptions!$C$57)*(1-E$18)
A22: 2 | B22: =-Assumptions!$C$59*$A22*(1-Assumptions!$C$57)*(1-B$18) | C22: =-Assumptions!$C$59*$A22*(1-Assumptions!$C$57)*(1-C$18) | D22: =-Assumptions!$C$59*$A22*(1-Assumptions!$C$57)*(1-D$18) | E22: =-Assumptions!$C$59*$A22*(1-Assumptions!$C$57)*(1-E$18)
A24: Unhedged, no pass-through exposure per $1/gal ($mm) | B24: =Assumptions!C59
A25: Pass-through on surcharge contracts set on Assumptions!C57; hedge ratios on row 18.

Sheet Phase 1
A1: Phase 1 — pre-November 3 deployment
A2: STAGE 1 MODEL — accelerated timeline. Exit-based returns on deal-team assumptions; full debt schedule, quarterly build and diligence-validated inputs follow in Stage 2.
A3: Project Equity Belt · Blackstone Tactical Opportunities × Infrastructure Partners · Highly Confidential · $ in millions unless noted
A5: Use | B5: $mm | C5: Fund | D5: Timing
A6: Rescue (DIP) loans, 2–3 Chapter 11 carriers | B6: 25 | C6: Tac Opps | D6: Term sheets Oct 14; interim orders Oct 23
A7: Chapter 7 fleet & yard purchases | B7: 20 | C7: BIP (PropCo) | D7: Bids Oct 14; first closings Oct 19–25
A8: Diligence, diesel hedge program, Ownership Works setup | B8: 3 | C8: Tac Opps / BIP | D8: Oct 5–16
A9: Phase 1 total | B9: =SUM(B6:B8)
A10: Phase 2 (Q1 2027 IC) | B10: ='Sources & Uses'!C12-B9
A11: Phase 1 Chapter 7 ties to S&U | B11: =B7-Assumptions!C22
A13: Key date | B13: Date | C13: Owner
A14: IC Phase 1 approval | B14: Oct 7 | C14: Tac Opps / BIP
A15: DIP term sheets out; Chapter 7 bids | B15: Oct 14 | C15: Tac Opps / BIP
A16: Diesel hedge placed | B16: Oct 16 | C16: BIP / Treasury
A17: Springfield hiring center opens; CDL cohort 1 | B17: Oct 21 | C17: OpCo / Ownership Works
A18: Stalking-horse agreement filed; interim DIP orders | B18: Oct 23 | C18: Tac Opps
A19: First employee equity grants | B19: Oct 27 | C19: OpCo
A20: Public announcement and site visit | B20: Oct 29 | C20: Public Affairs
A21: Election Day | B21: Nov 3 | C21: —
A22: Phase 2 IC; platform close; 363 closings | B22: Q1 2027 | C22: Tac Opps / BIP
